Workbook
Name PaiementsParAn: 'Water Sewer'!$F$6
Name PaiementsParAn: 'INS RET'!$G$6
Name pmtType: 'INS RET'!$F$20
Name pmtType: 'Water Sewer'!$E$16
Name rate: 'INS RET'!$J$6
Name rate: 'Water Sewer'!$I$6
Name roundOpt: 'INS RET'!$F$24
Name roundOpt: 'Water Sewer'!$E$18
Name TauxIntérêt: 'Water Sewer'!$F$3
Name TauxIntérêt: 'INS RET'!$G$3

Sheet Cover Sheet
A1: ='JV III Consolidated'!J1 -> Operating Budget
A2: ='JV III Consolidated'!J2 -> Lincoln JV III
A3: ='JV III Consolidated'!Q1 -> 46023

Sheet Source and Use of Cash
A1: LINCOLN SUB JOINT VENTURE III
A2: Use of Cash Resources for 2026 Budget Defecit
B7: CASH FLOW AFTER INTEREST ON DEBT SERVICE Year 2026 | E7: =+'JV III Consolidated'!Q131 -> 79039.968
B9: ADD: Operating Cash projected 01/01/2026 | E9: =+'JV III Consolidated'!D139 -> 140840.01
B11: LESS: Monthly Contributions to TI Escrow | E11: 0 | F11: Request discontinuence TI contributions starting 1 January 2026
A13: {A} | B13: ADD BACK: TI Improvements and LC Costs | E13: =+'JV III Consolidated'!Q117+'JV III Consolidated'!Q120 -> 33135.755 | F13: To be paid by TI Reserve
C15: Preliminary Cash Defecit | E15: =SUM(E7:E13) -> 253015.73
A17: {B} | C17: Investor Capital Contributions | E17: 250000
C18: Projected Cash Balance, 31 December 2026 | E18: =SUM(E15:E17) -> 503015.73
B22: Summary of TI Allowance Escrow:
C24: 46022 | D24: Projected Balance, | E24: =+'JV III Consolidated'!D148 -> 117089
A25: {A} | B25: LESS: TI Improvements and Lease Costs year 2026 | E25: =-E13 -> -33135.755
C27: Remaining Balance, TI Escrow | E27: =+E24+E25 -> 83953.245
A28: {B} | C28: Request transfer to cover defecit 2026 | F28: Request funds to be used to cover defecit
C29: Balance of TI Escrow 31 Dec 2026 | E29: =+E27+E28 -> 83953.245
B32: Other Options:
B33: 1 | C33: Discuss lower interest rate
C34: May result in some element of Cash Management as previously proposed by Liberty.
C35: (This was LIK Management, Inc determining what excess cash was available to remit to Bank - not
C36: the normal Bank Cash Management). May require more complexities in structuring
C37: at this time.
B39: 2 | C39: Partners' Capital Call
C40: A possible alternative, subject to approval by Investors.
B42: 3 | C42: Potential sale or re-purpose of the Interplex.
B44: 4 | C44: Further Base Rents Reductions
C45: Base Rents for 2027 are further reduced from 2026 by 3 months Solary $36,075 and 9 months
C46: SEOM $118,318 Total of $155K. Reimbursements for CAM and RETax basd on 2024 would
C47: be about $3,300.

Sheet Assumptions
B1: Budget Assumptions | E1: 46023
B2: ='JV III Consolidated'!J2 -> Lincoln JV III
B4: Account Code | C4: Description | D4: Assumption / Notes
B5: Revenues
B6: ='JV III Consolidated'!A10 -> 4230-8501 | C6: =VLOOKUP($B6,'JV III Consolidated'!$A$10:$U$148,3,FALSE) -> Rental Income - In Place | D6: =IFERROR(VLOOKUP($B6,'JV III Consolidated'!$A$10:$U$148,21,FALSE),"") -> Performed Analysis of Rent Roll
B7: ='JV III Consolidated'!A11 -> 4230-8501 | C7: ='JV III Consolidated'!C11 -> Rental Income - New & Renewal | D7: ='JV III Consolidated'!U11 -> As projected by Leasing Manager
B8: ='JV III Consolidated'!A12 -> 4240-8501 | C8: =VLOOKUP($B8,'JV III Consolidated'!$A$10:$U$148,3,FALSE) -> Percentage Rents | D8: =IFERROR(VLOOKUP($B8,'JV III Consolidated'!$A$10:$U$148,21,FALSE),"") -> 0
B9: ='JV III Consolidated'!A13 -> 4990-8501 | C9: =VLOOKUP($B9,'JV III Consolidated'!$A$10:$U$148,3,FALSE) -> Miscellaneous | D9: =IFERROR(VLOOKUP($B9,'JV III Consolidated'!$A$10:$U$148,21,FALSE),"") -> N/A
B10: ='JV III Consolidated'!A14 -> 9190-8501 | C10: =VLOOKUP($B10,'JV III Consolidated'!$A$10:$U$148,3,FALSE) -> Interest Income | D10: =IFERROR(VLOOKUP($B10,'JV III Consolidated'!$A$10:$U$148,21,FALSE),"") -> N/A
B11: Reimbursements | D11: =IFERROR(VLOOKUP($B11,'JV III Consolidated'!$A$10:$U$148,21,FALSE),"")
B12: ='JV III Consolidated'!A18 -> 4710-8502 | C12: =VLOOKUP($B12,'JV III Consolidated'!$A$10:$U$148,3,FALSE) -> Electric | D12: =IFERROR(VLOOKUP($B12,'JV III Consolidated'!$A$10:$U$148,21,FALSE),"") -> Set to occupancy
B13: ='JV III Consolidated'!A19 -> 4910-8502 | C13: =VLOOKUP($B13,'JV III Consolidated'!$A$10:$U$148,3,FALSE) -> Common Area Maintenance | D13: =IFERROR(VLOOKUP($B13,'JV III Consolidated'!$A$10:$U$148,21,FALSE),"") -> By tenant, based on expenses and tenant base year
B14: ='JV III Consolidated'!A20 -> 4920-8502 | C14: =VLOOKUP($B14,'JV III Consolidated'!$A$10:$U$148,3,FALSE) -> Real Estate Taxes | D14: =IFERROR(VLOOKUP($B14,'JV III Consolidated'!$A$10:$U$148,21,FALSE),"") -> By tenant, based on expenses and tenant base year
B15: ='JV III Consolidated'!A21 -> 4930-8502 | C15: =VLOOKUP($B15,'JV III Consolidated'!$A$10:$U$148,3,FALSE) -> Insurance | D15: =IFERROR(VLOOKUP($B15,'JV III Consolidated'!$A$10:$U$148,21,FALSE),"") -> Included in CAM line item
B16: Reimbursable Expenses | D16: =IFERROR(VLOOKUP($B16,'JV III Consolidated'!$A$10:$U$148,21,FALSE),"")
B17: ='JV III Consolidated'!A27 -> 6030-8502 | C17: =VLOOKUP($B17,'JV III Consolidated'!$A$10:$U$148,3,FALSE) -> Maintenance Salaries | D17: =IFERROR(VLOOKUP($B17,'JV III Consolidated'!$A$10:$U$148,21,FALSE),"") -> Based on 2026 Payroll Budget
B18: ='JV III Consolidated'!A29 -> 6120-8502 | C18: =VLOOKUP($B18,'JV III Consolidated'!$A$10:$U$148,3,FALSE) -> Electric | D18: =IFERROR(VLOOKUP($B18,'JV III Consolidated'!$A$10:$U$148,21,FALSE),"") -> 2026 budget as provided by Electric Supplier
B19: ='JV III Consolidated'!A31 -> 6130-8502 | C19: =VLOOKUP($B19,'JV III Consolidated'!$A$10:$U$148,3,FALSE) -> Water & Sewer | D19: =IFERROR(VLOOKUP($B19,'JV III Consolidated'!$A$10:$U$148,21,FALSE),"") -> 2025 Business Plan grown 3%
B20: ='JV III Consolidated'!A36 -> 6220-8502 | C20: =VLOOKUP($B20,'JV III Consolidated'!$A$10:$U$148,3,FALSE) -> Building Maintenance | D20: ='JV III Consolidated'!U35 -> Includes Split systems & Zone lines
B21: ='JV III Consolidated'!A38 -> 6330-8502 | C21: =VLOOKUP($B21,'JV III Consolidated'!$A$10:$U$148,3,FALSE) -> Parking Lot Cleaning | D21: =IFERROR(VLOOKUP($B21,'JV III Consolidated'!$A$10:$U$148,21,FALSE),"") -> Covered by Condo Fee
B22: ='JV III Consolidated'!A43 -> 6360-8502 | C22: =VLOOKUP($B22,'JV III Consolidated'!$A$10:$U$148,3,FALSE) -> Parking Lot Maintenance | D22: =IFERROR(VLOOKUP($B22,'JV III Consolidated'!$A$10:$U$148,21,FALSE),"") -> Covered by Condo Fee
B23: ='JV III Consolidated'!A45 -> 6370-8502 | C23: =VLOOKUP($B23,'JV III Consolidated'!$A$10:$U$148,3,FALSE) -> Snow Removal | D23: =IFERROR(VLOOKUP($B23,'JV III Consolidated'!$A$10:$U$148,21,FALSE),"") -> Covered by Condo Fee
B24: ='JV III Consolidated'!A50 -> 6380-8502 | C24: =VLOOKUP($B24,'JV III Consolidated'!$A$10:$U$148,3,FALSE) -> Landscaping | D24: =IFERROR(VLOOKUP($B24,'JV III Consolidated'!$A$10:$U$148,21,FALSE),"") -> Covered by Condo Fee
B25: ='JV III Consolidated'!A52 -> 6350-8502 | C25: =VLOOKUP($B25,'JV III Consolidated'!$A$10:$U$148,3,FALSE) -> Security | D25: =IFERROR(VLOOKUP($B25,'JV III Consolidated'!$A$10:$U$148,21,FALSE),"") -> Covered by Condo Fee
B26: ='JV III Consolidated'!A54 -> 6610-8502 | C26: =VLOOKUP($B26,'JV III Consolidated'!$A$10:$U$148,3,FALSE) -> Management Fee | D26: =IFERROR(VLOOKUP($B26,'JV III Consolidated'!$A$10:$U$148,21,FALSE),"") -> 4% of projected revenue
B27: ='JV III Consolidated'!A56 -> 6270-8502 | C27: =VLOOKUP($B27,'JV III Consolidated'!$A$10:$U$148,3,FALSE) -> Trash Removal | D27: =IFERROR(VLOOKUP($B27,'JV III Consolidated'!$A$10:$U$148,21,FALSE),"") -> Covered by Condo Fee
B28: ='JV III Consolidated'!A58 -> 6410-8502 | C28: =VLOOKUP($B28,'JV III Consolidated'!$A$10:$U$148,3,FALSE) -> Real Estate Taxes | D28: =IFERROR(VLOOKUP($B28,'JV III Consolidated'!$A$10:$U$148,21,FALSE),"") -> Per assessments and estimated increases
B29: ='JV III Consolidated'!A63 -> 6510-8502 | C29: =VLOOKUP($B29,'JV III Consolidated'!$A$10:$U$148,3,FALSE) -> Insurance | D29: =IFERROR(VLOOKUP($B29,'JV III Consolidated'!$A$10:$U$148,21,FALSE),"") -> 2025 Business Plan grown 3%
B30: ='JV III Consolidated'!A67 -> 6250-8502 | C30: =VLOOKUP($B30,'JV III Consolidated'!$A$10:$U$148,3,FALSE) -> Cleaning & Supplies | D30: =IFERROR(VLOOKUP($B30,'JV III Consolidated'!$A$10:$U$148,21,FALSE),"") -> As per detail above
B31: Non-Reimbursable Expenses | D31: =IFERROR(VLOOKUP($B31,'JV III Consolidated'!$A$10:$U$148,21,FALSE),"")
B32: ='JV III Consolidated'!A75 -> 5210-8501 | C32: =VLOOKUP($B32,'JV III Consolidated'!$A$10:$U$148,3,FALSE) -> Bad Debt | D32: =IFERROR(VLOOKUP($B32,'JV III Consolidated'!$A$10:$U$148,21,FALSE),"") -> 0
B33: ='JV III Consolidated'!A77 -> 6010-8501 | C33: =VLOOKUP($B33,'JV III Consolidated'!$A$10:$U$148,4,FALSE) -> Salaries & Wages | D33: =IFERROR(VLOOKUP($B33,'JV III Consolidated'!$A$10:$U$148,21,FALSE),"") -> Based on 2026 Payroll Budget
B34: ='JV III Consolidated'!A78 -> 6620-8501 | C34: =VLOOKUP($B34,'JV III Consolidated'!$A$10:$U$148,4,FALSE) -> Commissions-Internal Broker | D34: =IFERROR(VLOOKUP($B34,'JV III Consolidated'!$A$10:$U$148,21,FALSE),"") -> Based on projected leasing assumptions
B35: ='JV III Consolidated'!A81 -> 6110-8501 | C35: =VLOOKUP($B35,'JV III Consolidated'!$A$10:$U$148,4,FALSE) -> Gas | D35: =IFERROR(VLOOKUP($B35,'JV III Consolidated'!$A$10:$U$148,21,FALSE),"") -> 0
B36: ='JV III Consolidated'!A82 -> 6120-8501 | C36: =VLOOKUP($B36,'JV III Consolidated'!$A$10:$U$148,4,FALSE) -> Electric | D36: =IFERROR(VLOOKUP($B36,'JV III Consolidated'!$A$10:$U$148,21,FALSE),"") -> 0
B37: ='JV III Consolidated'!A83 -> 6130-8501 | C37: =VLOOKUP($B37,'JV III Consolidated'!$A$10:$U$148,4,FALSE) -> Water & Sewer | D37: =IFERROR(VLOOKUP($B37,'JV III Consolidated'!$A$10:$U$148,21,FALSE),"") -> 0
B38: ='JV III Consolidated'!A88 -> 6220-8501 | C38: =VLOOKUP($B38,'JV III Consolidated'!$A$10:$U$148,3,FALSE) -> Building Maintenance | D38: =IFERROR(VLOOKUP($B38,'JV III Consolidated'!$A$10:$U$148,21,FALSE),"") -> 2025 Business Plan grown 3%
B39: ='JV III Consolidated'!A90 -> 6610-8501 | C39: =VLOOKUP($B39,'JV III Consolidated'!$A$10:$U$148,3,FALSE) -> Management fee | D39: =IFERROR(VLOOKUP($B39,'JV III Consolidated'!$A$10:$U$148,21,FALSE),"") -> 0
B40: ='JV III Consolidated'!A92 -> 7110-8501 | C40: =VLOOKUP($B40,'JV III Consolidated'!$A$10:$U$148,3,FALSE) -> Marketing | D40: =IFERROR(VLOOKUP($B40,'JV III Consolidated'!$A$10:$U$148,21,FALSE),"") -> 2025 Business Plan grown 3%
B41: ='JV III Consolidated'!A94 -> 8210-8501 | C41: =VLOOKUP($B41,'JV III Consolidated'!$A$10:$U$148,3,FALSE) -> Business Taxes | D41: =IFERROR(VLOOKUP($B41,'JV III Consolidated'!$A$10:$U$148,21,FALSE),"") -> Based on tax rate and revenues
...

Sheet JV III Consolidated
B1: Consolidated - 1, 2, 4 | J1: Operating Budget | Q1: =DATE(2026,1,1) -> 46023
J2: Lincoln JV III
Q3: =Q1 -> 46023 | R3: 7/2025 Reprojections
B4: ='Renew & Vac - Rent, TI, LC'!A6+'Renew & Vac - Rent, TI, LC'!A28+'Renew & Vac - Rent, TI, LC'!A50 -> 139635 | E4: Jan | F4: Feb | G4: Mar | H4: Apr | I4: May | J4: Jun | K4: Jul | L4: Aug | M4: Sep | N4: Oct | O4: Nov | P4: Dec | Q4: Total | R4: Total | S4: Var. | T4: Input | U4: Notes
D6: Occupancy % | E6: =SUM('361'!E7,'362'!E7,'364'!E7)/$B$4 -> 0.61410146 | F6: =SUM('361'!F7,'362'!F7,'364'!F7)/$B$4 -> 0.61410146 | G6: =SUM('361'!G7,'362'!G7,'364'!G7)/$B$4 -> 0.61410146 | H6: =SUM('361'!H7,'362'!H7,'364'!H7)/$B$4 -> 0.56112642 | I6: =SUM('361'!I7,'362'!I7,'364'!I7)/$B$4 -> 0.56112642 | J6: =SUM('361'!J7,'362'!J7,'364'!J7)/$B$4 -> 0.56112642 | K6: =SUM('361'!K7,'362'!K7,'364'!K7)/$B$4 -> 0.56112642 | L6: =SUM('361'!L7,'362'!L7,'364'!L7)/$B$4 -> 0.56112642 | ... P6: =SUM('361'!P7,'362'!P7,'364'!P7)/$B$4 -> 0.4757651
B8: Revenues
A10: 4230-8501 | C10: Rental Income - In Place | E10: =+'361'!E10+'362'!E10+'364'!E10 -> 117311.49 | F10: =+'361'!F10+'362'!F10+'364'!F10 -> 113108.16 | G10: =+'361'!G10+'362'!G10+'364'!G10 -> 108595.99 | H10: =+'361'!H10+'362'!H10+'364'!H10 -> 90365.9 | I10: =+'361'!I10+'362'!I10+'364'!I10 -> 86891.73 | J10: =+'361'!J10+'362'!J10+'364'!J10 -> 78990.23 | K10: =+'361'!K10+'362'!K10+'364'!K10 -> 67639.43 | L10: =+'361'!L10+'362'!L10+'364'!L10 -> 71744.97 | ... P10: =+'361'!P10+'362'!P10+'364'!P10 -> 60494.86 | Q10: =SUM(E10:P10) -> 979211.43 | R10: 1503977.4 | S10: =(Q10+Q11)/R10-1 -> -0.054095379 | U10: Performed Analysis of Rent Roll
A11: 4230-8501 | C11: Rental Income - New & Renewal | E11: =+'361'!E11+'362'!E11+'364'!E11 -> 16352.295 | F11: =+'361'!F11+'362'!F11+'364'!F11 -> 20555.628 | G11: =+'361'!G11+'362'!G11+'364'!G11 -> 25067.795 | H11: =+'361'!H11+'362'!H11+'364'!H11 -> 29164.495 | I11: =+'361'!I11+'362'!I11+'364'!I11 -> 32720.328 | J11: =+'361'!J11+'362'!J11+'364'!J11 -> 40695.287 | K11: =+'361'!K11+'362'!K11+'364'!K11 -> 44994.287 | L11: =+'361'!L11+'362'!L11+'364'!L11 -> 46245.287 | ... P11: =+'361'!P11+'362'!P11+'364'!P11 -> 47170.917 | Q11: =SUM(E11:P11) -> 443407.77 | U11: As projected by Leasing Manager
A12: 4240-8501 | C12: Percentage Rents | E12: =+'361'!E12+'362'!E12+'364'!E12 -> 0 | F12: =+'361'!F12+'362'!F12+'364'!F12 -> 0 | G12: =+'361'!G12+'362'!G12+'364'!G12 -> 0 | H12: =+'361'!H12+'362'!H12+'364'!H12 -> 0 | I12: =+'361'!I12+'362'!I12+'364'!I12 -> 0 | J12: =+'361'!J12+'362'!J12+'364'!J12 -> 0 | K12: =+'361'!K12+'362'!K12+'364'!K12 -> 0 | L12: =+'361'!L12+'362'!L12+'364'!L12 -> 0 | ... P12: =+'361'!P12+'362'!P12+'364'!P12 -> 0 | Q12: =SUM(E12:P12) -> 0 | S12: =Q12/R12-1 -> #DIV/0!
A13: 4990-8501 | C13: Miscellaneous | E13: =+'361'!E13+'362'!E13+'364'!E13 -> 0 | F13: =+'361'!F13+'362'!F13+'364'!F13 -> 0 | G13: =+'361'!G13+'362'!G13+'364'!G13 -> 0 | H13: =+'361'!H13+'362'!H13+'364'!H13 -> 0 | I13: =+'361'!I13+'362'!I13+'364'!I13 -> 0 | J13: =+'361'!J13+'362'!J13+'364'!J13 -> 0 | K13: =+'361'!K13+'362'!K13+'364'!K13 -> 0 | L13: =+'361'!L13+'362'!L13+'364'!L13 -> 0 | ... P13: =+'361'!P13+'362'!P13+'364'!P13 -> 0 | Q13: =SUM(E13:P13) -> 0 | R13: 0 | S13: =IFERROR(Q13/R13-1,"") | U13: N/A
A14: 9190-8501 | C14: Interest Income | E14: =+'361'!E14+'362'!E14+'364'!E14 -> 0 | F14: =+'361'!F14+'362'!F14+'364'!F14 -> 0 | G14: =+'361'!G14+'362'!G14+'364'!G14 -> 0 | H14: =+'361'!H14+'362'!H14+'364'!H14 -> 0 | I14: =+'361'!I14+'362'!I14+'364'!I14 -> 0 | J14: =+'361'!J14+'362'!J14+'364'!J14 -> 0 | K14: =+'361'!K14+'362'!K14+'364'!K14 -> 0 | L14: =+'361'!L14+'362'!L14+'364'!L14 -> 0 | ... P14: =+'361'!P14+'362'!P14+'364'!P14 -> 0 | Q14: =SUM(E14:P14) -> 0 | R14: 0 | U14: N/A
D15: Total Rental and Other: | E15: =SUM(E10:E14) -> 133663.78 | F15: =SUM(F10:F14) -> 133663.79 | G15: =SUM(G10:G14) -> 133663.78 | H15: =SUM(H10:H14) -> 119530.39 | I15: =SUM(I10:I14) -> 119612.06 | J15: =SUM(J10:J14) -> 119685.52 | K15: =SUM(K10:K14) -> 112633.72 | L15: =SUM(L10:L14) -> 117990.26 | ... R15: =SUM(R10:R14) -> 1503977.4 | S15: =Q15/R15-1 -> -0.054095379
B17: Reimbursements
A18: 4710-8502 | C18: Electric | E18: =+'361'!E18+'362'!E18+'364'!E18 -> 10302.184 | F18: =+'361'!F18+'362'!F18+'364'!F18 -> 9109.9855 | G18: =+'361'!G18+'362'!G18+'364'!G18 -> 7359.7405 | H18: =+'361'!H18+'362'!H18+'364'!H18 -> 4562.5296 | I18: =+'361'!I18+'362'!I18+'364'!I18 -> 4057.6656 | J18: =+'361'!J18+'362'!J18+'364'!J18 -> 4394.6565 | K18: =+'361'!K18+'362'!K18+'364'!K18 -> 5202.816 | L18: =+'361'!L18+'362'!L18+'364'!L18 -> 5187.1248 | ... P18: =+'361'!P18+'362'!P18+'364'!P18 -> 7747.5708 | Q18: =SUM(E18:P18) -> 70761.162 | R18: 82857.27 | S18: =Q18/R18-1 -> -0.14598728 | U18: Set to occupancy
A19: 4910-8502 | C19: Common Area Maintenance | E19: =+'361'!E19+'362'!E19+'364'!E19 -> 5070 | F19: =+'361'!F19+'362'!F19+'364'!F19 -> 5070 | G19: =+'361'!G19+'362'!G19+'364'!G19 -> 5070 | H19: =+'361'!H19+'362'!H19+'364'!H19 -> 5070 | I19: =+'361'!I19+'362'!I19+'364'!I19 -> 5070 | J19: =+'361'!J19+'362'!J19+'364'!J19 -> 5070 | K19: =+'361'!K19+'362'!K19+'364'!K19 -> 5070 | L19: =+'361'!L19+'362'!L19+'364'!L19 -> 5070 | ... P19: =+'361'!P19+'362'!P19+'364'!P19 -> 5070 | Q19: =SUM(E19:P19) -> 60840 | R19: 54578 | S19: =Q19/R19-1 -> 0.11473487 | U19: By tenant, based on expenses and tenant base year
A20: 4920-8502 | C20: Real Estate Taxes | E20: =+'361'!E20+'362'!E20+'364'!E20 -> 560 | F20: =+'361'!F20+'362'!F20+'364'!F20 -> 560 | G20: =+'361'!G20+'362'!G20+'364'!G20 -> 560 | H20: =+'361'!H20+'362'!H20+'364'!H20 -> 560 | I20: =+'361'!I20+'362'!I20+'364'!I20 -> 560 | J20: =+'361'!J20+'362'!J20+'364'!J20 -> 560 | K20: =+'361'!K20+'362'!K20+'364'!K20 -> 560 | L20: =+'361'!L20+'362'!L20+'364'!L20 -> 560 | ... P20: =+'361'!P20+'362'!P20+'364'!P20 -> 560 | Q20: =SUM(E20:P20) -> 6720 | R20: 11186 | S20: =Q20/R20-1 -> -0.39924906 | U20: By tenant, based on expenses and tenant base year
A21: 4930-8502 | C21: Insurance | E21: =+'361'!E21+'362'!E21+'364'!E21 -> 0 | F21: =+'361'!F21+'362'!F21+'364'!F21 -> 0 | G21: =+'361'!G21+'362'!G21+'364'!G21 -> 0 | H21: =+'361'!H21+'362'!H21+'364'!H21 -> 0 | I21: =+'361'!I21+'362'!I21+'364'!I21 -> 0 | J21: =+'361'!J21+'362'!J21+'364'!J21 -> 0 | K21: =+'361'!K21+'362'!K21+'364'!K21 -> 0 | L21: =+'361'!L21+'362'!L21+'364'!L21 -> 0 | ... P21: =+'361'!P21+'362'!P21+'364'!P21 -> 0 | Q21: =SUM(E21:P21) -> 0 | R21: 0 | S21: =IFERROR(Q21/R21-1,"") | U21: Included in CAM line item
D22: Total Reimbursements: | E22: =SUM(E18:E21) -> 15932.184 | F22: =SUM(F18:F21) -> 14739.985 | G22: =SUM(G18:G21) -> 12989.74 | H22: =SUM(H18:H21) -> 10192.53 | I22: =SUM(I18:I21) -> 9687.6656 | J22: =SUM(J18:J21) -> 10024.656 | K22: =SUM(K18:K21) -> 10832.816 | L22: =SUM(L18:L21) -> 10817.125 | ... R22: =SUM(R18:R21) -> 148621.27 | S22: =Q22/R22-1 -> -0.069304399
B24: TOTAL REVENUES | E24: =+E15+E22 -> 149595.97 | F24: =+F15+F22 -> 148403.77 | G24: =+G15+G22 -> 146653.53 | H24: =+H15+H22 -> 129722.92 | I24: =+I15+I22 -> 129299.72 | J24: =+J15+J22 -> 129710.17 | K24: =+K15+K22 -> 123466.53 | L24: =+L15+L22 -> 128807.38 | ... R24: =+R15+R22 -> 1652598.7 | S24: =Q24/R24-1 -> -0.055463154
Q25: =+'361'!Q24+'362'!Q24+'364'!Q24 -> 1560940.4
B26: Reimbursable Expenses
A27: 6030-8502 | C27: Maintenance Salaries | E27: =+'361'!E27+'362'!E27+'364'!E27 -> 3931.6667 | F27: =+'361'!F27+'362'!F27+'364'!F27 -> 3931.6667 | G27: =+'361'!G27+'362'!G27+'364'!G27 -> 3931.6667 | H27: =+'361'!H27+'362'!H27+'364'!H27 -> 3931.6667 | I27: =+'361'!I27+'362'!I27+'364'!I27 -> 3931.6667 | J27: =+'361'!J27+'362'!J27+'364'!J27 -> 3931.6667 | K27: =+'361'!K27+'362'!K27+'364'!K27 -> 3931.6667 | L27: =+'361'!L27+'362'!L27+'364'!L27 -> 3931.6667 | ... P27: =+'361'!P27+'362'!P27+'364'!P27 -> 3931.6667 | Q27: =SUM(E27:P27) -> 47180 | R27: 30778.77 | S27: =Q27/R27-1 -> 0.53287477 | U27: Based on 2026 Payroll Budget
A29: 6120-8502 | C29: Electric | E29: =+'361'!E29+'362'!E29+'364'!E29 -> 17256 | F29: =+'361'!F29+'362'!F29+'364'!F29 -> 15367 | G29: =+'361'!G29+'362'!G29+'364'!G29 -> 12325 | H29: =+'361'!H29+'362'!H29+'364'!H29 -> 8167 | I29: =+'361'!I29+'362'!I29+'364'!I29 -> 7297 | J29: =+'361'!J29+'362'!J29+'364'!J29 -> 7928 | K29: =+'361'!K29+'362'!K29+'364'!K29 -> 9433 | L29: =+'361'!L29+'362'!L29+'364'!L29 -> 9482 | ... P29: =+'361'!P29+'362'!P29+'364'!P29 -> 15544 | Q29: =SUM(E29:P29) -> 127883 | R29: 125357.78 | S29: =Q29/R29-1 -> 0.020144103 | U29: 2026 budget as provided by Electric Supplier
A31: 6130-8502 | C31: Water & Sewer | E31: =+'361'!E31+'362'!E31+'364'!E31 -> 4165.48 | F31: =+'361'!F31+'362'!F31+'364'!F31 -> 4018.19 | G31: =+'361'!G31+'362'!G31+'364'!G31 -> 4425.04 | H31: =+'361'!H31+'362'!H31+'364'!H31 -> 2943.9 | I31: =+'361'!I31+'362'!I31+'364'!I31 -> 3179.77 | J31: =+'361'!J31+'362'!J31+'364'!J31 -> 3185.95 | K31: =+'361'!K31+'362'!K31+'364'!K31 -> 3448.6 | L31: =+'361'!L31+'362'!L31+'364'!L31 -> 3597.95 | ... P31: =+'361'!P31+'362'!P31+'364'!P31 -> 4417.83 | Q31: =SUM(E31:P31) -> 44542.21 | R31: 43939.16 | S31: =Q31/R31-1 -> 0.013724659 | U31: 2025 Business Plan grown 3%
D33: Building Maint.-Contractual | E33: =+'361'!E33+'362'!E33+'364'!E33 -> 5657 | F33: =+'361'!F33+'362'!F33+'364'!F33 -> 4982 | G33: =+'361'!G33+'362'!G33+'364'!G33 -> 3642 | H33: =+'361'!H33+'362'!H33+'364'!H33 -> 8029 | I33: =+'361'!I33+'362'!I33+'364'!I33 -> 4332 | J33: =+'361'!J33+'362'!J33+'364'!J33 -> 2832 | K33: =+'361'!K33+'362'!K33+'364'!K33 -> 6307 | L33: =+'361'!L33+'362'!L33+'364'!L33 -> 4332 | ... P33: =+'361'!P33+'362'!P33+'364'!P33 -> 2832 | Q33: =SUM(E33:P33) -> 58948
D34: Building Maint.-Recurring | E34: =+'361'!E34+'362'!E34+'364'!E34 -> 6345 | F34: =+'361'!F34+'362'!F34+'364'!F34 -> 6270 | G34: =+'361'!G34+'362'!G34+'364'!G34 -> 5445 | H34: =+'361'!H34+'362'!H34+'364'!H34 -> 6645 | I34: =+'361'!I34+'362'!I34+'364'!I34 -> 15480 | J34: =+'361'!J34+'362'!J34+'364'!J34 -> 5345 | K34: =+'361'!K34+'362'!K34+'364'!K34 -> 6890 | L34: =+'361'!L34+'362'!L34+'364'!L34 -> 5070 | ... P34: =+'361'!P34+'362'!P34+'364'!P34 -> 5170 | Q34: =SUM(E34:P34) -> 85200
D35: Building Maint.-Big Projects | E35: =+'361'!E35+'362'!E35+'364'!E35 -> 0 | F35: =+'361'!F35+'362'!F35+'364'!F35 -> 4635 | G35: =+'361'!G35+'362'!G35+'364'!G35 -> 0 | H35: =+'361'!H35+'362'!H35+'364'!H35 -> 0 | I35: =+'361'!I35+'362'!I35+'364'!I35 -> 0 | J35: =+'361'!J35+'362'!J35+'364'!J35 -> 46350 | K35: =+'361'!K35+'362'!K35+'364'!K35 -> 0 | L35: =+'361'!L35+'362'!L35+'364'!L35 -> 0 | ... P35: =+'361'!P35+'362'!P35+'364'!P35 -> 0 | Q35: =SUM(E35:P35) -> 55620 | U35: Includes Split systems & Zone lines
A36: 6220-8502 | C36: Building Maintenance | E36: =SUM(E33:E35) -> 12002 | F36: =SUM(F33:F35) -> 15887 | G36: =SUM(G33:G35) -> 9087 | H36: =SUM(H33:H35) -> 14674 | I36: =SUM(I33:I35) -> 19812 | J36: =SUM(J33:J35) -> 54527 | K36: =SUM(K33:K35) -> 13197 | L36: =SUM(L33:L35) -> 9402 | ... Q36: =SUM(Q33:Q35) -> 199768 | R36: 124189.81 | S36: =Q36/R36-1 -> 0.60856998
A38: 6330-8502 | B38: (SC) | C38: Parking Lot Cleaning | E38: =+'361'!E38+'362'!E38+'364'!E38 -> 0 | F38: =+'361'!F38+'362'!F38+'364'!F38 -> 0 | G38: =+'361'!G38+'362'!G38+'364'!G38 -> 0 | H38: =+'361'!H38+'362'!H38+'364'!H38 -> 0 | I38: =+'361'!I38+'362'!I38+'364'!I38 -> 0 | J38: =+'361'!J38+'362'!J38+'364'!J38 -> 0 | K38: =+'361'!K38+'362'!K38+'364'!K38 -> 0 | L38: =+'361'!L38+'362'!L38+'364'!L38 -> 0 | ... P38: =+'361'!P38+'362'!P38+'364'!P38 -> 0 | Q38: =SUM(E38:P38) -> 0 | U38: Covered by Condo Fee
D40: Parking Lot Maint.-Contractual | E40: =+'361'!E40+'362'!E40+'364'!E40 -> 0 | F40: =+'361'!F40+'362'!F40+'364'!F40 -> 0 | G40: =+'361'!G40+'362'!G40+'364'!G40 -> 0 | H40: =+'361'!H40+'362'!H40+'364'!H40 -> 0 | I40: =+'361'!I40+'362'!I40+'364'!I40 -> 0 | J40: =+'361'!J40+'362'!J40+'364'!J40 -> 0 | K40: =+'361'!K40+'362'!K40+'364'!K40 -> 0 | L40: =+'361'!L40+'362'!L40+'364'!L40 -> 0 | ... P40: =+'361'!P40+'362'!P40+'364'!P40 -> 0 | Q40: =SUM(E40:P40) -> 0
D41: Parking Lot Maint.-Recurring | E41: =+'361'!E41+'362'!E41+'364'!E41 -> 0 | F41: =+'361'!F41+'362'!F41+'364'!F41 -> 0 | G41: =+'361'!G41+'362'!G41+'364'!G41 -> 0 | H41: =+'361'!H41+'362'!H41+'364'!H41 -> 0 | I41: =+'361'!I41+'362'!I41+'364'!I41 -> 0 | J41: =+'361'!J41+'362'!J41+'364'!J41 -> 0 | K41: =+'361'!K41+'362'!K41+'364'!K41 -> 0 | L41: =+'361'!L41+'362'!L41+'364'!L41 -> 0 | ... P41: =+'361'!P41+'362'!P41+'364'!P41 -> 0 | Q41: =SUM(E41:P41) -> 0
D42: Parking Lot Maint.-Big Projects | E42: =+'361'!E42+'362'!E42+'364'!E42 -> 0 | F42: =+'361'!F42+'362'!F42+'364'!F42 -> 0 | G42: =+'361'!G42+'362'!G42+'364'!G42 -> 0 | H42: =+'361'!H42+'362'!H42+'364'!H42 -> 0 | I42: =+'361'!I42+'362'!I42+'364'!I42 -> 0 | J42: =+'361'!J42+'362'!J42+'364'!J42 -> 0 | K42: =+'361'!K42+'362'!K42+'364'!K42 -> 0 | L42: =+'361'!L42+'362'!L42+'364'!L42 -> 0 | ... P42: =+'361'!P42+'362'!P42+'364'!P42 -> 0 | Q42: =SUM(E42:P42) -> 0
A43: 6360-8502 | C43: Parking Lot Maintenance | E43: =SUM(E40:E42) -> 0 | F43: =SUM(F40:F42) -> 0 | G43: =SUM(G40:G42) -> 0 | H43: =SUM(H40:H42) -> 0 | I43: =SUM(I40:I42) -> 0 | J43: =SUM(J40:J42) -> 0 | K43: =SUM(K40:K42) -> 0 | L43: =SUM(L40:L42) -> 0 | ... Q43: =SUM(Q40:Q42) -> 0 | R43: 646.79 | S43: =Q43/R43-1 -> -1 | U43: Covered by Condo Fee
A45: 6370-8502 | C45: Snow Removal | E45: =+'361'!E45+'362'!E45+'364'!E45 -> 0 | F45: =+'361'!F45+'362'!F45+'364'!F45 -> 0 | G45: =+'361'!G45+'362'!G45+'364'!G45 -> 0 | H45: =+'361'!H45+'362'!H45+'364'!H45 -> 0 | I45: =+'361'!I45+'362'!I45+'364'!I45 -> 0 | J45: =+'361'!J45+'362'!J45+'364'!J45 -> 0 | K45: =+'361'!K45+'362'!K45+'364'!K45 -> 0 | L45: =+'361'!L45+'362'!L45+'364'!L45 -> 0 | ... P45: =+'361'!P45+'362'!P45+'364'!P45 -> 0 | Q45: =SUM(E45:P45) -> 0 | R45: 0 | S45: =Q45/R45-1 -> #DIV/0! | U45: Covered by Condo Fee
D47: Landscaping-Contractual | E47: =+'361'!E47+'362'!E47+'364'!E47 -> 0 | F47: =+'361'!F47+'362'!F47+'364'!F47 -> 0 | G47: =+'361'!G47+'362'!G47+'364'!G47 -> 0 | H47: =+'361'!H47+'362'!H47+'364'!H47 -> 0 | I47: =+'361'!I47+'362'!I47+'364'!I47 -> 0 | J47: =+'361'!J47+'362'!J47+'364'!J47 -> 0 | K47: =+'361'!K47+'362'!K47+'364'!K47 -> 0 | L47: =+'361'!L47+'362'!L47+'364'!L47 -> 0 | ... P47: =+'361'!P47+'362'!P47+'364'!P47 -> 0 | Q47: =SUM(E47:P47) -> 0
D48: Landscaping-Recurring | E48: =+'361'!E48+'362'!E48+'364'!E48 -> 0 | F48: =+'361'!F48+'362'!F48+'364'!F48 -> 0 | G48: =+'361'!G48+'362'!G48+'364'!G48 -> 0 | H48: =+'361'!H48+'362'!H48+'364'!H48 -> 0 | I48: =+'361'!I48+'362'!I48+'364'!I48 -> 0 | J48: =+'361'!J48+'362'!J48+'364'!J48 -> 0 | K48: =+'361'!K48+'362'!K48+'364'!K48 -> 0 | L48: =+'361'!L48+'362'!L48+'364'!L48 -> 0 | ... P48: =+'361'!P48+'362'!P48+'364'!P48 -> 0 | Q48: =SUM(E48:P48) -> 0
D49: Landscaping-Big Projects | E49: =+'361'!E49+'362'!E49+'364'!E49 -> 0 | F49: =+'361'!F49+'362'!F49+'364'!F49 -> 0 | G49: =+'361'!G49+'362'!G49+'364'!G49 -> 0 | H49: =+'361'!H49+'362'!H49+'364'!H49 -> 0 | I49: =+'361'!I49+'362'!I49+'364'!I49 -> 0 | J49: =+'361'!J49+'362'!J49+'364'!J49 -> 0 | K49: =+'361'!K49+'362'!K49+'364'!K49 -> 0 | L49: =+'361'!L49+'362'!L49+'364'!L49 -> 0 | ... P49: =+'361'!P49+'362'!P49+'364'!P49 -> 0 | Q49: =SUM(E49:P49) -> 0
A50: 6380-8502 | C50: Landscaping | E50: =SUM(E47:E49) -> 0 | F50: =SUM(F47:F49) -> 0 | G50: =SUM(G47:G49) -> 0 | H50: =SUM(H47:H49) -> 0 | I50: =SUM(I47:I49) -> 0 | J50: =SUM(J47:J49) -> 0 | K50: =SUM(K47:K49) -> 0 | L50: =SUM(L47:L49) -> 0 | ... Q50: =SUM(Q47:Q49) -> 0 | R50: 450 | S50: =Q50/R50-1 -> -1 | U50: Covered by Condo Fee
A52: 6350-8502 | C52: Security | E52: =+'361'!E52+'362'!E52+'364'!E52 -> 0 | F52: =+'361'!F52+'362'!F52+'364'!F52 -> 0 | G52: =+'361'!G52+'362'!G52+'364'!G52 -> 0 | H52: =+'361'!H52+'362'!H52+'364'!H52 -> 0 | I52: =+'361'!I52+'362'!I52+'364'!I52 -> 0 | J52: =+'361'!J52+'362'!J52+'364'!J52 -> 0 | K52: =+'361'!K52+'362'!K52+'364'!K52 -> 0 | L52: =+'361'!L52+'362'!L52+'364'!L52 -> 0 | ... P52: =+'361'!P52+'362'!P52+'364'!P52 -> 0 | Q52: =SUM(E52:P52) -> 0 | S52: =Q52/R52-1 -> #DIV/0! | U52: Covered by Condo Fee
A54: 6610-8502 | B54: (BP) | C54: Management Fee | E54: =+'361'!E54+'362'!E54+'364'!E54 -> 5984 | F54: =+'361'!F54+'362'!F54+'364'!F54 -> 5936 | G54: =+'361'!G54+'362'!G54+'364'!G54 -> 5866 | H54: =+'361'!H54+'362'!H54+'364'!H54 -> 5188 | I54: =+'361'!I54+'362'!I54+'364'!I54 -> 5172 | J54: =+'361'!J54+'362'!J54+'364'!J54 -> 5188 | K54: =+'361'!K54+'362'!K54+'364'!K54 -> 4939 | L54: =+'361'!L54+'362'!L54+'364'!L54 -> 5153 | ... P54: =+'361'!P54+'362'!P54+'364'!P54 -> 4842 | Q54: =SUM(E54:P54) -> 62436 | R54: 66207.36 | S54: =Q54/R54-1 -> -0.056962851 | U54: 4% of projected revenue
...

Sheet 361
B1: 3610 | J1: =+'JV III Consolidated'!J1 -> Operating Budget | Q1: ='JV III Consolidated'!Q1 -> 46023
J2: ='JV III Consolidated'!J2 -> Lincoln JV III
Q3: =Q1 -> 46023 | S3: 7/2025 Reprojections
B4: ='Renew & Vac - Rent, TI, LC'!A6 -> 41821 | E4: Jan | F4: Feb | G4: Mar | H4: Apr | I4: May | J4: Jun | K4: Jul | L4: Aug | M4: Sep | N4: Oct | O4: Nov | P4: Dec | Q4: Total | R4: Total PSF | S4: Total | T4: Var. | U4: Input | V4: Notes
D6: Occupancy % | E6: ='Renew & Vac - Rent, TI, LC'!AH9 -> 0.5898 | F6: ='Renew & Vac - Rent, TI, LC'!AI9 -> 0.5898 | G6: ='Renew & Vac - Rent, TI, LC'!AJ9 -> 0.5898 | H6: ='Renew & Vac - Rent, TI, LC'!AK9 -> 0.5898 | I6: ='Renew & Vac - Rent, TI, LC'!AL9 -> 0.5898 | J6: ='Renew & Vac - Rent, TI, LC'!AM9 -> 0.5898 | K6: ='Renew & Vac - Rent, TI, LC'!AN9 -> 0.5898 | L6: ='Renew & Vac - Rent, TI, LC'!AO9 -> 0.5898 | ... P6: ='Renew & Vac - Rent, TI, LC'!AS9 -> 0.5898
D7: Occupancy SF | E7: =$B$4*E6 -> 24666.026 | F7: =$B$4*F6 -> 24666.026 | G7: =$B$4*G6 -> 24666.026 | H7: =$B$4*H6 -> 24666.026 | I7: =$B$4*I6 -> 24666.026 | J7: =$B$4*J6 -> 24666.026 | K7: =$B$4*K6 -> 24666.026 | L7: =$B$4*L6 -> 24666.026 | ... P7: =$B$4*P6 -> 24666.026
B8: Revenues
A10: 4230-8501 | C10: Rental Income - In Place | E10: =SUMIFS('In Place Revenue'!$G:$G,'In Place Revenue'!$A:$A,$B$1,'In Place Revenue'!$H:$H,1) -> 25265.13 | F10: =SUMIFS('In Place Revenue'!$G:$G,'In Place Revenue'!$A:$A,$B$1,'In Place Revenue'!$H:$H,2) -> 21061.8 | G10: =SUMIFS('In Place Revenue'!$G:$G,'In Place Revenue'!$A:$A,$B$1,'In Place Revenue'!$H:$H,3) -> 19266.3 | H10: =SUMIFS('In Place Revenue'!$G:$G,'In Place Revenue'!$A:$A,$B$1,'In Place Revenue'!$H:$H,4) -> 17241.88 | I10: =SUMIFS('In Place Revenue'!$G:$G,'In Place Revenue'!$A:$A,$B$1,'In Place Revenue'!$H:$H,5) -> 15196.88 | J10: =SUMIFS('In Place Revenue'!$G:$G,'In Place Revenue'!$A:$A,$B$1,'In Place Revenue'!$H:$H,6) -> 9190.63 | K10: =SUMIFS('In Place Revenue'!$G:$G,'In Place Revenue'!$A:$A,$B$1,'In Place Revenue'!$H:$H,7) -> 7388 | L10: =SUMIFS('In Place Revenue'!$G:$G,'In Place Revenue'!$A:$A,$B$1,'In Place Revenue'!$H:$H,8) -> 6171.75 | M10: =SUMIFS('In Place Revenue'!$G:$G,'In Place Revenue'!$A:$A,$B$1,'In Place Revenue'!$H:$H,9) -> 6171.75 | N10: =SUMIFS('In Place Revenue'!$G:$G,'In Place Revenue'!$A:$A,$B$1,'In Place Revenue'!$H:$H,10) -> 4414.25 | O10: =SUMIFS('In Place Revenue'!$G:$G,'In Place Revenue'!$A:$A,$B$1,'In Place Revenue'!$H:$H,11) -> 4414.25 | P10: =SUMIFS('In Place Revenue'!$G:$G,'In Place Revenue'!$A:$A,$B$1,'In Place Revenue'!$H:$H,12) -> 4414.25 | Q10: =SUM(E10:P10) -> 140196.87 | R10: =Q10/$B$4 -> 3.3523079 | S10: 344588.27 | T10: =IFERROR((Q10+Q11)/S10-1,"-") -> 0.16673986 | V10: Inplace reviewed, ok
A11: 4230-8501 | C11: Rental Income - New & Renewal | E11: ='Renew & Vac - Rent, TI, LC'!AH10 -> 9431.875 | F11: ='Renew & Vac - Rent, TI, LC'!AI10 -> 13635.208 | G11: ='Renew & Vac - Rent, TI, LC'!AJ10 -> 15430.708 | H11: ='Renew & Vac - Rent, TI, LC'!AK10 -> 15430.708 | I11: ='Renew & Vac - Rent, TI, LC'!AL10 -> 17475.708 | J11: ='Renew & Vac - Rent, TI, LC'!AM10 -> 23605.292 | K11: ='Renew & Vac - Rent, TI, LC'!AN10 -> 25407.917 | L11: ='Renew & Vac - Rent, TI, LC'!AO10 -> 26658.917 | ... P11: ='Renew & Vac - Rent, TI, LC'!AS10 -> 29871.917 | Q11: =SUM(E11:P11) -> 261848 | R11: =Q11/$B$4 -> 6.2611607 | T11: =IFERROR(Q11/S11-1,"-") -> -
A12: 4240-8501 | C12: Percentage Rents | E12: 0 | F12: 0 | G12: 0 | H12: 0 | I12: 0 | J12: 0 | K12: 0 | L12: 0 | M12: 0 | N12: 0 | O12: 0 | P12: 0 | Q12: =SUM(E12:P12) -> 0 | R12: =Q12/$B$4 -> 0 | T12: =R12/S12-1 -> #DIV/0!
A13: 4990-8501 | C13: Miscellaneous | E13: 0 | F13: 0 | G13: 0 | H13: 0 | I13: 0 | J13: 0 | K13: 0 | L13: 0 | M13: 0 | N13: 0 | O13: 0 | P13: 0 | Q13: =SUM(E13:P13) -> 0 | R13: =Q13/$B$4 -> 0 | T13: =IFERROR(Q13/S13-1,"-") -> -
A14: 9190-8501 | C14: Interest Income | E14: 0 | F14: 0 | G14: 0 | H14: 0 | I14: 0 | J14: 0 | K14: 0 | L14: 0 | M14: 0 | N14: 0 | O14: 0 | P14: 0 | Q14: =SUM(E14:P14) -> 0 | R14: =Q14/$B$4 -> 0 | T14: =IFERROR(Q14/S14-1,"-") -> -
C15: Total Rental and Other | E15: =SUM(E10:E14) -> 34697.005 | F15: =SUM(F10:F14) -> 34697.008 | G15: =SUM(G10:G14) -> 34697.008 | H15: =SUM(H10:H14) -> 32672.588 | I15: =SUM(I10:I14) -> 32672.588 | J15: =SUM(J10:J14) -> 32795.922 | K15: =SUM(K10:K14) -> 32795.917 | L15: =SUM(L10:L14) -> 32830.667 | ... Q15: =SUM(Q10:Q14) -> 402044.87 | R15: =Q15/$B$4 -> 9.6134686 | S15: =SUM(S10:S14) -> 344588.27 | T15: =IFERROR(Q15/S15-1,"-") -> 0.16673986
B17: Reimbursements
A18: 4710-8502 | C18: Electric | E18: =E6*E29 -> 4529.0742 | F18: =F6*F29 -> 3922.7598 | G18: =G6*G29 -> 2932.4856 | H18: =H6*H29 -> 1787.6838 | I18: =I6*I29 -> 1485.1164 | J18: =J6*J29 -> 1739.91 | K18: =K6*K29 -> 2132.127 | L18: =L6*L29 -> 2111.484 | ... P18: =P6*P29 -> 4106.7774 | Q18: =SUM(E18:P18) -> 30423.064 | R18: =Q18/$B$4 -> 0.72745902 | S18: 28439.42 | T18: =IFERROR(Q18/S18-1,"-") -> 0.069749791 | U18: DW | V18: =Q18/Q29*100&"% Set to occupancy" -> 58.98% Set to occupancy
A19: 4910-8502 | C19: Common Area Maintenance | E19: =+'Tenant Recoveries'!F21 -> 1670 | F19: =+E19 -> 1670 | G19: =+F19 -> 1670 | H19: =+G19 -> 1670 | I19: =+H19 -> 1670 | J19: =+I19 -> 1670 | K19: =+J19 -> 1670 | L19: =+K19 -> 1670 | M19: =+L19 -> 1670 | ... P19: =+O19 -> 1670 | Q19: =SUM(E19:P19) -> 20040 | R19: =Q19/$B$4 -> 0.4791851 | S19: 17594 | T19: =IFERROR(Q19/S19-1,"-") -> 0.13902467 | V19: =Q19/(Q71-Q63-Q58-Q29) -> 0.091197906
A20: 4920-8502 | C20: Real Estate Taxes | E20: =+'Tenant Recoveries'!F22 -> 130 | F20: =+E20 -> 130 | G20: =+F20 -> 130 | H20: =+G20 -> 130 | I20: =+H20 -> 130 | J20: =+I20 -> 130 | K20: =+J20 -> 130 | L20: =+K20 -> 130 | M20: =+L20 -> 130 | ... P20: =+O20 -> 130 | Q20: =SUM(E20:P20) -> 1560 | R20: =Q20/$B$4 -> 0.037301834 | S20: 3386 | T20: =IFERROR(Q20/S20-1,"-") -> -0.53927939 | V20: =Q20/Q58 -> 0.038425745
A21: 4930-8502 | C21: Insurance | Q21: =SUM(E21:P21) -> 0 | R21: =Q21/$B$4 -> 0 | T21: =IFERROR(Q21/S21-1,"-") -> -
C22: Total Reimbursements | E22: =SUM(E18:E21) -> 6329.0742 | F22: =SUM(F18:F21) -> 5722.7598 | G22: =SUM(G18:G21) -> 4732.4856 | H22: =SUM(H18:H21) -> 3587.6838 | I22: =SUM(I18:I21) -> 3285.1164 | J22: =SUM(J18:J21) -> 3539.91 | K22: =SUM(K18:K21) -> 3932.127 | L22: =SUM(L18:L21) -> 3911.484 | ... Q22: =SUM(Q18:Q21) -> 52023.064 | R22: =Q22/$B$4 -> 1.243946 | S22: =SUM(S18:S21) -> 49419.42 | T22: =IFERROR(Q22/S22-1,"-") -> 0.052684625
R23: =Q23/$B$4 -> 0
B24: TOTAL REVENUES | E24: =+E15+E22 -> 41026.079 | F24: =+F15+F22 -> 40419.768 | G24: =+G15+G22 -> 39429.494 | H24: =+H15+H22 -> 36260.272 | I24: =+I15+I22 -> 35957.705 | J24: =+J15+J22 -> 36335.832 | K24: =+K15+K22 -> 36728.044 | L24: =+L15+L22 -> 36742.151 | ... Q24: =+Q15+Q22 -> 454067.93 | R24: =Q24/$B$4 -> 10.857415 | S24: =+S15+S22 -> 394007.69 | T24: =IFERROR(Q24/S24-1,"-") -> 0.15243419 | V24: Why is 2026 revenues 17.48% higher
V25: Move out -,1429, 2 new -- 1.838+2.394 | Z25: =1838+2394-1429 -> 2803 | AA25: =+Z25*18.5 -> 51855.5 | AB25: =+Q24-S24 -> 60060.244
B26: Reimbursable Expenses
A27: 6030-8502 | C27: Maintenance Salaries | E27: ='Allocated Expenses'!E4 -> 1179.5 | F27: ='Allocated Expenses'!F4 -> 1179.5 | G27: ='Allocated Expenses'!G4 -> 1179.5 | H27: ='Allocated Expenses'!H4 -> 1179.5 | I27: ='Allocated Expenses'!I4 -> 1179.5 | J27: ='Allocated Expenses'!J4 -> 1179.5 | K27: ='Allocated Expenses'!K4 -> 1179.5 | L27: ='Allocated Expenses'!L4 -> 1179.5 | ... P27: ='Allocated Expenses'!P4 -> 1179.5 | Q27: =SUM(E27:P27) -> 14154 | R27: =Q27/$B$4 -> 0.33844241 | S27: 8881.32 | T27: =IFERROR(Q27/S27-1,"-") -> 0.59368202
A29: 6120-8502 | C29: Electric | E29: 7679 | F29: 6651 | G29: 4972 | H29: 3031 | I29: 2518 | J29: 2950 | K29: 3615 | L29: 3580 | M29: 2717 | N29: 2835 | O29: 4071 | P29: 6963 | Q29: =SUM(E29:P29) -> 51582 | R29: =Q29/$B$4 -> 1.2333995 | S29: 49514.07 | T29: =IFERROR(Q29/S29-1,"-") -> 0.041764492 | U29: DW | V29: Data\Shared\Properties\Business Plans - All Entities\2026\ISG Electric data
A31: 6130-8502 | C31: Water & Sewer | E31: ='Water Sewer'!D9 -> 1965.4 | F31: ='Water Sewer'!E9 -> 1938.62 | G31: ='Water Sewer'!F9 -> 1875.79 | H31: ='Water Sewer'!G9 -> 1798.54 | I31: ='Water Sewer'!H9 -> 1995.27 | J31: ='Water Sewer'!I9 -> 1897.42 | K31: ='Water Sewer'!J9 -> 1907.72 | L31: ='Water Sewer'!K9 -> 1988.06 | ... P31: ='Water Sewer'!O9 -> 2011.75 | Q31: =SUM(E31:P31) -> 23159.41 | R31: =Q31/$B$4 -> 0.55377466 | S31: 23066.28 | T31: =IFERROR(Q31/S31-1,"-") -> 0.0040374954 | U31: AK | V31: 2025 Business Plan grown 3%
D33: Building Maint.-Contractual | E33: ='Building Maint'!C13 -> 1960 | F33: ='Building Maint'!D13 -> 1660 | G33: ='Building Maint'!E13 -> 1820 | H33: ='Building Maint'!F13 -> 2610 | I33: ='Building Maint'!G13 -> 1010 | J33: ='Building Maint'!H13 -> 1010 | K33: ='Building Maint'!I13 -> 2610 | L33: ='Building Maint'!J13 -> 1010 | ... P33: ='Building Maint'!N13 -> 1010 | Q33: =SUM(E33:P33) -> 20140 | R33: =Q33/$B$4 -> 0.48157624
D34: Building Maint.-Recurring | E34: ='Building Maint'!C6 -> 2115 | F34: ='Building Maint'!D6 -> 2040 | G34: ='Building Maint'!E6 -> 1815 | H34: ='Building Maint'!F6 -> 2215 | I34: ='Building Maint'!G6 -> 4290 | J34: ='Building Maint'!H6 -> 1690 | K34: ='Building Maint'!I6 -> 2385 | L34: ='Building Maint'!J6 -> 1690 | ... P34: ='Building Maint'!N6 -> 1690 | Q34: =SUM(E34:P34) -> 28250 | R34: =Q34/$B$4 -> 0.67549796
D35: Building Maint.-Big Projects | F35: =1.03*1500 -> 1545 | J35: =1.03*15000 -> 15450 | N35: =1.03*1500 -> 1545 | Q35: =SUM(E35:P35) -> 18540 | R35: =Q35/$B$4 -> 0.44331795 | V35: Split systems & Zone lines
A36: 6220-8502 | C36: Building Maintenance | E36: =SUM(E33:E35) -> 4075 | F36: =SUM(F33:F35) -> 5245 | G36: =SUM(G33:G35) -> 3635 | H36: =SUM(H33:H35) -> 4825 | I36: =SUM(I33:I35) -> 5300 | J36: =SUM(J33:J35) -> 18150 | K36: =SUM(K33:K35) -> 4995 | L36: =SUM(L33:L35) -> 2700 | ... Q36: =SUM(Q33:Q35) -> 66930 | R36: =Q36/$B$4 -> 1.6003921 | S36: 40295.41 | T36: =IFERROR(Q36/S36-1,"-") -> 0.66098322
A38: 6330-850 | B38: (SC) | C38: Parking Lot Cleaning | Q38: =SUM(E38:P38) -> 0 | R38: =Q38/$B$4 -> 0
D40: Parking Lot Maint.-Contractual | Q40: =SUM(E40:P40) -> 0 | R40: =Q40/$B$4 -> 0
D41: Parking Lot Maint.-Recurring | E41: ='Parking Lot Maint'!C6 -> 0 | F41: ='Parking Lot Maint'!D6 -> 0 | G41: ='Parking Lot Maint'!E6 -> 0 | H41: ='Parking Lot Maint'!F6 -> 0 | I41: ='Parking Lot Maint'!G6 -> 0 | J41: ='Parking Lot Maint'!H6 -> 0 | K41: ='Parking Lot Maint'!I6 -> 0 | L41: ='Parking Lot Maint'!J6 -> 0 | ... P41: ='Parking Lot Maint'!N6 -> 0 | Q41: =SUM(E41:P41) -> 0 | R41: =Q41/$B$4 -> 0
D42: Parking Lot Maint.-Big Projects | Q42: =SUM(E42:P42) -> 0 | R42: =Q42/$B$4 -> 0
A43: 6330-8502 | C43: Parking Lot Maintenance | E43: =SUM(E40:E42) -> 0 | F43: =SUM(F40:F42) -> 0 | G43: =SUM(G40:G42) -> 0 | H43: =SUM(H40:H42) -> 0 | I43: =SUM(I40:I42) -> 0 | J43: =SUM(J40:J42) -> 0 | K43: =SUM(K40:K42) -> 0 | L43: =SUM(L40:L42) -> 0 | ... Q43: =SUM(Q40:Q42) -> 0 | R43: =Q43/$B$4 -> 0 | S43: 114 | T43: =IFERROR(Q43/S43-1,"-") -> -1
A45: 6370-8502 | C45: Snow Removal | Q45: =SUM(E45:P45) -> 0 | R45: =Q45/$B$4 -> 0 | T45: =IFERROR(Q45/S45-1,"-") -> -
D47: Landscaping-Contractual | Q47: =SUM(E47:P47) -> 0 | R47: =Q47/$B$4 -> 0
D48: Landscaping-Recurring | E48: =Landscaping!C6 -> 0 | F48: =Landscaping!D6 -> 0 | G48: =Landscaping!E6 -> 0 | H48: =Landscaping!F6 -> 0 | I48: =Landscaping!G6 -> 0 | J48: =Landscaping!H6 -> 0 | K48: =Landscaping!I6 -> 0 | L48: =Landscaping!J6 -> 0 | ... P48: =Landscaping!N6 -> 0 | Q48: =SUM(E48:P48) -> 0 | R48: =Q48/$B$4 -> 0
D49: Landscaping-Big Projects | Q49: =SUM(G49:P49) -> 0 | R49: =Q49/$B$4 -> 0
A50: 6380-8502 | C50: Landscaping | E50: =SUM(E47:E49) -> 0 | F50: =SUM(F47:F49) -> 0 | G50: =SUM(G47:G49) -> 0 | H50: =SUM(H47:H49) -> 0 | I50: =SUM(I47:I49) -> 0 | J50: =SUM(J47:J49) -> 0 | K50: =SUM(K47:K49) -> 0 | L50: =SUM(L47:L49) -> 0 | ... Q50: =SUM(Q47:Q49) -> 0 | R50: =Q50/$B$4 -> 0 | S50: 135 | T50: =IFERROR(Q50/S50-1,"-") -> -1
...

Sheet 362
B1: 3620 | J1: =+'JV III Consolidated'!J1 -> Operating Budget | Q1: ='JV III Consolidated'!Q1 -> 46023
J2: =+'JV III Consolidated'!J2 -> Lincoln JV III
Q3: =Q1 -> 46023 | S3: 7/2025 Reprojections
B4: ='Renew & Vac - Rent, TI, LC'!A28 -> 49020 | E4: Jan | F4: Feb | G4: Mar | H4: Apr | I4: May | J4: Jun | K4: Jul | L4: Aug | M4: Sep | N4: Oct | O4: Nov | P4: Dec | Q4: Total | R4: Total PSF | S4: Total | T4: Var. | U4: Input | V4: Notes
D6: Occupancy % | E6: ='Renew & Vac - Rent, TI, LC'!AH31 -> 0.4266 | F6: ='Renew & Vac - Rent, TI, LC'!AI31 -> 0.4266 | G6: ='Renew & Vac - Rent, TI, LC'!AJ31 -> 0.4266 | H6: ='Renew & Vac - Rent, TI, LC'!AK31 -> 0.4266 | I6: ='Renew & Vac - Rent, TI, LC'!AL31 -> 0.4266 | J6: ='Renew & Vac - Rent, TI, LC'!AM31 -> 0.4266 | K6: ='Renew & Vac - Rent, TI, LC'!AN31 -> 0.4266 | L6: ='Renew & Vac - Rent, TI, LC'!AO31 -> 0.4266 | ... P6: ='Renew & Vac - Rent, TI, LC'!AS31 -> 0.4092
D7: Occupancy SF | E7: =$B$4*E6 -> 20911.932 | F7: =$B$4*F6 -> 20911.932 | G7: =$B$4*G6 -> 20911.932 | H7: =$B$4*H6 -> 20911.932 | I7: =$B$4*I6 -> 20911.932 | J7: =$B$4*J6 -> 20911.932 | K7: =$B$4*K6 -> 20911.932 | L7: =$B$4*L6 -> 20911.932 | ... P7: =$B$4*P6 -> 20058.984
B8: Revenues
A10: 4230-8501 | C10: Rental Income - In Place | E10: =SUMIFS('In Place Revenue'!$G:$G,'In Place Revenue'!$A:$A,$B$1,'In Place Revenue'!$H:$H,1) -> 30972.1 | F10: =SUMIFS('In Place Revenue'!$G:$G,'In Place Revenue'!$A:$A,$B$1,'In Place Revenue'!$H:$H,2) -> 30972.1 | G10: =SUMIFS('In Place Revenue'!$G:$G,'In Place Revenue'!$A:$A,$B$1,'In Place Revenue'!$H:$H,3) -> 30972.1 | H10: =SUMIFS('In Place Revenue'!$G:$G,'In Place Revenue'!$A:$A,$B$1,'In Place Revenue'!$H:$H,4) -> 26791.43 | I10: =SUMIFS('In Place Revenue'!$G:$G,'In Place Revenue'!$A:$A,$B$1,'In Place Revenue'!$H:$H,5) -> 25362.26 | J10: =SUMIFS('In Place Revenue'!$G:$G,'In Place Revenue'!$A:$A,$B$1,'In Place Revenue'!$H:$H,6) -> 23467.01 | K10: =SUMIFS('In Place Revenue'!$G:$G,'In Place Revenue'!$A:$A,$B$1,'In Place Revenue'!$H:$H,7) -> 23467.01 | L10: =SUMIFS('In Place Revenue'!$G:$G,'In Place Revenue'!$A:$A,$B$1,'In Place Revenue'!$H:$H,8) -> 23485.55 | M10: =SUMIFS('In Place Revenue'!$G:$G,'In Place Revenue'!$A:$A,$B$1,'In Place Revenue'!$H:$H,9) -> 23772.11 | N10: =SUMIFS('In Place Revenue'!$G:$G,'In Place Revenue'!$A:$A,$B$1,'In Place Revenue'!$H:$H,10) -> 23772.11 | O10: =SUMIFS('In Place Revenue'!$G:$G,'In Place Revenue'!$A:$A,$B$1,'In Place Revenue'!$H:$H,11) -> 23772.11 | P10: =SUMIFS('In Place Revenue'!$G:$G,'In Place Revenue'!$A:$A,$B$1,'In Place Revenue'!$H:$H,12) -> 23772.11 | Q10: =SUM(E10:P10) -> 310578 | R10: =Q10/$B$4 -> 6.3357405 | S10: 403669.53 | T10: =IFERROR((Q10+Q11)/S10-1,"-") -> 0.0072897171 | U10: DW | V10: Home Solutions Realty expected to renew 6/1 but at a reduced rent ($18.50 from $19.00)
A11: 4230-8501 | C11: Rental Income - New & Renewal | E11: ='Renew & Vac - Rent, TI, LC'!AH32 -> 2962.875 | F11: ='Renew & Vac - Rent, TI, LC'!AI32 -> 2962.875 | G11: ='Renew & Vac - Rent, TI, LC'!AJ32 -> 2962.875 | H11: ='Renew & Vac - Rent, TI, LC'!AK32 -> 7058.9583 | I11: ='Renew & Vac - Rent, TI, LC'!AL32 -> 8569.7917 | J11: ='Renew & Vac - Rent, TI, LC'!AM32 -> 10415.167 | K11: ='Renew & Vac - Rent, TI, LC'!AN32 -> 10415.167 | L11: ='Renew & Vac - Rent, TI, LC'!AO32 -> 10415.167 | ... P11: ='Renew & Vac - Rent, TI, LC'!AS32 -> 9025.7917 | Q11: =SUM(E11:P11) -> 96034.167 | R11: =Q11/$B$4 -> 1.9590813 | T11: =IFERROR(Q11/S11-1,"-") -> -
A12: 4240-8501 | C12: Percentage Rent | E12: 0 | F12: 0 | G12: 0 | H12: 0 | I12: 0 | J12: 0 | K12: 0 | L12: 0 | M12: 0 | N12: 0 | O12: 0 | P12: 0 | Q12: =SUM(E12:P12) -> 0 | R12: =Q12/$B$4 -> 0 | T12: =R12/S12-1 -> #DIV/0! | W12: =G12-H12 -> 0
A13: 4990-8501 | C13: Miscellaneous | E13: 0 | F13: 0 | G13: 0 | H13: 0 | I13: 0 | J13: 0 | K13: 0 | L13: 0 | M13: 0 | N13: 0 | O13: 0 | P13: 0 | Q13: =SUM(E13:P13) -> 0 | R13: =Q13/$B$4 -> 0 | T13: =IFERROR(Q13/S13-1,"-") -> -
A14: 9190-8501 | C14: Interest Income | E14: 0 | F14: 0 | G14: 0 | H14: 0 | I14: 0 | J14: 0 | K14: 0 | L14: 0 | M14: 0 | N14: 0 | O14: 0 | P14: 0 | Q14: =SUM(E14:P14) -> 0 | R14: =Q14/$B$4 -> 0 | T14: =IFERROR(Q14/S14-1,"-") -> -
C15: Total Rental and Other | E15: =SUM(E10:E14) -> 33934.975 | F15: =SUM(F10:F14) -> 33934.975 | G15: =SUM(G10:G14) -> 33934.975 | H15: =SUM(H10:H14) -> 33850.388 | I15: =SUM(I10:I14) -> 33932.052 | J15: =SUM(J10:J14) -> 33882.177 | K15: =SUM(K10:K14) -> 33882.177 | L15: =SUM(L10:L14) -> 33900.717 | ... Q15: =SUM(Q10:Q14) -> 406612.17 | R15: =Q15/$B$4 -> 8.2948218 | S15: =SUM(S10:S14) -> 403669.53 | T15: =IFERROR(Q15/S15-1,"-") -> 0.0072897171
B17: Reimbursements
A18: 4710-8502 | C18: Electric | E18: =E6*E29 -> 2270.7918 | F18: =F6*F29 -> 2138.5458 | G18: =G6*G29 -> 1749.06 | H18: =H6*H29 -> 1174.8564 | I18: =I6*I29 -> 1109.5866 | J18: =J6*J29 -> 1199.1726 | K18: =K6*K29 -> 1457.2656 | L18: =L6*L29 -> 1546.8516 | ... P18: =P6*P29 -> 2027.586 | Q18: =SUM(E18:P18) -> 18526.768 | R18: =Q18/$B$4 -> 0.37794304 | S18: 24752.02 | T18: =IFERROR(Q18/S18-1,"-") -> -0.25150482 | U18: DW | V18: =Q18/Q29*100&"% Set to occupancy" -> 42.4623950860627% Set to occupancy
A19: 4910-8502 | C19: Common Area Maintenance | E19: =+'Tenant Recoveries'!G21 -> 1900 | F19: =+E19 -> 1900 | G19: =+F19 -> 1900 | H19: =+G19 -> 1900 | I19: =+H19 -> 1900 | J19: =+I19 -> 1900 | K19: =+J19 -> 1900 | L19: =+K19 -> 1900 | M19: =+L19 -> 1900 | ... P19: =+O19 -> 1900 | Q19: =SUM(E19:P19) -> 22800 | R19: =Q19/$B$4 -> 0.46511628 | S19: 20384 | T19: =IFERROR(Q19/S19-1,"-") -> 0.11852433 | V19: =Q19/(Q71-Q63-Q58-Q29) -> 0.11547064
A20: 4920-8502 | C20: Real Estate Taxes | E20: =+'Tenant Recoveries'!G22 -> 200 | F20: =+E20 -> 200 | G20: =+F20 -> 200 | H20: =+G20 -> 200 | I20: =+H20 -> 200 | J20: =+I20 -> 200 | K20: =+J20 -> 200 | L20: =+K20 -> 200 | M20: =+L20 -> 200 | ... P20: =+O20 -> 200 | Q20: =SUM(E20:P20) -> 2400 | R20: =Q20/$B$4 -> 0.048959608 | S20: 2760 | T20: =IFERROR(Q20/S20-1,"-") -> -0.13043478 | V20: =Q20/Q58 -> 0.056345444
A21: 4930-8502 | C21: Insurance | Q21: =SUM(E21:P21) -> 0 | R21: =Q21/$B$4 -> 0 | T21: =IFERROR(Q21/S21-1,"-") -> -
C22: Total Reimbursements | E22: =SUM(E18:E21) -> 4370.7918 | F22: =SUM(F18:F21) -> 4238.5458 | G22: =SUM(G18:G21) -> 3849.06 | H22: =SUM(H18:H21) -> 3274.8564 | I22: =SUM(I18:I21) -> 3209.5866 | J22: =SUM(J18:J21) -> 3299.1726 | K22: =SUM(K18:K21) -> 3557.2656 | L22: =SUM(L18:L21) -> 3646.8516 | ... Q22: =SUM(Q18:Q21) -> 43726.768 | R22: =Q22/$B$4 -> 0.89201892 | S22: =SUM(S18:S21) -> 47896.02 | T22: =IFERROR(Q22/S22-1,"-") -> -0.087047993
R23: =Q23/$B$4 -> 0
B24: TOTAL REVENUES | E24: =+E15+E22 -> 38305.767 | F24: =+F15+F22 -> 38173.521 | G24: =+G15+G22 -> 37784.035 | H24: =+H15+H22 -> 37125.245 | I24: =+I15+I22 -> 37141.638 | J24: =+J15+J22 -> 37181.349 | K24: =+K15+K22 -> 37439.442 | L24: =+L15+L22 -> 37547.568 | ... Q24: =+Q15+Q22 -> 450338.93 | R24: =Q24/$B$4 -> 9.1868408 | S24: =+S15+S22 -> 451565.55 | T24: =IFERROR(Q24/S24-1,"-") -> -0.0027163625
B26: Reimbursable Expenses
A27: 6030-8502 | C27: Maintenance Salaries | E27: ='Allocated Expenses'!E5 -> 1376.0833 | F27: ='Allocated Expenses'!F5 -> 1376.0833 | G27: ='Allocated Expenses'!G5 -> 1376.0833 | H27: ='Allocated Expenses'!H5 -> 1376.0833 | I27: ='Allocated Expenses'!I5 -> 1376.0833 | J27: ='Allocated Expenses'!J5 -> 1376.0833 | K27: ='Allocated Expenses'!K5 -> 1376.0833 | L27: ='Allocated Expenses'!L5 -> 1376.0833 | ... P27: ='Allocated Expenses'!P5 -> 1376.0833 | Q27: =SUM(E27:P27) -> 16513 | R27: =Q27/$B$4 -> 0.33686251 | S27: 10684.65 | T27: =IFERROR(Q27/S27-1,"-") -> 0.54548815
A29: 6120-8502 | C29: Electric | E29: 5323 | F29: 5013 | G29: 4100 | H29: 2754 | I29: 2601 | J29: 2811 | K29: 3416 | L29: 3626 | M29: 3014 | N29: 2860 | O29: 3158 | P29: 4955 | Q29: =SUM(E29:P29) -> 43631 | R29: =Q29/$B$4 -> 0.89006528 | S29: 41563.41 | T29: =IFERROR(Q29/S29-1,"-") -> 0.049745437 | U29: DW | V29: Data\Shared\Properties\Business Plans - All Entities\2026\ISG Electric data
A31: 6130-8502 | C31: Water & Sewer | E31: ='Water Sewer'!D14 -> 1320.46 | F31: ='Water Sewer'!E14 -> 1207.16 | G31: ='Water Sewer'!F14 -> 1658.3 | H31: ='Water Sewer'!G14 -> 259.56 | I31: ='Water Sewer'!H14 -> 259.56 | J31: ='Water Sewer'!I14 -> 445.99 | K31: ='Water Sewer'!J14 -> 616.97 | L31: ='Water Sewer'!K14 -> 697.31 | ... P31: ='Water Sewer'!O14 -> 1413.16 | Q31: =SUM(E31:P31) -> 10220.69 | R31: =Q31/$B$4 -> 0.20850041 | S31: 9618.34 | T31: =IFERROR(Q31/S31-1,"-") -> 0.062625152 | V31: 2025 Business Plan grown 3%
D33: Building Maint.-Contractual | E33: ='Building Maint'!C14 -> 1931 | F33: ='Building Maint'!D14 -> 1756 | G33: ='Building Maint'!E14 -> 1006 | H33: ='Building Maint'!F14 -> 2792 | I33: ='Building Maint'!G14 -> 1756 | J33: ='Building Maint'!H14 -> 1006 | K33: ='Building Maint'!I14 -> 1931 | L33: ='Building Maint'!J14 -> 1756 | ... P33: ='Building Maint'!N14 -> 1006 | Q33: =SUM(E33:P33) -> 20494 | R33: =Q33/$B$4 -> 0.41807426
D34: Building Maint.-Recurring | E34: ='Building Maint'!C7 -> 2115 | F34: ='Building Maint'!D7 -> 2090 | G34: ='Building Maint'!E7 -> 1815 | H34: ='Building Maint'!F7 -> 2215 | I34: ='Building Maint'!G7 -> 4290 | J34: ='Building Maint'!H7 -> 1965 | K34: ='Building Maint'!I7 -> 2115 | L34: ='Building Maint'!J7 -> 1690 | ... P34: ='Building Maint'!N7 -> 1790 | Q34: =SUM(E34:P34) -> 28185 | R34: =Q34/$B$4 -> 0.5749694
D35: Building Maint.-Big Projects | F35: =1.03*1500 -> 1545 | J35: =1.03*15000 -> 15450 | N35: =1.03*1500 -> 1545 | Q35: =SUM(E35:P35) -> 18540 | R35: =Q35/$B$4 -> 0.37821297
A36: 6220-8502 | C36: Building Maintenance | E36: =SUM(E33:E35) -> 4046 | F36: =SUM(F33:F35) -> 5391 | G36: =SUM(G33:G35) -> 2821 | H36: =SUM(H33:H35) -> 5007 | I36: =SUM(I33:I35) -> 6046 | J36: =SUM(J33:J35) -> 18421 | K36: =SUM(K33:K35) -> 4046 | L36: =SUM(L33:L35) -> 3446 | ... Q36: =SUM(Q33:Q35) -> 67219 | R36: =Q36/$B$4 -> 1.3712566 | S36: 42613.28 | T36: =IFERROR(Q36/S36-1,"-") -> 0.57741906
A38: 6330-850 | B38: (SC) | C38: Parking Lot Cleaning | Q38: =SUM(E38:P38) -> 0 | R38: =Q38/$B$4 -> 0
D40: Parking Lot Maint.-Contractual | Q40: =SUM(E40:P40) -> 0 | R40: =Q40/$B$4 -> 0
D41: Parking Lot Maint.-Recurring | E41: ='Parking Lot Maint'!C7 -> 0 | F41: ='Parking Lot Maint'!D7 -> 0 | G41: ='Parking Lot Maint'!E7 -> 0 | H41: ='Parking Lot Maint'!F7 -> 0 | I41: ='Parking Lot Maint'!G7 -> 0 | J41: ='Parking Lot Maint'!H7 -> 0 | K41: ='Parking Lot Maint'!I7 -> 0 | L41: ='Parking Lot Maint'!J7 -> 0 | ... P41: ='Parking Lot Maint'!N7 -> 0 | Q41: =SUM(E41:P41) -> 0 | R41: =Q41/$B$4 -> 0
D42: Parking Lot Maint.-Big Projects | Q42: =SUM(E42:P42) -> 0 | R42: =Q42/$B$4 -> 0
A43: 6330-8502 | C43: Parking Lot Maintenance | E43: =SUM(E40:E42) -> 0 | F43: =SUM(F40:F42) -> 0 | G43: =SUM(G40:G42) -> 0 | H43: =SUM(H40:H42) -> 0 | I43: =SUM(I40:I42) -> 0 | J43: =SUM(J40:J42) -> 0 | K43: =SUM(K40:K42) -> 0 | L43: =SUM(L40:L42) -> 0 | ... Q43: =SUM(Q40:Q42) -> 0 | R43: =Q43/$B$4 -> 0 | S43: 400 | T43: =IFERROR(Q43/S43-1,"-") -> -1
A45: 6370-8502 | C45: Snow Removal | Q45: =SUM(E45:P45) -> 0 | R45: =Q45/$B$4 -> 0 | T45: =IFERROR(Q45/S45-1,"-") -> -
Q46: =SUM(E46:P46) -> 0
D47: Landscaping-Contractual | Q47: =SUM(E47:P47) -> 0 | R47: =Q47/$B$4 -> 0
D48: Landscaping-Recurring | E48: =Landscaping!C7 -> 0 | F48: =Landscaping!D7 -> 0 | G48: =Landscaping!E7 -> 0 | H48: =Landscaping!F7 -> 0 | I48: =Landscaping!G7 -> 0 | J48: =Landscaping!H7 -> 0 | K48: =Landscaping!I7 -> 0 | L48: =Landscaping!J7 -> 0 | ... P48: =Landscaping!N7 -> 0 | Q48: =SUM(E48:P48) -> 0 | R48: =Q48/$B$4 -> 0
D49: Landscaping-Big Projects | Q49: =SUM(E49:P49) -> 0 | R49: =Q49/$B$4 -> 0
A50: 6380-8502 | C50: Landscaping | E50: =SUM(E47:E49) -> 0 | F50: =SUM(F47:F49) -> 0 | G50: =SUM(G47:G49) -> 0 | H50: =SUM(H47:H49) -> 0 | I50: =SUM(I47:I49) -> 0 | J50: =SUM(J47:J49) -> 0 | K50: =SUM(K47:K49) -> 0 | L50: =SUM(L47:L49) -> 0 | ... Q50: =SUM(Q47:Q49) -> 0 | R50: =Q50/$B$4 -> 0 | S50: 158 | T50: =IFERROR(Q50/S50-1,"-") -> -1
...

Sheet 364
B1: 3640 | J1: =+'362'!J1 -> Operating Budget | Q1: ='JV III Consolidated'!Q1 -> 46023
J2: =+'362'!J2 -> Lincoln JV III
Q3: =Q1 -> 46023 | S3: 7/2025 Reprojections
B4: ='Renew & Vac - Rent, TI, LC'!A50 -> 48794 | E4: Jan | F4: Feb | G4: Mar | H4: Apr | I4: May | J4: Jun | K4: Jul | L4: Aug | M4: Sep | N4: Oct | O4: Nov | P4: Dec | Q4: Total | R4: Total PSF | S4: Total | T4: Var. | U4: Input | V4: Notes
D6: Occupancy % | E6: ='Renew & Vac - Rent, TI, LC'!AH53 -> 0.8233 | F6: ='Renew & Vac - Rent, TI, LC'!AI53 -> 0.8233 | G6: ='Renew & Vac - Rent, TI, LC'!AJ53 -> 0.8233 | H6: ='Renew & Vac - Rent, TI, LC'!AK53 -> 0.6717 | I6: ='Renew & Vac - Rent, TI, LC'!AL53 -> 0.6717 | J6: ='Renew & Vac - Rent, TI, LC'!AM53 -> 0.6717 | K6: ='Renew & Vac - Rent, TI, LC'!AN53 -> 0.6717 | L6: ='Renew & Vac - Rent, TI, LC'!AO53 -> 0.6717 | ... P6: ='Renew & Vac - Rent, TI, LC'!AS53 -> 0.4449
D7: Occupancy SF | E7: =$B$4*E6 -> 40172.1 | F7: =$B$4*F6 -> 40172.1 | G7: =$B$4*G6 -> 40172.1 | H7: =$B$4*H6 -> 32774.93 | I7: =$B$4*I6 -> 32774.93 | J7: =$B$4*J6 -> 32774.93 | K7: =$B$4*K6 -> 32774.93 | L7: =$B$4*L6 -> 32774.93 | ... P7: =$B$4*P6 -> 21708.451
B8: Revenues
A10: 4230-8501 | C10: Rental Income - In Place | E10: =SUMIFS('In Place Revenue'!$G:$G,'In Place Revenue'!$A:$A,$B$1,'In Place Revenue'!$H:$H,1) -> 61074.26 | F10: =SUMIFS('In Place Revenue'!$G:$G,'In Place Revenue'!$A:$A,$B$1,'In Place Revenue'!$H:$H,2) -> 61074.26 | G10: =SUMIFS('In Place Revenue'!$G:$G,'In Place Revenue'!$A:$A,$B$1,'In Place Revenue'!$H:$H,3) -> 58357.59 | H10: =SUMIFS('In Place Revenue'!$G:$G,'In Place Revenue'!$A:$A,$B$1,'In Place Revenue'!$H:$H,4) -> 46332.59 | I10: =SUMIFS('In Place Revenue'!$G:$G,'In Place Revenue'!$A:$A,$B$1,'In Place Revenue'!$H:$H,5) -> 46332.59 | J10: =SUMIFS('In Place Revenue'!$G:$G,'In Place Revenue'!$A:$A,$B$1,'In Place Revenue'!$H:$H,6) -> 46332.59 | K10: =SUMIFS('In Place Revenue'!$G:$G,'In Place Revenue'!$A:$A,$B$1,'In Place Revenue'!$H:$H,7) -> 36784.42 | L10: =SUMIFS('In Place Revenue'!$G:$G,'In Place Revenue'!$A:$A,$B$1,'In Place Revenue'!$H:$H,8) -> 42087.67 | M10: =SUMIFS('In Place Revenue'!$G:$G,'In Place Revenue'!$A:$A,$B$1,'In Place Revenue'!$H:$H,9) -> 42087.67 | N10: =SUMIFS('In Place Revenue'!$G:$G,'In Place Revenue'!$A:$A,$B$1,'In Place Revenue'!$H:$H,10) -> 28542.92 | O10: =SUMIFS('In Place Revenue'!$G:$G,'In Place Revenue'!$A:$A,$B$1,'In Place Revenue'!$H:$H,11) -> 27121.5 | P10: =SUMIFS('In Place Revenue'!$G:$G,'In Place Revenue'!$A:$A,$B$1,'In Place Revenue'!$H:$H,12) -> 32308.5 | Q10: =SUM(E10:P10) -> 528436.56 | R10: =Q10/$B$4 -> 10.82995 | S10: 755719.63 | T10: =IFERROR((Q10+Q11)/S10-1,"-") -> -0.18757944
A11: 4230-8501 | C11: Rental Income - New & Renewal | E11: ='Renew & Vac - Rent, TI, LC'!AH54 -> 3957.5449 | F11: ='Renew & Vac - Rent, TI, LC'!AI54 -> 3957.5449 | G11: ='Renew & Vac - Rent, TI, LC'!AJ54 -> 6674.2116 | H11: ='Renew & Vac - Rent, TI, LC'!AK54 -> 6674.8282 | I11: ='Renew & Vac - Rent, TI, LC'!AL54 -> 6674.8282 | J11: ='Renew & Vac - Rent, TI, LC'!AM54 -> 6674.8282 | K11: ='Renew & Vac - Rent, TI, LC'!AN54 -> 9171.2033 | L11: ='Renew & Vac - Rent, TI, LC'!AO54 -> 9171.2033 | ... P11: ='Renew & Vac - Rent, TI, LC'!AS54 -> 8273.2083 | Q11: =SUM(E11:P11) -> 85525.604 | R11: =Q11/$B$4 -> 1.7527894 | T11: =IFERROR(Q11/S11-1,"-") -> -
A12: 4240-8501 | C12: Percentage Rents | E12: 0 | F12: 0 | G12: 0 | H12: 0 | I12: 0 | J12: 0 | K12: 0 | L12: 0 | M12: 0 | N12: 0 | O12: 0 | P12: 0 | Q12: =SUM(E12:P12) -> 0 | R12: =Q12/$B$4 -> 0 | T12: =R12/S12-1 -> #DIV/0!
A13: 4990-8501 | C13: Miscellaneous | E13: 0 | F13: 0 | G13: 0 | H13: 0 | I13: 0 | J13: 0 | K13: 0 | L13: 0 | M13: 0 | N13: 0 | O13: 0 | P13: 0 | Q13: =SUM(E13:P13) -> 0 | R13: =Q13/$B$4 -> 0 | T13: =IFERROR(Q13/S13-1,"-") -> -
A14: 9190-8501 | C14: Interest Income | E14: 0 | F14: 0 | G14: 0 | H14: 0 | I14: 0 | J14: 0 | K14: 0 | L14: 0 | M14: 0 | N14: 0 | O14: 0 | P14: 0 | Q14: =SUM(E14:P14) -> 0 | R14: =Q14/$B$4 -> 0 | T14: =IFERROR(Q14/S14-1,"-") -> -
C15: Total Rental and Other | E15: =SUM(E10:E14) -> 65031.805 | F15: =SUM(F10:F14) -> 65031.805 | G15: =SUM(G10:G14) -> 65031.802 | H15: =SUM(H10:H14) -> 53007.418 | I15: =SUM(I10:I14) -> 53007.418 | J15: =SUM(J10:J14) -> 53007.418 | K15: =SUM(K10:K14) -> 45955.623 | L15: =SUM(L10:L14) -> 51258.873 | ... Q15: =SUM(Q10:Q14) -> 613962.16 | R15: =Q15/$B$4 -> 12.582739 | S15: =SUM(S10:S14) -> 755719.63 | T15: =IFERROR(Q15/S15-1,"-") -> -0.18757944
B17: Reimbursements
A18: 4710-8502 | C18: Electric | E18: =E6*E29 -> 3502.3182 | F18: =F6*F29 -> 3048.6799 | G18: =G6*G29 -> 2678.1949 | H18: =H6*H29 -> 1599.9894 | I18: =I6*I29 -> 1462.9626 | J18: =J6*J29 -> 1455.5739 | K18: =K6*K29 -> 1613.4234 | L18: =L6*L29 -> 1528.7892 | ... P18: =P6*P29 -> 1613.2074 | Q18: =SUM(E18:P18) -> 21811.331 | R18: =Q18/$B$4 -> 0.44700846 | S18: 29665.83 | T18: =IFERROR(Q18/S18-1,"-") -> -0.26476586 | U18: DW | V18: =Q18/Q29*100&"% Set to occupancy" -> 66.7625681052954% Set to occupancy
A19: 4910-8502 | C19: Common Area Maintenance | E19: =+'Tenant Recoveries'!H21 -> 1500 | F19: =+E19 -> 1500 | G19: =+F19 -> 1500 | H19: =+G19 -> 1500 | I19: =+H19 -> 1500 | J19: =+I19 -> 1500 | K19: =+J19 -> 1500 | L19: =+K19 -> 1500 | M19: =+L19 -> 1500 | ... P19: =+O19 -> 1500 | Q19: =SUM(E19:P19) -> 18000 | R19: =Q19/$B$4 -> 0.36889782 | S19: 16600 | T19: =IFERROR(Q19/S19-1,"-") -> 0.084337349 | V19: =Q19/(Q71-Q63-Q58-Q29) -> 0.075648896
A20: 4920-8502 | C20: Real Estate Taxes | E20: =+'Tenant Recoveries'!H22 -> 230 | F20: =+E20 -> 230 | G20: =+F20 -> 230 | H20: =+G20 -> 230 | I20: =+H20 -> 230 | J20: =+I20 -> 230 | K20: =+J20 -> 230 | L20: =+K20 -> 230 | M20: =+L20 -> 230 | ... P20: =+O20 -> 230 | Q20: =SUM(E20:P20) -> 2760 | R20: =Q20/$B$4 -> 0.056564332 | S20: 5040 | T20: =IFERROR(Q20/S20-1,"-") -> -0.45238095 | V20: =Q20/Q58 -> 0.051197835
A21: 4930-8502 | C21: Insurance | Q21: =SUM(E21:P21) -> 0 | R21: =Q21/$B$4 -> 0 | T21: =IFERROR(Q21/S21-1,"-") -> -
C22: Total Reimbursements | E22: =SUM(E18:E21) -> 5232.3182 | F22: =SUM(F18:F21) -> 4778.6799 | G22: =SUM(G18:G21) -> 4408.1949 | H22: =SUM(H18:H21) -> 3329.9894 | I22: =SUM(I18:I21) -> 3192.9626 | J22: =SUM(J18:J21) -> 3185.5739 | K22: =SUM(K18:K21) -> 3343.4234 | L22: =SUM(L18:L21) -> 3258.7892 | ... Q22: =SUM(Q18:Q21) -> 42571.331 | R22: =Q22/$B$4 -> 0.87247061 | S22: =SUM(S18:S21) -> 51305.83 | T22: =IFERROR(Q22/S22-1,"-") -> -0.17024379
R23: =Q23/$B$4 -> 0
B24: TOTAL REVENUES | E24: =+E15+E22 -> 70264.123 | F24: =+F15+F22 -> 69810.485 | G24: =+G15+G22 -> 69439.996 | H24: =+H15+H22 -> 56337.408 | I24: =+I15+I22 -> 56200.381 | J24: =+J15+J22 -> 56192.992 | K24: =+K15+K22 -> 49299.047 | L24: =+L15+L22 -> 54517.662 | ... Q24: =+Q15+Q22 -> 656533.5 | R24: =Q24/$B$4 -> 13.45521 | S24: =+S15+S22 -> 807025.46 | T24: =IFERROR(Q24/S24-1,"-") -> -0.18647734 | V24: Solaray - $108,225; SEOM - $39,439 | W24: =+S24-Q24 -> 150491.96
V25: $147,664 combined
B26: Reimbursable Expenses
A27: 6030-8502 | C27: Maintenance Salaries | E27: ='Allocated Expenses'!E6 -> 1376.0833 | F27: ='Allocated Expenses'!F6 -> 1376.0833 | G27: ='Allocated Expenses'!G6 -> 1376.0833 | H27: ='Allocated Expenses'!H6 -> 1376.0833 | I27: ='Allocated Expenses'!I6 -> 1376.0833 | J27: ='Allocated Expenses'!J6 -> 1376.0833 | K27: ='Allocated Expenses'!K6 -> 1376.0833 | L27: ='Allocated Expenses'!L6 -> 1376.0833 | ... P27: ='Allocated Expenses'!P6 -> 1376.0833 | Q27: =SUM(E27:P27) -> 16513 | R27: =Q27/$B$4 -> 0.33842276 | S27: 11212.8 | T27: =IFERROR(Q27/S27-1,"-") -> 0.47269192
A29: 6120-8502 | C29: Electric | E29: 4254 | F29: 3703 | G29: 3253 | H29: 2382 | I29: 2178 | J29: 2167 | K29: 2402 | L29: 2276 | M29: 1975 | N29: 1964 | O29: 2490 | P29: 3626 | Q29: =SUM(E29:P29) -> 32670 | R29: =Q29/$B$4 -> 0.66954953 | S29: 34280.3 | T29: =IFERROR(Q29/S29-1,"-") -> -0.046974501 | U29: DW | V29: Data\Shared\Properties\Business Plans - All Entities\2026\ISG Electric data
A31: 6130-8502 | C31: Water & Sewer | E31: ='Water Sewer'!D19 -> 879.62 | F31: ='Water Sewer'!E19 -> 872.41 | G31: ='Water Sewer'!F19 -> 890.95 | H31: ='Water Sewer'!G19 -> 885.8 | I31: ='Water Sewer'!H19 -> 924.94 | J31: ='Water Sewer'!I19 -> 842.54 | K31: ='Water Sewer'!J19 -> 923.91 | L31: ='Water Sewer'!K19 -> 912.58 | ... P31: ='Water Sewer'!O19 -> 992.92 | Q31: =SUM(E31:P31) -> 11162.11 | R31: =Q31/$B$4 -> 0.22875989 | S31: 11254.54 | T31: =IFERROR(Q31/S31-1,"-") -> -0.0082126857 | V31: 2025 Business Plan grown 3%
D33: Building Maint.-Contractual | E33: ='Building Maint'!C15 -> 1766 | F33: ='Building Maint'!D15 -> 1566 | G33: ='Building Maint'!E15 -> 816 | H33: ='Building Maint'!F15 -> 2627 | I33: ='Building Maint'!G15 -> 1566 | J33: ='Building Maint'!H15 -> 816 | K33: ='Building Maint'!I15 -> 1766 | L33: ='Building Maint'!J15 -> 1566 | ... P33: ='Building Maint'!N15 -> 816 | Q33: =SUM(E33:P33) -> 18314 | R33: =Q33/$B$4 -> 0.37533303
