Workbook
Name PaiementsParAn: 'Water Sewer'!$F$6
Name PaiementsParAn: 'INS RET'!$G$6
Name pmtType: 'INS RET'!$F$20
Name pmtType: 'Water Sewer'!$E$18
Name rate: 'INS RET'!$J$6
Name rate: 'Water Sewer'!$I$6
Name roundOpt: 'INS RET'!$F$24
Name roundOpt: 'Water Sewer'!$E$21
Name TauxIntérêt: 'Water Sewer'!$F$3
Name TauxIntérêt: 'INS RET'!$G$3

Sheet Cover Sheet
A1: ='NI LLC-Consolidated'!J1 -> Operating Budget
A2: ='NI LLC-Consolidated'!J2 -> Neshaminy Interplex LLC
A3: ='NI LLC-Consolidated'!Q1 -> 46023

Sheet Source and Use of Cash
A1: NESHAMINY INTERPELX LLC
A2: Summary Source and Use of Cash for 2026 Budget
B5: CASH FLOW AFTER INTEREST ON DEBT SERVICE | E5: =+'NI LLC-Consolidated'!Q134 -> 297244 | F5: TI costs for 2025 are included in this defecit
B7: ADD: Operating Cash 01/01/2026 | E7: =+'NI LLC-Consolidated'!D139 -> 395118.24 | F7: From 2025 reprojections at end of August
B9: LESS: Monthly Contributions to TI Escrow | E9: 0 | F9: Request no TI contributions for 2026
A11: {A} | B11: ADD: TI Improvements and LC Costs | E11: =+'NI LLC-Consolidated'!Q144+'NI LLC-Consolidated'!Q146 -> 180992.97 | F11: To be funded by balances in TI Reserve
C13: Cash Balance, 31 December 2026 | E13: =SUM(E5:E11) -> 873355.21
A15: {A} | B15: Summary of TI Allowance Escrow:
C17: 46022 | D17: Projected Balance, | E17: =+'NI LLC-Consolidated'!D152 -> 364692
B18: LESS: TI Improvements and Lease Costs year 2026 | E18: =-E11 -> -180992.97
C20: Remaining Balance, TI Escrow | E20: =+E17+E18 -> 183699.03
C22: Balance of TI Escrow 31 Dec 2026 | E22: =+E20+E21 -> 183699.03 | F22: Request funds if needed for any shortfalls
A25: {B} | B25: USE OF DEBT SRVICE ESTROW TRUST FUNDS
C27: 45966 | D27: Per Bank Statement | E27: 2015700
D28: ADD Interest Earnings:
D29: Estimated Interest Nov & Dec 2025 | E29: 12200
D30: Estimated Interest Year 2026 | E30: 73500
D32: Total Available | E32: =SUM(E27:E31) -> 2101400
D33: Initial Escrow Deposit | E33: -1840516
D34: Interest Earnings Available | E34: =+E32+E33 -> 260883.99 | F34: {With permission from Trustees}
C36: FOR INTERNAL DISCUSSION POINTS ONLY
B37: Other Options:
B38: 1 | C38: Discuss lower interest rate
C39: May result in some element of Cash Management as previously proposed by Liberty.
C40: (This was NI LLC determing what excess cash was available to remit to Bank - not
C41: the normal Bank Cash Management). May require more complexities in structuring
C42: at this time.
B44: 2 | C44: Use of Debt Service Escrow
C45: This may be better used for year 2027.
B47: 3 | C47: Potential sale or re-purpose of the Interplex.

Sheet Assumptions
B1: Budget Assumptions | E1: ='NI LLC-Consolidated'!Q1 -> 46023
B2: ='NI LLC-Consolidated'!J2 -> Neshaminy Interplex LLC
B6: Account Code | C6: Description | D6: Assumption / Notes
B7: Revenues
B8: ='NI LLC-Consolidated'!A10 -> 4230-8501 | C8: =IFERROR(VLOOKUP($B8,'NI LLC-Consolidated'!$A$10:$U$155,3,FALSE),"") -> Rental Income - In Place | D8: =IFERROR(VLOOKUP($B8,'NI LLC-Consolidated'!$A$10:$U$155,21,FALSE),"") -> 0
B9: ='NI LLC-Consolidated'!A11 -> 4230-8501 | C9: ='NI LLC-Consolidated'!C11 -> Rental Income - New & Renewal | D9: =IFERROR(VLOOKUP($B9,'NI LLC-Consolidated'!$A$10:$U$155,21,FALSE),"") -> 0
B10: ='NI LLC-Consolidated'!A12 -> 4240-8501 | C10: ='NI LLC-Consolidated'!C12 -> Percentage Rents | D10: =IFERROR(VLOOKUP($B10,'NI LLC-Consolidated'!$A$10:$U$155,21,FALSE),"") -> 0
B11: ='NI LLC-Consolidated'!A13 -> 4990-8501 | C11: =IFERROR(VLOOKUP($B11,'NI LLC-Consolidated'!$A$10:$U$155,3,FALSE),"") -> Miscellaneous | D11: =IFERROR(VLOOKUP($B11,'NI LLC-Consolidated'!$A$10:$U$155,21,FALSE),"") -> Gym Fees and $5K/qtr for Billboard (Applied to 4080)
B12: ='NI LLC-Consolidated'!A14 -> 9190-8501 | C12: =IFERROR(VLOOKUP($B12,'NI LLC-Consolidated'!$A$10:$U$155,3,FALSE),"") -> Interest Income | D12: =IFERROR(VLOOKUP($B12,'NI LLC-Consolidated'!$A$10:$U$155,21,FALSE),"") -> Annualized one month of interest from recent statement (Applied to 4050)
B13: Reimbursements | D13: =IFERROR(VLOOKUP($B13,'NI LLC-Consolidated'!$A$10:$U$155,21,FALSE),"")
B14: ='NI LLC-Consolidated'!A18 -> 4710-8502 | C14: =IFERROR(VLOOKUP($B14,'NI LLC-Consolidated'!$A$10:$U$155,3,FALSE),"") -> Electric | D14: =IFERROR(VLOOKUP($B14,'NI LLC-Consolidated'!$A$10:$U$155,21,FALSE),"") -> Set to occupancy
B15: ='NI LLC-Consolidated'!A19 -> 4910-8502 | C15: =IFERROR(VLOOKUP($B15,'NI LLC-Consolidated'!$A$10:$U$155,3,FALSE),"") -> Common Area Maintenance | D15: =IFERROR(VLOOKUP($B15,'NI LLC-Consolidated'!$A$10:$U$155,21,FALSE),"") -> 0
B16: ='NI LLC-Consolidated'!A20 -> 4920-8502 | C16: =IFERROR(VLOOKUP($B16,'NI LLC-Consolidated'!$A$10:$U$155,3,FALSE),"") -> Real Estate Taxes | D16: =IFERROR(VLOOKUP($B16,'NI LLC-Consolidated'!$A$10:$U$155,21,FALSE),"") -> 0
B17: ='NI LLC-Consolidated'!A21 -> 4930-8502 | C17: =IFERROR(VLOOKUP($B17,'NI LLC-Consolidated'!$A$10:$U$155,3,FALSE),"") -> Insurance | D17: =IFERROR(VLOOKUP($B17,'NI LLC-Consolidated'!$A$10:$U$155,21,FALSE),"") -> 0
B18: Reimbursable Expenses | D18: =IFERROR(VLOOKUP($B18,'NI LLC-Consolidated'!$A$10:$U$155,21,FALSE),"")
B19: ='NI LLC-Consolidated'!A27 -> 6030-8502 | C19: =IFERROR(VLOOKUP($B19,'NI LLC-Consolidated'!$A$10:$U$155,3,FALSE),"") -> Maintenance Salaries | D19: =IFERROR(VLOOKUP($B19,'NI LLC-Consolidated'!$A$10:$U$155,21,FALSE),"") -> Based on 2026 Payroll Budget
B20: ='NI LLC-Consolidated'!A29 -> 6120-8502 | C20: =IFERROR(VLOOKUP($B20,'NI LLC-Consolidated'!$A$10:$U$155,3,FALSE),"") -> Electric | D20: =IFERROR(VLOOKUP($B20,'NI LLC-Consolidated'!$A$10:$U$155,21,FALSE),"") -> Data\Shared\Properties\Business Plans - All Entities\2026\ISG Electric data
B21: ='NI LLC-Consolidated'!A31 -> 6130-8502 | C21: =IFERROR(VLOOKUP($B21,'NI LLC-Consolidated'!$A$10:$U$155,3,FALSE),"") -> Water & Sewer | D21: =IFERROR(VLOOKUP($B21,'NI LLC-Consolidated'!$A$10:$U$155,21,FALSE),"") -> 2025 Business Plan grown 3%
B22: ='NI LLC-Consolidated'!A36 -> 6220-8502 | C22: =IFERROR(VLOOKUP($B22,'NI LLC-Consolidated'!$A$10:$U$155,3,FALSE),"") -> Building Maintenance | D22: =IFERROR(VLOOKUP($B22,'NI LLC-Consolidated'!$A$10:$U$155,21,FALSE),"") -> 0
B23: ='NI LLC-Consolidated'!A38 -> 6330-8502 | C23: =IFERROR(VLOOKUP($B23,'NI LLC-Consolidated'!$A$10:$U$155,3,FALSE),"") -> Parking Lot Cleaning | D23: =IFERROR(VLOOKUP($B23,'NI LLC-Consolidated'!$A$10:$U$155,21,FALSE),"") -> 0
B24: ='NI LLC-Consolidated'!A43 -> 6360-8502 | C24: =IFERROR(VLOOKUP($B24,'NI LLC-Consolidated'!$A$10:$U$155,3,FALSE),"") -> Parking Lot Maintenance | D24: =IFERROR(VLOOKUP($B24,'NI LLC-Consolidated'!$A$10:$U$155,21,FALSE),"") -> 0
B25: ='NI LLC-Consolidated'!A45 -> 6370-8502 | C25: =IFERROR(VLOOKUP($B25,'NI LLC-Consolidated'!$A$10:$U$155,3,FALSE),"") -> Snow Removal | D25: =IFERROR(VLOOKUP($B25,'NI LLC-Consolidated'!$A$10:$U$155,21,FALSE),"") -> 2025 Business Plan grown 3%
B26: ='NI LLC-Consolidated'!A50 -> 6380-8502 | C26: =IFERROR(VLOOKUP($B26,'NI LLC-Consolidated'!$A$10:$U$155,3,FALSE),"") -> Landscaping | D26: =IFERROR(VLOOKUP($B26,'NI LLC-Consolidated'!$A$10:$U$155,21,FALSE),"") -> 0
B27: ='NI LLC-Consolidated'!A52 -> 6350-8502 | C27: =IFERROR(VLOOKUP($B27,'NI LLC-Consolidated'!$A$10:$U$155,3,FALSE),"") -> Security | D27: =IFERROR(VLOOKUP($B27,'NI LLC-Consolidated'!$A$10:$U$155,21,FALSE),"") -> 2025 Business Plan grown 3%
B28: ='NI LLC-Consolidated'!A54 -> 6610-8502 | C28: =IFERROR(VLOOKUP($B28,'NI LLC-Consolidated'!$A$10:$U$155,3,FALSE),"") -> Management Fee | D28: =IFERROR(VLOOKUP($B28,'NI LLC-Consolidated'!$A$10:$U$155,21,FALSE),"") -> 4% EGR for 5-8, 6% EGR for A-C
B29: ='NI LLC-Consolidated'!A56 -> 6270-8502 | C29: =IFERROR(VLOOKUP($B29,'NI LLC-Consolidated'!$A$10:$U$155,3,FALSE),"") -> Trash Removal | D29: =IFERROR(VLOOKUP($B29,'NI LLC-Consolidated'!$A$10:$U$155,21,FALSE),"") -> 2025 Business Plan grown 3%
B30: ='NI LLC-Consolidated'!A58 -> 6410-8502 | C30: =IFERROR(VLOOKUP($B30,'NI LLC-Consolidated'!$A$10:$U$155,3,FALSE),"") -> Real Estate Taxes | D30: =IFERROR(VLOOKUP($B30,'NI LLC-Consolidated'!$A$10:$U$155,21,FALSE),"") -> 0
B31: ='NI LLC-Consolidated'!A63 -> 6510-8502 | C31: =IFERROR(VLOOKUP($B31,'NI LLC-Consolidated'!$A$10:$U$155,3,FALSE),"") -> Insurance | D31: =IFERROR(VLOOKUP($B31,'NI LLC-Consolidated'!$A$10:$U$155,21,FALSE),"") -> 0
B32: ='NI LLC-Consolidated'!A67 -> 6250-8502 | C32: =IFERROR(VLOOKUP($B32,'NI LLC-Consolidated'!$A$10:$U$155,3,FALSE),"") -> Cleaning & Supplies | D32: =IFERROR(VLOOKUP($B32,'NI LLC-Consolidated'!$A$10:$U$155,21,FALSE),"") -> Based on occupancy.
B33: Non-Reimbursable Expenses | D33: =IFERROR(VLOOKUP($B33,'NI LLC-Consolidated'!$A$10:$U$155,21,FALSE),"")
B34: ='NI LLC-Consolidated'!A75 -> 5210-8501 | C34: =IFERROR(VLOOKUP($B34,'NI LLC-Consolidated'!$A$10:$U$155,3,FALSE),"") -> Bad Debt | D34: =IFERROR(VLOOKUP($B34,'NI LLC-Consolidated'!$A$10:$U$155,21,FALSE),"") -> 0
B35: ='NI LLC-Consolidated'!A77 -> 6010-8501 | C35: =IFERROR(VLOOKUP($B35,'NI LLC-Consolidated'!$A$10:$U$155,4,FALSE),"") -> Salaries & Wages | D35: =IFERROR(VLOOKUP($B35,'NI LLC-Consolidated'!$A$10:$U$155,21,FALSE),"") -> Based on 2026 Payroll Budget
B36: ='NI LLC-Consolidated'!A78 -> 6620-8501 | C36: =IFERROR(VLOOKUP($B36,'NI LLC-Consolidated'!$A$10:$U$155,4,FALSE),"") -> Commissions-Internal Broker | D36: =IFERROR(VLOOKUP($B36,'NI LLC-Consolidated'!$A$10:$U$155,21,FALSE),"") -> Based on projected leasing assumptions
B37: ='NI LLC-Consolidated'!A81 -> 6110-8501 | C37: =IFERROR(VLOOKUP($B37,'NI LLC-Consolidated'!$A$10:$U$155,4,FALSE),"") -> Gas | D37: =IFERROR(VLOOKUP($B37,'NI LLC-Consolidated'!$A$10:$U$155,21,FALSE),"") -> 0
B38: ='NI LLC-Consolidated'!A82 -> 6120-8501 | C38: =IFERROR(VLOOKUP($B38,'NI LLC-Consolidated'!$A$10:$U$155,4,FALSE),"") -> Electric | D38: =IFERROR(VLOOKUP($B38,'NI LLC-Consolidated'!$A$10:$U$155,21,FALSE),"") -> 0
B39: ='NI LLC-Consolidated'!A83 -> 6130-8501 | C39: =IFERROR(VLOOKUP($B39,'NI LLC-Consolidated'!$A$10:$U$155,4,FALSE),"") -> Water & Sewer | D39: =IFERROR(VLOOKUP($B39,'NI LLC-Consolidated'!$A$10:$U$155,21,FALSE),"") -> 0
B40: ='NI LLC-Consolidated'!A88 -> 6220-8501 | C40: =IFERROR(VLOOKUP($B40,'NI LLC-Consolidated'!$A$10:$U$155,3,FALSE),"") -> Building Maintenance | D40: =IFERROR(VLOOKUP($B40,'NI LLC-Consolidated'!$A$10:$U$155,21,FALSE),"") -> 2025 Business Plan grown 3%
B41: ='NI LLC-Consolidated'!A90 -> 6610-8501 | C41: =IFERROR(VLOOKUP($B41,'NI LLC-Consolidated'!$A$10:$U$155,3,FALSE),"") -> Management fee | D41: =IFERROR(VLOOKUP($B41,'NI LLC-Consolidated'!$A$10:$U$155,21,FALSE),"") -> 0
B42: ='NI LLC-Consolidated'!A92 -> 7110-8501 | C42: =IFERROR(VLOOKUP($B42,'NI LLC-Consolidated'!$A$10:$U$155,3,FALSE),"") -> Marketing | D42: =IFERROR(VLOOKUP($B42,'NI LLC-Consolidated'!$A$10:$U$155,21,FALSE),"") -> 2025 Business Plan grown 3%
B43: ='NI LLC-Consolidated'!A94 -> 8210-8501 | C43: =IFERROR(VLOOKUP($B43,'NI LLC-Consolidated'!$A$10:$U$155,3,FALSE),"") -> Business Taxes | D43: =IFERROR(VLOOKUP($B43,'NI LLC-Consolidated'!$A$10:$U$155,21,FALSE),"") -> 2025 Business Plan grown 3%
...

Sheet NI LLC-Consolidated
B1: Consolidated - 5,6,7,8,A,B,C | J1: Operating Budget | Q1: =DATE(2026,1,1) -> 46023
J2: Neshaminy Interplex LLC
Q3: =Q1 -> 46023 | R3: 7/2025 Reprojections
B4: ='Renew & Vac'!A6+'Renew & Vac'!A28+'Renew & Vac'!A50+'Renew & Vac'!A72+'Renew & Vac'!A94+'Renew & Vac'!A116+'Renew & Vac'!A138 -> 397315 | E4: Jan | F4: Feb | G4: Mar | H4: Apr | I4: May | J4: Jun | K4: Jul | L4: Aug | M4: Sep | N4: Oct | O4: Nov | P4: Dec | Q4: Total | R4: Total | S4: Var. | T4: Input | U4: Notes
D6: Occupancy % | E6: =SUM('4050'!E7,'4060'!E7,'4070'!E7,'4080'!E7,'40A0'!E7,'40B0'!E7,'40C0'!E7)/$B$4 -> 0.6669179 | F6: =SUM('4050'!F7,'4060'!F7,'4070'!F7,'4080'!F7,'40A0'!F7,'40B0'!F7,'40C0'!F7)/$B$4 -> 0.6685275 | G6: =SUM('4050'!G7,'4060'!G7,'4070'!G7,'4080'!G7,'40A0'!G7,'40B0'!G7,'40C0'!G7)/$B$4 -> 0.67367598 | H6: =SUM('4050'!H7,'4060'!H7,'4070'!H7,'4080'!H7,'40A0'!H7,'40B0'!H7,'40C0'!H7)/$B$4 -> 0.68748835 | I6: =SUM('4050'!I7,'4060'!I7,'4070'!I7,'4080'!I7,'40A0'!I7,'40B0'!I7,'40C0'!I7)/$B$4 -> 0.68748835 | J6: =SUM('4050'!J7,'4060'!J7,'4070'!J7,'4080'!J7,'40A0'!J7,'40B0'!J7,'40C0'!J7)/$B$4 -> 0.68748835 | K6: =SUM('4050'!K7,'4060'!K7,'4070'!K7,'4080'!K7,'40A0'!K7,'40B0'!K7,'40C0'!K7)/$B$4 -> 0.68375787 | L6: =SUM('4050'!L7,'4060'!L7,'4070'!L7,'4080'!L7,'40A0'!L7,'40B0'!L7,'40C0'!L7)/$B$4 -> 0.68375787 | ... P6: =SUM('4050'!P7,'4060'!P7,'4070'!P7,'4080'!P7,'40A0'!P7,'40B0'!P7,'40C0'!P7)/$B$4 -> 0.66519737
B8: Revenues
A10: 4230-8501 | C10: Rental Income - In Place | E10: =+'4050'!E10+'4060'!E10+'4070'!E10+'4080'!E10+'40A0'!E10+'40B0'!E10+'40C0'!E10+'4000'!E9 -> 293482.04 | F10: =+'4050'!F10+'4060'!F10+'4070'!F10+'4080'!F10+'40A0'!F10+'40B0'!F10+'40C0'!F10+'4000'!F9 -> 291222.19 | G10: =+'4050'!G10+'4060'!G10+'4070'!G10+'4080'!G10+'40A0'!G10+'40B0'!G10+'40C0'!G10+'4000'!G9 -> 291487.24 | H10: =+'4050'!H10+'4060'!H10+'4070'!H10+'4080'!H10+'40A0'!H10+'40B0'!H10+'40C0'!H10+'4000'!H9 -> 279312.18 | I10: =+'4050'!I10+'4060'!I10+'4070'!I10+'4080'!I10+'40A0'!I10+'40B0'!I10+'40C0'!I10+'4000'!I9 -> 280119.76 | J10: =+'4050'!J10+'4060'!J10+'4070'!J10+'4080'!J10+'40A0'!J10+'40B0'!J10+'40C0'!J10+'4000'!J9 -> 280257.6 | K10: =+'4050'!K10+'4060'!K10+'4070'!K10+'4080'!K10+'40A0'!K10+'40B0'!K10+'40C0'!K10+'4000'!K9 -> 220520.85 | L10: =+'4050'!L10+'4060'!L10+'4070'!L10+'4080'!L10+'40A0'!L10+'40B0'!L10+'40C0'!L10+'4000'!L9 -> 219090.56 | ... P10: =+'4050'!P10+'4060'!P10+'4070'!P10+'4080'!P10+'40A0'!P10+'40B0'!P10+'40C0'!P10+'4000'!P9 -> 192534.82 | Q10: =SUM(E10:P10) -> 2953594.6 | R10: 4725706 | S10: =(Q10+Q11)/R10-1 -> -0.047732592
A11: 4230-8501 | C11: Rental Income - New & Renewal | E11: =+'4050'!E11+'4060'!E11+'4070'!E11+'4080'!E11+'40A0'!E11+'40B0'!E11+'40C0'!E11+'4000'!E10 -> 82100.625 | F11: =+'4050'!F11+'4060'!F11+'4070'!F11+'4080'!F11+'40A0'!F11+'40B0'!F11+'40C0'!F11+'4000'!F10 -> 85400.062 | G11: =+'4050'!G11+'4060'!G11+'4070'!G11+'4080'!G11+'40A0'!G11+'40B0'!G11+'40C0'!G11+'4000'!G10 -> 88907.272 | H11: =+'4050'!H11+'4060'!H11+'4070'!H11+'4080'!H11+'40A0'!H11+'40B0'!H11+'40C0'!H11+'4000'!H10 -> 105864.77 | I11: =+'4050'!I11+'4060'!I11+'4070'!I11+'4080'!I11+'40A0'!I11+'40B0'!I11+'40C0'!I11+'4000'!I10 -> 105864.77 | J11: =+'4050'!J11+'4060'!J11+'4070'!J11+'4080'!J11+'40A0'!J11+'40B0'!J11+'40C0'!J11+'4000'!J10 -> 105864.77 | K11: =+'4050'!K11+'4060'!K11+'4070'!K11+'4080'!K11+'40A0'!K11+'40B0'!K11+'40C0'!K11+'4000'!K10 -> 150605.44 | L11: =+'4050'!L11+'4060'!L11+'4070'!L11+'4080'!L11+'40A0'!L11+'40B0'!L11+'40C0'!L11+'4000'!L10 -> 152343.94 | ... P11: =+'4050'!P11+'4060'!P11+'4070'!P11+'4080'!P11+'40A0'!P11+'40B0'!P11+'40C0'!P11+'4000'!P10 -> 167497.23 | Q11: =SUM(E11:P11) -> 1546541.2
A12: 4240-8501 | C12: Percentage Rents | E12: =+'4050'!E12+'4060'!E12+'4070'!E12+'4080'!E12+'40A0'!E12+'40B0'!E12+'40C0'!E12+'4000'!E10 -> 0 | F12: =+'4050'!F12+'4060'!F12+'4070'!F12+'4080'!F12+'40A0'!F12+'40B0'!F12+'40C0'!F12+'4000'!F10 -> 0 | G12: =+'4050'!G12+'4060'!G12+'4070'!G12+'4080'!G12+'40A0'!G12+'40B0'!G12+'40C0'!G12+'4000'!G10 -> 0 | H12: =+'4050'!H12+'4060'!H12+'4070'!H12+'4080'!H12+'40A0'!H12+'40B0'!H12+'40C0'!H12+'4000'!H10 -> 0 | I12: =+'4050'!I12+'4060'!I12+'4070'!I12+'4080'!I12+'40A0'!I12+'40B0'!I12+'40C0'!I12+'4000'!I10 -> 0 | J12: =+'4050'!J12+'4060'!J12+'4070'!J12+'4080'!J12+'40A0'!J12+'40B0'!J12+'40C0'!J12+'4000'!J10 -> 0 | K12: =+'4050'!K12+'4060'!K12+'4070'!K12+'4080'!K12+'40A0'!K12+'40B0'!K12+'40C0'!K12+'4000'!K10 -> 0 | L12: =+'4050'!L12+'4060'!L12+'4070'!L12+'4080'!L12+'40A0'!L12+'40B0'!L12+'40C0'!L12+'4000'!L10 -> 0 | ... P12: =+'4050'!P12+'4060'!P12+'4070'!P12+'4080'!P12+'40A0'!P12+'40B0'!P12+'40C0'!P12+'4000'!P10 -> 0 | Q12: =SUM(E12:P12) -> 0 | S12: =Q12/R12-1 -> #DIV/0!
A13: 4990-8501 | C13: Miscellaneous | E13: =+'4050'!E13+'4060'!E13+'4070'!E13+'4080'!E13+'40A0'!E13+'40B0'!E13+'40C0'!E13+'4000'!E11 -> 200 | F13: =+'4050'!F13+'4060'!F13+'4070'!F13+'4080'!F13+'40A0'!F13+'40B0'!F13+'40C0'!F13+'4000'!F11 -> 200 | G13: =+'4050'!G13+'4060'!G13+'4070'!G13+'4080'!G13+'40A0'!G13+'40B0'!G13+'40C0'!G13+'4000'!G11 -> 5200 | H13: =+'4050'!H13+'4060'!H13+'4070'!H13+'4080'!H13+'40A0'!H13+'40B0'!H13+'40C0'!H13+'4000'!H11 -> 200 | I13: =+'4050'!I13+'4060'!I13+'4070'!I13+'4080'!I13+'40A0'!I13+'40B0'!I13+'40C0'!I13+'4000'!I11 -> 200 | J13: =+'4050'!J13+'4060'!J13+'4070'!J13+'4080'!J13+'40A0'!J13+'40B0'!J13+'40C0'!J13+'4000'!J11 -> 5200 | K13: =+'4050'!K13+'4060'!K13+'4070'!K13+'4080'!K13+'40A0'!K13+'40B0'!K13+'40C0'!K13+'4000'!K11 -> 200 | L13: =+'4050'!L13+'4060'!L13+'4070'!L13+'4080'!L13+'40A0'!L13+'40B0'!L13+'40C0'!L13+'4000'!L11 -> 200 | ... P13: =+'4050'!P13+'4060'!P13+'4070'!P13+'4080'!P13+'40A0'!P13+'40B0'!P13+'40C0'!P13+'4000'!P11 -> 5200 | Q13: =SUM(E13:P13) -> 22400 | S13: =Q13/R13-1 -> #DIV/0! | T13: DW | U13: Gym Fees and $5K/qtr for Billboard (Applied to 4080)
A14: 9190-8501 | C14: Interest Income | E14: =+'4050'!E14+'4060'!E14+'4070'!E14+'4080'!E14+'40A0'!E14+'40B0'!E14+'40C0'!E14+'4000'!E12 -> 207 | F14: =+'4050'!F14+'4060'!F14+'4070'!F14+'4080'!F14+'40A0'!F14+'40B0'!F14+'40C0'!F14+'4000'!F12 -> 207 | G14: =+'4050'!G14+'4060'!G14+'4070'!G14+'4080'!G14+'40A0'!G14+'40B0'!G14+'40C0'!G14+'4000'!G12 -> 207 | H14: =+'4050'!H14+'4060'!H14+'4070'!H14+'4080'!H14+'40A0'!H14+'40B0'!H14+'40C0'!H14+'4000'!H12 -> 207 | I14: =+'4050'!I14+'4060'!I14+'4070'!I14+'4080'!I14+'40A0'!I14+'40B0'!I14+'40C0'!I14+'4000'!I12 -> 207 | J14: =+'4050'!J14+'4060'!J14+'4070'!J14+'4080'!J14+'40A0'!J14+'40B0'!J14+'40C0'!J14+'4000'!J12 -> 207 | K14: =+'4050'!K14+'4060'!K14+'4070'!K14+'4080'!K14+'40A0'!K14+'40B0'!K14+'40C0'!K14+'4000'!K12 -> 207 | L14: =+'4050'!L14+'4060'!L14+'4070'!L14+'4080'!L14+'40A0'!L14+'40B0'!L14+'40C0'!L14+'4000'!L12 -> 207 | ... P14: =+'4050'!P14+'4060'!P14+'4070'!P14+'4080'!P14+'40A0'!P14+'40B0'!P14+'40C0'!P14+'4000'!P12 -> 207 | Q14: =SUM(E14:P14) -> 2484 | R14: 0 | T14: DW | U14: Annualized one month of interest from recent statement (Applied to 4050)
D15: Total Rental and Other: | E15: =SUM(E10:E14) -> 375989.67 | F15: =SUM(F10:F14) -> 377029.25 | G15: =SUM(G10:G14) -> 385801.51 | H15: =SUM(H10:H14) -> 385583.95 | I15: =SUM(I10:I14) -> 386391.53 | J15: =SUM(J10:J14) -> 391529.37 | K15: =SUM(K10:K14) -> 371533.29 | L15: =SUM(L10:L14) -> 371841.5 | ... R15: =SUM(R10:R14) -> 4725706 | S15: =Q15/R15-1 -> -0.042466923
B17: Reimbursements
A18: 4710-8502 | C18: Electric | E18: =+'4050'!E18+'4060'!E18+'4070'!E18+'4080'!E18+'40A0'!E18+'40B0'!E18+'40C0'!E18+'4000'!E16 -> 62057.521 | F18: =+'4050'!F18+'4060'!F18+'4070'!F18+'4080'!F18+'40A0'!F18+'40B0'!F18+'40C0'!F18+'4000'!F16 -> 56555.837 | G18: =+'4050'!G18+'4060'!G18+'4070'!G18+'4080'!G18+'40A0'!G18+'40B0'!G18+'40C0'!G18+'4000'!G16 -> 54115.025 | H18: =+'4050'!H18+'4060'!H18+'4070'!H18+'4080'!H18+'40A0'!H18+'40B0'!H18+'40C0'!H18+'4000'!H16 -> 52905.408 | I18: =+'4050'!I18+'4060'!I18+'4070'!I18+'4080'!I18+'40A0'!I18+'40B0'!I18+'40C0'!I18+'4000'!I16 -> 54964.321 | J18: =+'4050'!J18+'4060'!J18+'4070'!J18+'4080'!J18+'40A0'!J18+'40B0'!J18+'40C0'!J18+'4000'!J16 -> 58906.282 | K18: =+'4050'!K18+'4060'!K18+'4070'!K18+'4080'!K18+'40A0'!K18+'40B0'!K18+'40C0'!K18+'4000'!K16 -> 63811.323 | L18: =+'4050'!L18+'4060'!L18+'4070'!L18+'4080'!L18+'40A0'!L18+'40B0'!L18+'40C0'!L18+'4000'!L16 -> 62006.217 | ... P18: =+'4050'!P18+'4060'!P18+'4070'!P18+'4080'!P18+'40A0'!P18+'40B0'!P18+'40C0'!P18+'4000'!P16 -> 61090.396 | Q18: =SUM(E18:P18) -> 690813.09 | R18: 632018 | S18: =Q18/R18-1 -> 0.093027551 | T18: DW | U18: Set to occupancy
A19: 4910-8502 | C19: Common Area Maintenance | E19: =+'4050'!E19+'4060'!E19+'4070'!E19+'4080'!E19+'40A0'!E19+'40B0'!E19+'40C0'!E19+'4000'!E17 -> 50300 | F19: =+'4050'!F19+'4060'!F19+'4070'!F19+'4080'!F19+'40A0'!F19+'40B0'!F19+'40C0'!F19+'4000'!F17 -> 50300 | G19: =+'4050'!G19+'4060'!G19+'4070'!G19+'4080'!G19+'40A0'!G19+'40B0'!G19+'40C0'!G19+'4000'!G17 -> 50300 | H19: =+'4050'!H19+'4060'!H19+'4070'!H19+'4080'!H19+'40A0'!H19+'40B0'!H19+'40C0'!H19+'4000'!H17 -> 50300 | I19: =+'4050'!I19+'4060'!I19+'4070'!I19+'4080'!I19+'40A0'!I19+'40B0'!I19+'40C0'!I19+'4000'!I17 -> 50300 | J19: =+'4050'!J19+'4060'!J19+'4070'!J19+'4080'!J19+'40A0'!J19+'40B0'!J19+'40C0'!J19+'4000'!J17 -> 50300 | K19: =+'4050'!K19+'4060'!K19+'4070'!K19+'4080'!K19+'40A0'!K19+'40B0'!K19+'40C0'!K19+'4000'!K17 -> 50300 | L19: =+'4050'!L19+'4060'!L19+'4070'!L19+'4080'!L19+'40A0'!L19+'40B0'!L19+'40C0'!L19+'4000'!L17 -> 50300 | ... P19: =+'4050'!P19+'4060'!P19+'4070'!P19+'4080'!P19+'40A0'!P19+'40B0'!P19+'40C0'!P19+'4000'!P17 -> 50300 | Q19: =SUM(E19:P19) -> 603600 | R19: 547773 | S19: =Q19/R19-1 -> 0.1019163
A20: 4920-8502 | C20: Real Estate Taxes | E20: =+'4050'!E20+'4060'!E20+'4070'!E20+'4080'!E20+'40A0'!E20+'40B0'!E20+'40C0'!E20+'4000'!E18 -> 8300 | F20: =+'4050'!F20+'4060'!F20+'4070'!F20+'4080'!F20+'40A0'!F20+'40B0'!F20+'40C0'!F20+'4000'!F18 -> 8300 | G20: =+'4050'!G20+'4060'!G20+'4070'!G20+'4080'!G20+'40A0'!G20+'40B0'!G20+'40C0'!G20+'4000'!G18 -> 8300 | H20: =+'4050'!H20+'4060'!H20+'4070'!H20+'4080'!H20+'40A0'!H20+'40B0'!H20+'40C0'!H20+'4000'!H18 -> 8300 | I20: =+'4050'!I20+'4060'!I20+'4070'!I20+'4080'!I20+'40A0'!I20+'40B0'!I20+'40C0'!I20+'4000'!I18 -> 8300 | J20: =+'4050'!J20+'4060'!J20+'4070'!J20+'4080'!J20+'40A0'!J20+'40B0'!J20+'40C0'!J20+'4000'!J18 -> 8300 | K20: =+'4050'!K20+'4060'!K20+'4070'!K20+'4080'!K20+'40A0'!K20+'40B0'!K20+'40C0'!K20+'4000'!K18 -> 8300 | L20: =+'4050'!L20+'4060'!L20+'4070'!L20+'4080'!L20+'40A0'!L20+'40B0'!L20+'40C0'!L20+'4000'!L18 -> 8300 | ... P20: =+'4050'!P20+'4060'!P20+'4070'!P20+'4080'!P20+'40A0'!P20+'40B0'!P20+'40C0'!P20+'4000'!P18 -> 8300 | Q20: =SUM(E20:P20) -> 99600 | R20: 82162 | S20: =Q20/R20-1 -> 0.21223923
A21: 4930-8502 | C21: Insurance | E21: =+'4050'!E21+'4060'!E21+'4070'!E21+'4080'!E21+'40A0'!E21+'40B0'!E21+'40C0'!E21+'4000'!E19 -> 0 | F21: =+'4050'!F21+'4060'!F21+'4070'!F21+'4080'!F21+'40A0'!F21+'40B0'!F21+'40C0'!F21+'4000'!F19 -> 0 | G21: =+'4050'!G21+'4060'!G21+'4070'!G21+'4080'!G21+'40A0'!G21+'40B0'!G21+'40C0'!G21+'4000'!G19 -> 0 | H21: =+'4050'!H21+'4060'!H21+'4070'!H21+'4080'!H21+'40A0'!H21+'40B0'!H21+'40C0'!H21+'4000'!H19 -> 0 | I21: =+'4050'!I21+'4060'!I21+'4070'!I21+'4080'!I21+'40A0'!I21+'40B0'!I21+'40C0'!I21+'4000'!I19 -> 0 | J21: =+'4050'!J21+'4060'!J21+'4070'!J21+'4080'!J21+'40A0'!J21+'40B0'!J21+'40C0'!J21+'4000'!J19 -> 0 | K21: =+'4050'!K21+'4060'!K21+'4070'!K21+'4080'!K21+'40A0'!K21+'40B0'!K21+'40C0'!K21+'4000'!K19 -> 0 | L21: =+'4050'!L21+'4060'!L21+'4070'!L21+'4080'!L21+'40A0'!L21+'40B0'!L21+'40C0'!L21+'4000'!L19 -> 0 | ... P21: =+'4050'!P21+'4060'!P21+'4070'!P21+'4080'!P21+'40A0'!P21+'40B0'!P21+'40C0'!P21+'4000'!P19 -> 0 | Q21: =SUM(E21:P21) -> 0 | R21: 0 | S21: =Q21/R21-1 -> #DIV/0!
D22: Total Reimbursements: | E22: =SUM(E18:E21) -> 120657.52 | F22: =SUM(F18:F21) -> 115155.84 | G22: =SUM(G18:G21) -> 112715.03 | H22: =SUM(H18:H21) -> 111505.41 | I22: =SUM(I18:I21) -> 113564.32 | J22: =SUM(J18:J21) -> 117506.28 | K22: =SUM(K18:K21) -> 122411.32 | L22: =SUM(L18:L21) -> 120606.22 | ... R22: =SUM(R18:R21) -> 1261953 | S22: =Q22/R22-1 -> 0.10464739
B24: TOTAL REVENUES | E24: =+E15+E22 -> 496647.19 | F24: =+F15+F22 -> 492185.09 | G24: =+G15+G22 -> 498516.54 | H24: =+H15+H22 -> 497089.36 | I24: =+I15+I22 -> 499955.85 | J24: =+J15+J22 -> 509035.65 | K24: =+K15+K22 -> 493944.61 | L24: =+L15+L22 -> 492447.72 | ... R24: =+R15+R22 -> 5987659 | S24: =Q24/R24-1 -> -0.011461258
Q25: =+'4050'!Q24+'4060'!Q24+'4070'!Q24+'4080'!Q24+'40A0'!Q24+'40B0'!Q24+'40C0'!Q24 -> 5919032.9
B26: Reimbursable Expenses
A27: 6030-8502 | C27: Maintenance Salaries | E27: =+'4050'!E27+'4060'!E27+'4070'!E27+'4080'!E27+'40A0'!E27+'40B0'!E27+'40C0'!E27+'4000'!E26 -> 8128.5833 | F27: =+'4050'!F27+'4060'!F27+'4070'!F27+'4080'!F27+'40A0'!F27+'40B0'!F27+'40C0'!F27+'4000'!F26 -> 8128.5833 | G27: =+'4050'!G27+'4060'!G27+'4070'!G27+'4080'!G27+'40A0'!G27+'40B0'!G27+'40C0'!G27+'4000'!G26 -> 8128.5833 | H27: =+'4050'!H27+'4060'!H27+'4070'!H27+'4080'!H27+'40A0'!H27+'40B0'!H27+'40C0'!H27+'4000'!H26 -> 8128.5833 | I27: =+'4050'!I27+'4060'!I27+'4070'!I27+'4080'!I27+'40A0'!I27+'40B0'!I27+'40C0'!I27+'4000'!I26 -> 8128.5833 | J27: =+'4050'!J27+'4060'!J27+'4070'!J27+'4080'!J27+'40A0'!J27+'40B0'!J27+'40C0'!J27+'4000'!J26 -> 8128.5833 | K27: =+'4050'!K27+'4060'!K27+'4070'!K27+'4080'!K27+'40A0'!K27+'40B0'!K27+'40C0'!K27+'4000'!K26 -> 8128.5833 | L27: =+'4050'!L27+'4060'!L27+'4070'!L27+'4080'!L27+'40A0'!L27+'40B0'!L27+'40C0'!L27+'4000'!L26 -> 8128.5833 | ... P27: =+'4050'!P27+'4060'!P27+'4070'!P27+'4080'!P27+'40A0'!P27+'40B0'!P27+'40C0'!P27+'4000'!P26 -> 8128.5833 | Q27: =SUM(E27:P27) -> 97543 | R27: 65400 | S27: =Q27/R27-1 -> 0.49148318 | U27: Based on 2026 Payroll Budget
A29: 6120-8502 | C29: Electric | E29: =+'4050'!E29+'4060'!E29+'4070'!E29+'4080'!E29+'40A0'!E29+'40B0'!E29+'40C0'!E29+'4000'!E28 -> 97164 | F29: =+'4050'!F29+'4060'!F29+'4070'!F29+'4080'!F29+'40A0'!F29+'40B0'!F29+'40C0'!F29+'4000'!F28 -> 88149 | G29: =+'4050'!G29+'4060'!G29+'4070'!G29+'4080'!G29+'40A0'!G29+'40B0'!G29+'40C0'!G29+'4000'!G28 -> 83677 | H29: =+'4050'!H29+'4060'!H29+'4070'!H29+'4080'!H29+'40A0'!H29+'40B0'!H29+'40C0'!H29+'4000'!H28 -> 80724 | I29: =+'4050'!I29+'4060'!I29+'4070'!I29+'4080'!I29+'40A0'!I29+'40B0'!I29+'40C0'!I29+'4000'!I28 -> 84119 | J29: =+'4050'!J29+'4060'!J29+'4070'!J29+'4080'!J29+'40A0'!J29+'40B0'!J29+'40C0'!J29+'4000'!J28 -> 90279 | K29: =+'4050'!K29+'4060'!K29+'4070'!K29+'4080'!K29+'40A0'!K29+'40B0'!K29+'40C0'!K29+'4000'!K28 -> 98568 | L29: =+'4050'!L29+'4060'!L29+'4070'!L29+'4080'!L29+'40A0'!L29+'40B0'!L29+'40C0'!L29+'4000'!L28 -> 95991 | ... P29: =+'4050'!P29+'4060'!P29+'4070'!P29+'4080'!P29+'40A0'!P29+'40B0'!P29+'40C0'!P29+'4000'!P28 -> 96590 | Q29: =SUM(E29:P29) -> 1070652 | R29: 970692 | S29: =Q29/R29-1 -> 0.10297808 | T29: DW | U29: Data\Shared\Properties\Business Plans - All Entities\2026\ISG Electric data
A31: 6130-8502 | C31: Water & Sewer | E31: =+'4050'!E31+'4060'!E31+'4070'!E31+'4080'!E31+'40A0'!E31+'40B0'!E31+'40C0'!E31+'4000'!E30 -> 5481.66 | F31: =+'4050'!F31+'4060'!F31+'4070'!F31+'4080'!F31+'40A0'!F31+'40B0'!F31+'40C0'!F31+'4000'!F30 -> 5746.37 | G31: =+'4050'!G31+'4060'!G31+'4070'!G31+'4080'!G31+'40A0'!G31+'40B0'!G31+'40C0'!G31+'4000'!G30 -> 6181.03 | H31: =+'4050'!H31+'4060'!H31+'4070'!H31+'4080'!H31+'40A0'!H31+'40B0'!H31+'40C0'!H31+'4000'!H30 -> 6196.48 | I31: =+'4050'!I31+'4060'!I31+'4070'!I31+'4080'!I31+'40A0'!I31+'40B0'!I31+'40C0'!I31+'4000'!I30 -> 10136.23 | J31: =+'4050'!J31+'4060'!J31+'4070'!J31+'4080'!J31+'40A0'!J31+'40B0'!J31+'40C0'!J31+'4000'!J30 -> 13574.37 | K31: =+'4050'!K31+'4060'!K31+'4070'!K31+'4080'!K31+'40A0'!K31+'40B0'!K31+'40C0'!K31+'4000'!K30 -> 15153.36 | L31: =+'4050'!L31+'4060'!L31+'4070'!L31+'4080'!L31+'40A0'!L31+'40B0'!L31+'40C0'!L31+'4000'!L30 -> 19042.64 | ... P31: =+'4050'!P31+'4060'!P31+'4070'!P31+'4080'!P31+'40A0'!P31+'40B0'!P31+'40C0'!P31+'4000'!P30 -> 5916.32 | Q31: =SUM(E31:P31) -> 120449.23 | R31: 95262 | S31: =Q31/R31-1 -> 0.26439955 | T31: DW | U31: 2025 Business Plan grown 3%
D33: Building Maint.-Contractual | E33: =+'4050'!E33+'4060'!E33+'4070'!E33+'4080'!E33+'40A0'!E33+'40B0'!E33+'40C0'!E33+'4000'!E32 -> 10827 | F33: =+'4050'!F33+'4060'!F33+'4070'!F33+'4080'!F33+'40A0'!F33+'40B0'!F33+'40C0'!F33+'4000'!F32 -> 9540 | G33: =+'4050'!G33+'4060'!G33+'4070'!G33+'4080'!G33+'40A0'!G33+'40B0'!G33+'40C0'!G33+'4000'!G32 -> 31478 | H33: =+'4050'!H33+'4060'!H33+'4070'!H33+'4080'!H33+'40A0'!H33+'40B0'!H33+'40C0'!H33+'4000'!H32 -> 28878 | I33: =+'4050'!I33+'4060'!I33+'4070'!I33+'4080'!I33+'40A0'!I33+'40B0'!I33+'40C0'!I33+'4000'!I32 -> 9540 | J33: =+'4050'!J33+'4060'!J33+'4070'!J33+'4080'!J33+'40A0'!J33+'40B0'!J33+'40C0'!J33+'4000'!J32 -> 31460 | K33: =+'4050'!K33+'4060'!K33+'4070'!K33+'4080'!K33+'40A0'!K33+'40B0'!K33+'40C0'!K33+'4000'!K32 -> 10827 | L33: =+'4050'!L33+'4060'!L33+'4070'!L33+'4080'!L33+'40A0'!L33+'40B0'!L33+'40C0'!L33+'4000'!L32 -> 9540 | ... P33: =+'4050'!P33+'4060'!P33+'4070'!P33+'4080'!P33+'40A0'!P33+'40B0'!P33+'40C0'!P33+'4000'!P32 -> 24755 | Q33: =SUM(E33:P33) -> 236723 | T33: DW | U33: 2025 Business Plan grown 3%
D34: Building Maint.-Recurring | E34: =+'4050'!E34+'4060'!E34+'4070'!E34+'4080'!E34+'40A0'!E34+'40B0'!E34+'40C0'!E34+'4000'!E33 -> 18455 | F34: =+'4050'!F34+'4060'!F34+'4070'!F34+'4080'!F34+'40A0'!F34+'40B0'!F34+'40C0'!F34+'4000'!F33 -> 11925 | G34: =+'4050'!G34+'4060'!G34+'4070'!G34+'4080'!G34+'40A0'!G34+'40B0'!G34+'40C0'!G34+'4000'!G33 -> 12430 | H34: =+'4050'!H34+'4060'!H34+'4070'!H34+'4080'!H34+'40A0'!H34+'40B0'!H34+'40C0'!H34+'4000'!H33 -> 14425 | I34: =+'4050'!I34+'4060'!I34+'4070'!I34+'4080'!I34+'40A0'!I34+'40B0'!I34+'40C0'!I34+'4000'!I33 -> 24295 | J34: =+'4050'!J34+'4060'!J34+'4070'!J34+'4080'!J34+'40A0'!J34+'40B0'!J34+'40C0'!J34+'4000'!J33 -> 13980 | K34: =+'4050'!K34+'4060'!K34+'4070'!K34+'4080'!K34+'40A0'!K34+'40B0'!K34+'40C0'!K34+'4000'!K33 -> 26380 | L34: =+'4050'!L34+'4060'!L34+'4070'!L34+'4080'!L34+'40A0'!L34+'40B0'!L34+'40C0'!L34+'4000'!L33 -> 12105 | ... P34: =+'4050'!P34+'4060'!P34+'4070'!P34+'4080'!P34+'40A0'!P34+'40B0'!P34+'40C0'!P34+'4000'!P33 -> 12230 | Q34: =SUM(E34:P34) -> 189220 | T34: DW | U34: 2025 Business Plan grown 3%
D35: Building Maint.-Big Projects | E35: =+'4050'!E35+'4060'!E35+'4070'!E35+'4080'!E35+'40A0'!E35+'40B0'!E35+'40C0'!E35+'4000'!E34 -> 0 | F35: =+'4050'!F35+'4060'!F35+'4070'!F35+'4080'!F35+'40A0'!F35+'40B0'!F35+'40C0'!F35+'4000'!F34 -> 20300 | G35: =+'4050'!G35+'4060'!G35+'4070'!G35+'4080'!G35+'40A0'!G35+'40B0'!G35+'40C0'!G35+'4000'!G34 -> 15150 | H35: =+'4050'!H35+'4060'!H35+'4070'!H35+'4080'!H35+'40A0'!H35+'40B0'!H35+'40C0'!H35+'4000'!H34 -> 24205 | I35: =+'4050'!I35+'4060'!I35+'4070'!I35+'4080'!I35+'40A0'!I35+'40B0'!I35+'40C0'!I35+'4000'!I34 -> 10300 | J35: =+'4050'!J35+'4060'!J35+'4070'!J35+'4080'!J35+'40A0'!J35+'40B0'!J35+'40C0'!J35+'4000'!J34 -> 20600 | K35: =+'4050'!K35+'4060'!K35+'4070'!K35+'4080'!K35+'40A0'!K35+'40B0'!K35+'40C0'!K35+'4000'!K34 -> 15450 | L35: =+'4050'!L35+'4060'!L35+'4070'!L35+'4080'!L35+'40A0'!L35+'40B0'!L35+'40C0'!L35+'4000'!L34 -> 10300 | ... P35: =+'4050'!P35+'4060'!P35+'4070'!P35+'4080'!P35+'40A0'!P35+'40B0'!P35+'40C0'!P35+'4000'!P34 -> 0 | Q35: =SUM(E35:P35) -> 151755 | T35: DW | U35: Contingency for repairs including Paint halls/Replace Fire panel/LED lighting/window replacement
A36: 6220-8502 | C36: Building Maintenance | E36: =SUM(E33:E35) -> 29282 | F36: =SUM(F33:F35) -> 41765 | G36: =SUM(G33:G35) -> 59058 | H36: =SUM(H33:H35) -> 67508 | I36: =SUM(I33:I35) -> 44135 | J36: =SUM(J33:J35) -> 66040 | K36: =SUM(K33:K35) -> 52657 | L36: =SUM(L33:L35) -> 31945 | ... Q36: =SUM(Q33:Q35) -> 577698 | R36: 576052 | S36: =Q36/R36-1 -> 0.0028573809
A38: 6330-8502 | B38: (SC) | C38: Parking Lot Cleaning | E38: =+'4050'!E38+'4060'!E38+'4070'!E38+'4080'!E38+'40A0'!E38+'40B0'!E38+'40C0'!E38+'4000'!E37 -> 0 | F38: =+'4050'!F38+'4060'!F38+'4070'!F38+'4080'!F38+'40A0'!F38+'40B0'!F38+'40C0'!F38+'4000'!F37 -> 0 | G38: =+'4050'!G38+'4060'!G38+'4070'!G38+'4080'!G38+'40A0'!G38+'40B0'!G38+'40C0'!G38+'4000'!G37 -> 0 | H38: =+'4050'!H38+'4060'!H38+'4070'!H38+'4080'!H38+'40A0'!H38+'40B0'!H38+'40C0'!H38+'4000'!H37 -> 0 | I38: =+'4050'!I38+'4060'!I38+'4070'!I38+'4080'!I38+'40A0'!I38+'40B0'!I38+'40C0'!I38+'4000'!I37 -> 0 | J38: =+'4050'!J38+'4060'!J38+'4070'!J38+'4080'!J38+'40A0'!J38+'40B0'!J38+'40C0'!J38+'4000'!J37 -> 0 | K38: =+'4050'!K38+'4060'!K38+'4070'!K38+'4080'!K38+'40A0'!K38+'40B0'!K38+'40C0'!K38+'4000'!K37 -> 0 | L38: =+'4050'!L38+'4060'!L38+'4070'!L38+'4080'!L38+'40A0'!L38+'40B0'!L38+'40C0'!L38+'4000'!L37 -> 0 | ... P38: =+'4050'!P38+'4060'!P38+'4070'!P38+'4080'!P38+'40A0'!P38+'40B0'!P38+'40C0'!P38+'4000'!P37 -> 0 | Q38: =SUM(E38:P38) -> 0 | R38: 0
D40: Parking Lot Maint.-Contractual | E40: =+'4050'!E40+'4060'!E40+'4070'!E40+'4080'!E40+'40A0'!E40+'40B0'!E40+'40C0'!E40+'4000'!E39 -> 0 | F40: =+'4050'!F40+'4060'!F40+'4070'!F40+'4080'!F40+'40A0'!F40+'40B0'!F40+'40C0'!F40+'4000'!F39 -> 0 | G40: =+'4050'!G40+'4060'!G40+'4070'!G40+'4080'!G40+'40A0'!G40+'40B0'!G40+'40C0'!G40+'4000'!G39 -> 0 | H40: =+'4050'!H40+'4060'!H40+'4070'!H40+'4080'!H40+'40A0'!H40+'40B0'!H40+'40C0'!H40+'4000'!H39 -> 0 | I40: =+'4050'!I40+'4060'!I40+'4070'!I40+'4080'!I40+'40A0'!I40+'40B0'!I40+'40C0'!I40+'4000'!I39 -> 0 | J40: =+'4050'!J40+'4060'!J40+'4070'!J40+'4080'!J40+'40A0'!J40+'40B0'!J40+'40C0'!J40+'4000'!J39 -> 0 | K40: =+'4050'!K40+'4060'!K40+'4070'!K40+'4080'!K40+'40A0'!K40+'40B0'!K40+'40C0'!K40+'4000'!K39 -> 0 | L40: =+'4050'!L40+'4060'!L40+'4070'!L40+'4080'!L40+'40A0'!L40+'40B0'!L40+'40C0'!L40+'4000'!L39 -> 0 | ... P40: =+'4050'!P40+'4060'!P40+'4070'!P40+'4080'!P40+'40A0'!P40+'40B0'!P40+'40C0'!P40+'4000'!P39 -> 0 | Q40: =SUM(E40:P40) -> 0
D41: Parking Lot Maint.-Recurring | E41: =+'4050'!E41+'4060'!E41+'4070'!E41+'4080'!E41+'40A0'!E41+'40B0'!E41+'40C0'!E41+'4000'!E40 -> 5340.55 | F41: =+'4050'!F41+'4060'!F41+'4070'!F41+'4080'!F41+'40A0'!F41+'40B0'!F41+'40C0'!F41+'4000'!F40 -> 5546.55 | G41: =+'4050'!G41+'4060'!G41+'4070'!G41+'4080'!G41+'40A0'!G41+'40B0'!G41+'40C0'!G41+'4000'!G40 -> 9177.3 | H41: =+'4050'!H41+'4060'!H41+'4070'!H41+'4080'!H41+'40A0'!H41+'40B0'!H41+'40C0'!H41+'4000'!H40 -> 5340.55 | I41: =+'4050'!I41+'4060'!I41+'4070'!I41+'4080'!I41+'40A0'!I41+'40B0'!I41+'40C0'!I41+'4000'!I40 -> 5546.55 | J41: =+'4050'!J41+'4060'!J41+'4070'!J41+'4080'!J41+'40A0'!J41+'40B0'!J41+'40C0'!J41+'4000'!J40 -> 9177.3 | K41: =+'4050'!K41+'4060'!K41+'4070'!K41+'4080'!K41+'40A0'!K41+'40B0'!K41+'40C0'!K41+'4000'!K40 -> 5340.55 | L41: =+'4050'!L41+'4060'!L41+'4070'!L41+'4080'!L41+'40A0'!L41+'40B0'!L41+'40C0'!L41+'4000'!L40 -> 5546.55 | ... P41: =+'4050'!P41+'4060'!P41+'4070'!P41+'4080'!P41+'40A0'!P41+'40B0'!P41+'40C0'!P41+'4000'!P40 -> 9177.3 | Q41: =SUM(E41:P41) -> 80257.6 | T41: DW | U41: 2025 Business Plan grown 3%
D42: Parking Lot Maint.-Big Projects | E42: =+'4050'!E42+'4060'!E42+'4070'!E42+'4080'!E42+'40A0'!E42+'40B0'!E42+'40C0'!E42+'4000'!E41 -> 0 | F42: =+'4050'!F42+'4060'!F42+'4070'!F42+'4080'!F42+'40A0'!F42+'40B0'!F42+'40C0'!F42+'4000'!F41 -> 0 | G42: =+'4050'!G42+'4060'!G42+'4070'!G42+'4080'!G42+'40A0'!G42+'40B0'!G42+'40C0'!G42+'4000'!G41 -> 0 | H42: =+'4050'!H42+'4060'!H42+'4070'!H42+'4080'!H42+'40A0'!H42+'40B0'!H42+'40C0'!H42+'4000'!H41 -> 19905 | I42: =+'4050'!I42+'4060'!I42+'4070'!I42+'4080'!I42+'40A0'!I42+'40B0'!I42+'40C0'!I42+'4000'!I41 -> 20000 | J42: =+'4050'!J42+'4060'!J42+'4070'!J42+'4080'!J42+'40A0'!J42+'40B0'!J42+'40C0'!J42+'4000'!J41 -> 10300 | K42: =+'4050'!K42+'4060'!K42+'4070'!K42+'4080'!K42+'40A0'!K42+'40B0'!K42+'40C0'!K42+'4000'!K41 -> 12360 | L42: =+'4050'!L42+'4060'!L42+'4070'!L42+'4080'!L42+'40A0'!L42+'40B0'!L42+'40C0'!L42+'4000'!L41 -> 12360 | ... P42: =+'4050'!P42+'4060'!P42+'4070'!P42+'4080'!P42+'40A0'!P42+'40B0'!P42+'40C0'!P42+'4000'!P41 -> 0 | Q42: =SUM(E42:P42) -> 114830 | T42: DW | U42: Includes asphalt/pothole repairs and restriping
A43: 6360-8502 | C43: Parking Lot Maintenance | E43: =SUM(E40:E42) -> 5340.55 | F43: =SUM(F40:F42) -> 5546.55 | G43: =SUM(G40:G42) -> 9177.3 | H43: =SUM(H40:H42) -> 25245.55 | I43: =SUM(I40:I42) -> 25546.55 | J43: =SUM(J40:J42) -> 19477.3 | K43: =SUM(K40:K42) -> 17700.55 | L43: =SUM(L40:L42) -> 17906.55 | ... Q43: =SUM(Q40:Q42) -> 195087.6 | R43: 151867 | S43: =Q43/R43-1 -> 0.28459507
A45: 6370-8502 | C45: Snow Removal | E45: =+'4050'!E45+'4060'!E45+'4070'!E45+'4080'!E45+'40A0'!E45+'40B0'!E45+'40C0'!E45+'4000'!E44 -> 26393.75 | F45: =+'4050'!F45+'4060'!F45+'4070'!F45+'4080'!F45+'40A0'!F45+'40B0'!F45+'40C0'!F45+'4000'!F44 -> 26393.75 | G45: =+'4050'!G45+'4060'!G45+'4070'!G45+'4080'!G45+'40A0'!G45+'40B0'!G45+'40C0'!G45+'4000'!G44 -> 25363.75 | H45: =+'4050'!H45+'4060'!H45+'4070'!H45+'4080'!H45+'40A0'!H45+'40B0'!H45+'40C0'!H45+'4000'!H44 -> 0 | I45: =+'4050'!I45+'4060'!I45+'4070'!I45+'4080'!I45+'40A0'!I45+'40B0'!I45+'40C0'!I45+'4000'!I44 -> 0 | J45: =+'4050'!J45+'4060'!J45+'4070'!J45+'4080'!J45+'40A0'!J45+'40B0'!J45+'40C0'!J45+'4000'!J44 -> 0 | K45: =+'4050'!K45+'4060'!K45+'4070'!K45+'4080'!K45+'40A0'!K45+'40B0'!K45+'40C0'!K45+'4000'!K44 -> 0 | L45: =+'4050'!L45+'4060'!L45+'4070'!L45+'4080'!L45+'40A0'!L45+'40B0'!L45+'40C0'!L45+'4000'!L44 -> 0 | ... P45: =+'4050'!P45+'4060'!P45+'4070'!P45+'4080'!P45+'40A0'!P45+'40B0'!P45+'40C0'!P45+'4000'!P44 -> 25878.75 | Q45: =SUM(E45:P45) -> 110210 | R45: 79322 | S45: =Q45/R45-1 -> 0.38940017 | T45: DW | U45: 2025 Business Plan grown 3%
D47: Landscaping-Contractual | E47: =+'4050'!E47+'4060'!E47+'4070'!E47+'4080'!E47+'40A0'!E47+'40B0'!E47+'40C0'!E47+'4000'!E46 -> 0 | F47: =+'4050'!F47+'4060'!F47+'4070'!F47+'4080'!F47+'40A0'!F47+'40B0'!F47+'40C0'!F47+'4000'!F46 -> 0 | G47: =+'4050'!G47+'4060'!G47+'4070'!G47+'4080'!G47+'40A0'!G47+'40B0'!G47+'40C0'!G47+'4000'!G46 -> 10547.803 | H47: =+'4050'!H47+'4060'!H47+'4070'!H47+'4080'!H47+'40A0'!H47+'40B0'!H47+'40C0'!H47+'4000'!H46 -> 10547.803 | I47: =+'4050'!I47+'4060'!I47+'4070'!I47+'4080'!I47+'40A0'!I47+'40B0'!I47+'40C0'!I47+'4000'!I46 -> 10547.803 | J47: =+'4050'!J47+'4060'!J47+'4070'!J47+'4080'!J47+'40A0'!J47+'40B0'!J47+'40C0'!J47+'4000'!J46 -> 10547.803 | K47: =+'4050'!K47+'4060'!K47+'4070'!K47+'4080'!K47+'40A0'!K47+'40B0'!K47+'40C0'!K47+'4000'!K46 -> 10547.803 | L47: =+'4050'!L47+'4060'!L47+'4070'!L47+'4080'!L47+'40A0'!L47+'40B0'!L47+'40C0'!L47+'4000'!L46 -> 10547.803 | ... P47: =+'4050'!P47+'4060'!P47+'4070'!P47+'4080'!P47+'40A0'!P47+'40B0'!P47+'40C0'!P47+'4000'!P46 -> 0 | Q47: =SUM(E47:P47) -> 94930.226 | T47: DW | U47: 2025 Business Plan grown 3%
D48: Landscaping-Recurring | E48: =+'4050'!E48+'4060'!E48+'4070'!E48+'4080'!E48+'40A0'!E48+'40B0'!E48+'40C0'!E48+'4000'!E47 -> 0 | F48: =+'4050'!F48+'4060'!F48+'4070'!F48+'4080'!F48+'40A0'!F48+'40B0'!F48+'40C0'!F48 -> 0 | G48: =+'4050'!G48+'4060'!H48+'4070'!G48+'4080'!G48+'40A0'!G48+'40B0'!G48+'40C0'!G48+'4000'!G47 -> 3476.25 | H48: =+'4050'!H48+'4060'!I48+'4070'!H48+'4080'!H48+'40A0'!H48+'40B0'!H48+'40C0'!H48+'4000'!H47 -> 5330.25 | I48: =+'4050'!I48+'4060'!J48+'4070'!I48+'4080'!I48+'40A0'!I48+'40B0'!I48+'40C0'!I48+'4000'!I47 -> 9244.25 | J48: =+'4050'!J48+'4060'!K48+'4070'!J48+'4080'!J48+'40A0'!J48+'40B0'!J48+'40C0'!J48+'4000'!J47 -> 3476.25 | K48: =+'4050'!K48+'4060'!L48+'4070'!K48+'4080'!K48+'40A0'!K48+'40B0'!K48+'40C0'!K48+'4000'!K47 -> 3476.25 | L48: =+'4050'!L48+'4060'!M48+'4070'!L48+'4080'!L48+'40A0'!L48+'40B0'!L48+'40C0'!L48+'4000'!L47 -> 3476.25 | M48: =+'4050'!M48+'4060'!M48+'4070'!M48+'4080'!M48+'40A0'!M48+'40B0'!M48+'40C0'!M48+'4000'!M47 -> 7081.25 | N48: =+'4050'!N48+'4060'!N48+'4070'!N48+'4080'!N48+'40A0'!N48+'40B0'!N48+'40C0'!N48+'4000'!N47 -> 7493.25 | O48: =+'4050'!O48+'4060'!O48+'4070'!O48+'4080'!O48+'40A0'!O48+'40B0'!O48+'40C0'!O48+'4000'!O47 -> 1287.5 | P48: =+'4050'!P48+'4060'!P48+'4070'!P48+'4080'!P48+'40A0'!P48+'40B0'!P48+'40C0'!P48+'4000'!P47 -> 0 | Q48: =SUM(E48:P48) -> 44341.5 | T48: DW | U48: 2025 Business Plan grown 3%
D49: Landscaping-Big Projects | E49: =+'4050'!E49+'4060'!E49+'4070'!E49+'4080'!E49+'40A0'!E49+'40B0'!E49+'40C0'!E49+'4000'!E48 -> 4166.6667 | F49: =+'4050'!F49+'4060'!F49+'4070'!F49+'4080'!F49+'40A0'!F49+'40B0'!F49+'40C0'!F49+'4000'!F48 -> 4166.6667 | G49: =+'4050'!G49+'4060'!G49+'4070'!G49+'4080'!G49+'40A0'!G49+'40B0'!G49+'40C0'!G49+'4000'!G48 -> 4166.6667 | H49: =+'4050'!H49+'4060'!H49+'4070'!H49+'4080'!H49+'40A0'!H49+'40B0'!H49+'40C0'!H49+'4000'!H48 -> 4166.6667 | I49: =+'4050'!I49+'4060'!I49+'4070'!I49+'4080'!I49+'40A0'!I49+'40B0'!I49+'40C0'!I49+'4000'!I48 -> 4166.6667 | J49: =+'4050'!J49+'4060'!J49+'4070'!J49+'4080'!J49+'40A0'!J49+'40B0'!J49+'40C0'!J49+'4000'!J48 -> 4166.6667 | K49: =+'4050'!K49+'4060'!K49+'4070'!K49+'4080'!K49+'40A0'!K49+'40B0'!K49+'40C0'!K49+'4000'!K48 -> 4166.6667 | L49: =+'4050'!L49+'4060'!L49+'4070'!L49+'4080'!L49+'40A0'!L49+'40B0'!L49+'40C0'!L49+'4000'!L48 -> 4166.6667 | ... P49: =+'4050'!P49+'4060'!P49+'4070'!P49+'4080'!P49+'40A0'!P49+'40B0'!P49+'40C0'!P49+'4000'!P48 -> 4166.6667 | Q49: =SUM(E49:P49) -> 50000 | T49: DW | U49: Fountain repairs
A50: 6380-8502 | C50: Landscaping | E50: =SUM(E47:E49) -> 4166.6667 | F50: =SUM(F47:F49) -> 4166.6667 | G50: =SUM(G47:G49) -> 18190.72 | H50: =SUM(H47:H49) -> 20044.72 | I50: =SUM(I47:I49) -> 23958.72 | J50: =SUM(J47:J49) -> 18190.72 | K50: =SUM(K47:K49) -> 18190.72 | L50: =SUM(L47:L49) -> 18190.72 | ... Q50: =SUM(Q47:Q49) -> 189271.73 | R50: 145803 | S50: =Q50/R50-1 -> 0.29813327
A52: 6350-8502 | C52: Security | E52: =+'4050'!E52+'4060'!E52+'4070'!E52+'4080'!E52+'40A0'!E52+'40B0'!E52+'40C0'!E52+'4000'!E51 -> 2112 | F52: =+'4050'!F52+'4060'!F52+'4070'!F52+'4080'!F52+'40A0'!F52+'40B0'!F52+'40C0'!F52+'4000'!F51 -> 2112 | G52: =+'4050'!G52+'4060'!G52+'4070'!G52+'4080'!G52+'40A0'!G52+'40B0'!G52+'40C0'!G52+'4000'!G51 -> 2112 | H52: =+'4050'!H52+'4060'!H52+'4070'!H52+'4080'!H52+'40A0'!H52+'40B0'!H52+'40C0'!H52+'4000'!H51 -> 2112 | I52: =+'4050'!I52+'4060'!I52+'4070'!I52+'4080'!I52+'40A0'!I52+'40B0'!I52+'40C0'!I52+'4000'!I51 -> 2112 | J52: =+'4050'!J52+'4060'!J52+'4070'!J52+'4080'!J52+'40A0'!J52+'40B0'!J52+'40C0'!J52+'4000'!J51 -> 2112 | K52: =+'4050'!K52+'4060'!K52+'4070'!K52+'4080'!K52+'40A0'!K52+'40B0'!K52+'40C0'!K52+'4000'!K51 -> 2112 | L52: =+'4050'!L52+'4060'!L52+'4070'!L52+'4080'!L52+'40A0'!L52+'40B0'!L52+'40C0'!L52+'4000'!L51 -> 2112 | ... P52: =+'4050'!P52+'4060'!P52+'4070'!P52+'4080'!P52+'40A0'!P52+'40B0'!P52+'40C0'!P52+'4000'!P51 -> 2112 | Q52: =SUM(E52:P52) -> 25344 | R52: 28451 | S52: =Q52/R52-1 -> -0.1092053 | U52: 2025 Business Plan grown 3%
A54: 6610-8502 | B54: (BP) | C54: Management Fee | E54: ='4050'!E54+'4060'!E54+'4070'!E54+'4080'!E54+'40A0'!E54+'40B0'!E54+'40C0'!E54+'4000'!E53 -> 21235 | F54: ='4050'!F54+'4060'!F54+'4070'!F54+'4080'!F54+'40A0'!F54+'40B0'!F54+'40C0'!F54+'4000'!F53 -> 21072 | G54: ='4050'!G54+'4060'!G54+'4070'!G54+'4080'!G54+'40A0'!G54+'40B0'!G54+'40C0'!G54+'4000'!G53 -> 21316 | H54: ='4050'!H54+'4060'!H54+'4070'!H54+'4080'!H54+'40A0'!H54+'40B0'!H54+'40C0'!H54+'4000'!H53 -> 21238 | I54: ='4050'!I54+'4060'!I54+'4070'!I54+'4080'!I54+'40A0'!I54+'40B0'!I54+'40C0'!I54+'4000'!I53 -> 21344 | J54: ='4050'!J54+'4060'!J54+'4070'!J54+'4080'!J54+'40A0'!J54+'40B0'!J54+'40C0'!J54+'4000'!J53 -> 21708 | K54: ='4050'!K54+'4060'!K54+'4070'!K54+'4080'!K54+'40A0'!K54+'40B0'!K54+'40C0'!K54+'4000'!K53 -> 21112 | L54: ='4050'!L54+'4060'!L54+'4070'!L54+'4080'!L54+'40A0'!L54+'40B0'!L54+'40C0'!L54+'4000'!L53 -> 21051 | ... P54: ='4050'!P54+'4060'!P54+'4070'!P54+'4080'!P54+'40A0'!P54+'40B0'!P54+'40C0'!P54+'4000'!P53 -> 20768 | Q54: =SUM(E54:P54) -> 253013 | R54: 255695 | S54: =Q54/R54-1 -> -0.010489059 | U54: 4% EGR for 5-8, 6% EGR for A-C
...

Sheet 4000
B1: Unallocated Expenses-G&A, Interest | J1: =+'NI LLC-Consolidated'!J1 -> Operating Budget | Q1: ='NI LLC-Consolidated'!Q1 -> 46023
J2: ='NI LLC-Consolidated'!J2 -> Neshaminy Interplex LLC
Q3: =Q1 -> 46023
E4: Jan | F4: Feb | G4: Mar | H4: Apr | I4: May | J4: Jun | K4: Jul | L4: Aug | M4: Sep | N4: Oct | O4: Nov | P4: Dec | Q4: Total
D6: Occupancy %
B7: Revenues
A9: 4230-8501 | C9: Rental Income | Q9: =SUM(E9:P9) -> 0
A10: 4240-8501 | C10: Percentage Rents | Q10: =SUM(E10:P10) -> 0
A11: 4990-8501 | C11: Miscellaneous | Q11: =SUM(E11:P11) -> 0
A12: 9190-8501 | C12: Interest Income | Q12: =SUM(E12:P12) -> 0
C13: Total Rental and Other | E13: =SUM(E9:E12) -> 0 | F13: =SUM(F9:F12) -> 0 | G13: =SUM(G9:G12) -> 0 | H13: =SUM(H9:H12) -> 0 | I13: =SUM(I9:I12) -> 0 | J13: =SUM(J9:J12) -> 0 | K13: =SUM(K9:K12) -> 0 | L13: =SUM(L9:L12) -> 0 | ... Q13: =SUM(Q9:Q12) -> 0
B15: Reimbursements
A16: 4710-8502 | C16: Electric | Q16: =SUM(E16:P16) -> 0
A17: 4910-8502 | C17: Common Area Maintenance | Q17: =SUM(E17:P17) -> 0
A18: 4920-8502 | C18: Real Estate Taxes | Q18: =SUM(E18:P18) -> 0
A19: 4930-8502 | C19: Insurance | Q19: =SUM(E19:P19) -> 0
C21: Total Reimbursements | E21: =SUM(E16:E19) -> 0 | F21: =SUM(F16:F19) -> 0 | G21: =SUM(G16:G19) -> 0 | H21: =SUM(H16:H19) -> 0 | I21: =SUM(I16:I19) -> 0 | J21: =SUM(J16:J19) -> 0 | K21: =SUM(K16:K19) -> 0 | L21: =SUM(L16:L19) -> 0 | ... Q21: =SUM(Q16:Q19) -> 0
B23: TOTAL REVENUES | E23: =+E13+E21 -> 0 | F23: =+F13+F21 -> 0 | G23: =+G13+G21 -> 0 | H23: =+H13+H21 -> 0 | I23: =+I13+I21 -> 0 | J23: =+J13+J21 -> 0 | K23: =+K13+K21 -> 0 | L23: =+L13+L21 -> 0 | ... Q23: =+Q13+Q21 -> 0
B25: Reimbursable Expenses
A26: 6030-8502 | C26: Maintenance Salaries | Q26: =SUM(E26:P26) -> 0
A28: 6120-8502 | C28: Electric | Q28: =SUM(E28:P28) -> 0
A30: 6130-8502 | C30: Water & Sewer | Q30: =SUM(E30:P30) -> 0
D32: Building Maint.-Contractual | Q32: =SUM(E32:P32) -> 0
D33: Building Maint.-Recurring | Q33: =SUM(E33:P33) -> 0
D34: Building Maint.-Big Projects | Q34: =SUM(E34:P34) -> 0
A35: 6220-8502 | C35: Building Maintenance | E35: =SUM(E32:E34) -> 0 | F35: =SUM(F32:F34) -> 0 | G35: =SUM(G32:G34) -> 0 | H35: =SUM(H32:H34) -> 0 | I35: =SUM(I32:I34) -> 0 | J35: =SUM(J32:J34) -> 0 | K35: =SUM(K32:K34) -> 0 | L35: =SUM(L32:L34) -> 0 | ... Q35: =SUM(Q32:Q34) -> 0
A37: 6330-8502 | B37: (SC) | C37: Parking Lot Cleaning | Q37: =SUM(E37:P37) -> 0
D39: Parking Lot Maint.-Contractual | Q39: =SUM(E39:P39) -> 0
D40: Parking Lot Maint.-Recurring | Q40: =SUM(E40:P40) -> 0
D41: Parking Lot Maint.-Big Projects | Q41: =SUM(E41:P41) -> 0
A42: 6360-8502 | C42: Parking Lot Maintenance | E42: =SUM(E39:E41) -> 0 | F42: =SUM(F39:F41) -> 0 | G42: =SUM(G39:G41) -> 0 | H42: =SUM(H39:H41) -> 0 | I42: =SUM(I39:I41) -> 0 | J42: =SUM(J39:J41) -> 0 | K42: =SUM(K39:K41) -> 0 | L42: =SUM(L39:L41) -> 0 | ... Q42: =SUM(Q39:Q41) -> 0
A44: 6370-8502 | C44: Snow Removal | Q44: =SUM(E44:P44) -> 0
D46: Landscaping-Contractual | Q46: =SUM(E46:P46) -> 0
D47: Landscaping-Recurring | Q47: =SUM(E47:P47) -> 0
D48: Landscaping-Big Projects | Q48: =SUM(E48:P48) -> 0
A49: 6380-8502 | C49: Landscaping | E49: =SUM(E46:E48) -> 0 | F49: =SUM(F46:F48) -> 0 | G49: =SUM(G46:G48) -> 0 | H49: =SUM(H46:H48) -> 0 | I49: =SUM(I46:I48) -> 0 | J49: =SUM(J46:J48) -> 0 | K49: =SUM(K46:K48) -> 0 | L49: =SUM(L46:L48) -> 0 | ... Q49: =SUM(Q46:Q48) -> 0
A51: 6350-8502 | C51: Security | Q51: =SUM(E51:P51) -> 0
A53: 6610-8502 | B53: (BP) | C53: Management Fee | E53: =ROUND(E$23*0.04,0) -> 0 | F53: =ROUND(F$23*0.04,0) -> 0 | G53: =ROUND(G$23*0.04,0) -> 0 | H53: =ROUND(H$23*0.04,0) -> 0 | I53: =ROUND(I$23*0.04,0) -> 0 | J53: =ROUND(J$23*0.04,0) -> 0 | K53: =ROUND(K$23*0.04,0) -> 0 | L53: =ROUND(L$23*0.04,0) -> 0 | ... P53: =ROUND(P$23*0.04,0) -> 0 | Q53: =SUM(E53:P53) -> 0
A55: 6270-8502 | C55: Trash Removal | Q55: =SUM(E55:P55) -> 0
A57: 6410-8502 | C57: Real Estate Taxes | Q57: =SUM(E57:P57) -> 0
...

Sheet 4050
B1: 4050 | J1: =+'NI LLC-Consolidated'!J1 -> Operating Budget | Q1: ='NI LLC-Consolidated'!Q1 -> 46023
J2: ='NI LLC-Consolidated'!J2 -> Neshaminy Interplex LLC
Q3: =Q1 -> 46023 | S3: 7/2025 Reprojections
B4: 54008 | E4: Jan | F4: Feb | G4: Mar | H4: Apr | I4: May | J4: Jun | K4: Jul | L4: Aug | M4: Sep | N4: Oct | O4: Nov | P4: Dec | Q4: Total | R4: Total PSF | S4: Total | T4: Var. | U4: Input | V4: Notes
D6: Occupancy % | E6: ='Renew & Vac'!AJ9 -> 0.5858 | F6: ='Renew & Vac'!AK9 -> 0.5858 | G6: ='Renew & Vac'!AL9 -> 0.5858 | H6: ='Renew & Vac'!AM9 -> 0.5858 | I6: ='Renew & Vac'!AN9 -> 0.5858 | J6: ='Renew & Vac'!AO9 -> 0.5858 | K6: ='Renew & Vac'!AP9 -> 0.5858 | L6: ='Renew & Vac'!AQ9 -> 0.5858 | ... P6: ='Renew & Vac'!AU9 -> 0.5858
D7: Occupancy SF | E7: =$B$4*E6 -> 31637.886 | F7: =$B$4*F6 -> 31637.886 | G7: =$B$4*G6 -> 31637.886 | H7: =$B$4*H6 -> 31637.886 | I7: =$B$4*I6 -> 31637.886 | J7: =$B$4*J6 -> 31637.886 | K7: =$B$4*K6 -> 31637.886 | L7: =$B$4*L6 -> 31637.886 | ... P7: =$B$4*P6 -> 31637.886
B8: Revenues
A10: 4230-8501 | C10: Rental Income - In Place | E10: =SUMIFS('In Place Revenue'!$G:$G,'In Place Revenue'!$A:$A,"4050",'In Place Revenue'!$H:$H,1) -> 43151.75 | F10: =SUMIFS('In Place Revenue'!$G:$G,'In Place Revenue'!$A:$A,"4050",'In Place Revenue'!$H:$H,2) -> 43151.75 | G10: =SUMIFS('In Place Revenue'!$G:$G,'In Place Revenue'!$A:$A,"4050",'In Place Revenue'!$H:$H,3) -> 43151.75 | H10: =SUMIFS('In Place Revenue'!$G:$G,'In Place Revenue'!$A:$A,"4050",'In Place Revenue'!$H:$H,4) -> 37187.33 | I10: =SUMIFS('In Place Revenue'!$G:$G,'In Place Revenue'!$A:$A,"4050",'In Place Revenue'!$H:$H,5) -> 37187.33 | J10: =SUMIFS('In Place Revenue'!$G:$G,'In Place Revenue'!$A:$A,"4050",'In Place Revenue'!$H:$H,6) -> 37187.33 | K10: =SUMIFS('In Place Revenue'!$G:$G,'In Place Revenue'!$A:$A,"4050",'In Place Revenue'!$H:$H,7) -> 19840.96 | L10: =SUMIFS('In Place Revenue'!$G:$G,'In Place Revenue'!$A:$A,"4050",'In Place Revenue'!$H:$H,8) -> 19840.96 | M10: =SUMIFS('In Place Revenue'!$G:$G,'In Place Revenue'!$A:$A,"4050",'In Place Revenue'!$H:$H,9) -> 19840.96 | N10: =SUMIFS('In Place Revenue'!$G:$G,'In Place Revenue'!$A:$A,"4050",'In Place Revenue'!$H:$H,10) -> 11025.71 | O10: =SUMIFS('In Place Revenue'!$G:$G,'In Place Revenue'!$A:$A,"4050",'In Place Revenue'!$H:$H,11) -> 7562.42 | P10: =SUMIFS('In Place Revenue'!$G:$G,'In Place Revenue'!$A:$A,"4050",'In Place Revenue'!$H:$H,12) -> 7562.42 | Q10: =SUM(E10:P10) -> 326690.67 | R10: =Q10/$B$4 -> 6.0489311 | S10: 534079.37 | T10: =IFERROR(Q10/S10-1,"-") -> -0.38831064
A11: 4230-8501 | C11: Rental Income - New & Renewal | E11: ='Renew & Vac'!AJ10 -> 5483.7083 | F11: ='Renew & Vac'!AK10 -> 5483.7083 | G11: ='Renew & Vac'!AL10 -> 5483.7083 | H11: ='Renew & Vac'!AM10 -> 11448.125 | I11: ='Renew & Vac'!AN10 -> 11448.125 | J11: ='Renew & Vac'!AO10 -> 11448.125 | K11: ='Renew & Vac'!AP10 -> 28841.292 | L11: ='Renew & Vac'!AQ10 -> 28841.292 | ... P11: ='Renew & Vac'!AU10 -> 41119.833 | Q11: =SUM(E11:P11) -> 257215.58 | R11: =Q11/$B$4 -> 4.762546 | T11: =IFERROR(Q11/S11-1,"-") -> -
A12: 4240-8501 | C12: Percentage Rents | E12: 0 | F12: 0 | G12: 0 | H12: 0 | I12: 0 | J12: 0 | K12: 0 | L12: 0 | M12: 0 | N12: 0 | O12: 0 | P12: 0 | Q12: =SUM(E12:P12) -> 0 | R12: =Q12/$B$4 -> 0 | T12: =R12/S12-1 -> #DIV/0!
A13: 4990-8501 | C13: Miscellaneous | E13: 0 | F13: 0 | G13: 0 | H13: 0 | I13: 0 | J13: 0 | K13: 0 | L13: 0 | M13: 0 | N13: 0 | O13: 0 | P13: 0 | Q13: =SUM(E13:P13) -> 0 | R13: =Q13/$B$4 -> 0 | T13: =IFERROR(Q13/S13-1,"-") -> -
A14: 9190-8501 | C14: Interest Income | E14: 207 | F14: 207 | G14: 207 | H14: 207 | I14: 207 | J14: 207 | K14: 207 | L14: 207 | M14: 207 | N14: 207 | O14: 207 | P14: 207 | Q14: =SUM(E14:P14) -> 2484 | R14: =Q14/$B$4 -> 0.045993186 | T14: =IFERROR(Q14/S14-1,"-") -> - | U14: DW | V14: Annualized one month of interest from recent statement
C15: Total Rental and Other | E15: =SUM(E10:E14) -> 48842.458 | F15: =SUM(F10:F14) -> 48842.458 | G15: =SUM(G10:G14) -> 48842.458 | H15: =SUM(H10:H14) -> 48842.455 | I15: =SUM(I10:I14) -> 48842.455 | J15: =SUM(J10:J14) -> 48842.455 | K15: =SUM(K10:K14) -> 48889.252 | L15: =SUM(L10:L14) -> 48889.252 | ... Q15: =SUM(Q10:Q14) -> 586390.25 | R15: =Q15/$B$4 -> 10.85747 | S15: =SUM(S10:S14) -> 534079.37 | T15: =IFERROR(Q15/S15-1,"-") -> 0.097945898
B17: Reimbursements
A18: 4710-8502 | C18: Electric | E18: =E6*E29 -> 7434.3878 | F18: =F6*F29 -> 6089.391 | G18: =G6*G29 -> 5289.1882 | H18: =H6*H29 -> 5077.1286 | I18: =I6*I29 -> 4161.5232 | J18: =J6*J29 -> 4534.6778 | K18: =K6*K29 -> 5136.2944 | L18: =L6*L29 -> 5243.4958 | ... P18: =P6*P29 -> 6659.9602 | Q18: =SUM(E18:P18) -> 64091.792 | R18: =Q18/$B$4 -> 1.1867092 | S18: 61616.19 | T18: =IFERROR(Q18/S18-1,"-") -> 0.040177788 | U18: DW | V18: =Q18/Q29*100&"% Set to occupancy" -> 58.58% Set to occupancy
A19: 4910-8502 | C19: Common Area Maintenance | E19: =+'Tenant Recoveries'!F21 -> 3600 | F19: =+E19 -> 3600 | G19: =+F19 -> 3600 | H19: =+G19 -> 3600 | I19: =+H19 -> 3600 | J19: =+I19 -> 3600 | K19: =+J19 -> 3600 | L19: =+K19 -> 3600 | M19: =+L19 -> 3600 | ... P19: =+O19 -> 3600 | Q19: =SUM(E19:P19) -> 43200 | R19: =Q19/$B$4 -> 0.7998815 | S19: 33608 | T19: =IFERROR(Q19/S19-1,"-") -> 0.28540824 | V19: =Q19/(Q71-Q63-Q58-Q29) -> 0.1462202
A20: 4920-8502 | C20: Real Estate Taxes | E20: =+'Tenant Recoveries'!F22 -> 200 | F20: =+E20 -> 200 | G20: =+F20 -> 200 | H20: =+G20 -> 200 | I20: =+H20 -> 200 | J20: =+I20 -> 200 | K20: =+J20 -> 200 | L20: =+K20 -> 200 | M20: =+L20 -> 200 | ... P20: =+O20 -> 200 | Q20: =SUM(E20:P20) -> 2400 | R20: =Q20/$B$4 -> 0.044437861 | S20: 1302 | T20: =IFERROR(Q20/S20-1,"-") -> 0.84331797 | V20: =Q20/Q58 -> 0.053031006
A21: 4930-8502 | C21: Insurance | Q21: =SUM(E21:P21) -> 0 | R21: =Q21/$B$4 -> 0 | S21: 0 | T21: =IFERROR(Q21/S21-1,"-") -> -
C22: Total Reimbursements | E22: =SUM(E18:E21) -> 11234.388 | F22: =SUM(F18:F21) -> 9889.391 | G22: =SUM(G18:G21) -> 9089.1882 | H22: =SUM(H18:H21) -> 8877.1286 | I22: =SUM(I18:I21) -> 7961.5232 | J22: =SUM(J18:J21) -> 8334.6778 | K22: =SUM(K18:K21) -> 8936.2944 | L22: =SUM(L18:L21) -> 9043.4958 | ... Q22: =SUM(Q18:Q21) -> 109691.79 | R22: =Q22/$B$4 -> 2.0310286 | S22: =SUM(S18:S21) -> 96526.19 | T22: =IFERROR(Q22/S22-1,"-") -> 0.13639409
R23: =Q23/$B$4 -> 0
B24: TOTAL REVENUES | E24: =+E15+E22 -> 60076.846 | F24: =+F15+F22 -> 58731.849 | G24: =+G15+G22 -> 57931.647 | H24: =+H15+H22 -> 57719.584 | I24: =+I15+I22 -> 56803.978 | J24: =+J15+J22 -> 57177.133 | K24: =+K15+K22 -> 57825.546 | L24: =+L15+L22 -> 57932.747 | ... Q24: =+Q15+Q22 -> 696082.05 | R24: =Q24/$B$4 -> 12.888499 | S24: =+S15+S22 -> 630605.56 | T24: =IFERROR(Q24/S24-1,"-") -> 0.10383113
B26: Reimbursable Expenses
A27: 6030-8502 | C27: Maintenance Salaries | E27: ='Allocated Expenses'!F6 -> 1104.9382 | F27: ='Allocated Expenses'!G6 -> 1104.9382 | G27: ='Allocated Expenses'!H6 -> 1104.9382 | H27: ='Allocated Expenses'!I6 -> 1104.9382 | I27: ='Allocated Expenses'!J6 -> 1104.9382 | J27: ='Allocated Expenses'!K6 -> 1104.9382 | K27: ='Allocated Expenses'!L6 -> 1104.9382 | L27: ='Allocated Expenses'!M6 -> 1104.9382 | ... P27: ='Allocated Expenses'!Q6 -> 1104.9382 | Q27: =SUM(E27:P27) -> 13259.259 | R27: =Q27/$B$4 -> 0.24550546 | S27: 9312 | T27: =IFERROR(Q27/S27-1,"-") -> 0.42388946 | V27: Based on 2026 Payroll budget
A29: 6120-8502 | C29: Electric | E29: 12691 | F29: 10395 | G29: 9029 | H29: 8667 | I29: 7104 | J29: 7741 | K29: 8768 | L29: 8951 | M29: 7497 | N29: 8898 | O29: 8299 | P29: 11369 | Q29: =SUM(E29:P29) -> 109409 | R29: =Q29/$B$4 -> 2.0257925 | S29: 106977.43 | T29: =IFERROR(Q29/S29-1,"-") -> 0.022729748 | U29: DW | V29: Data\Shared\Properties\Business Plans - All Entities\2026\ISG Electric data
A31: 6130-8502 | C31: Water & Sewer | E31: ='Water Sewer'!D10 -> 903.31 | F31: ='Water Sewer'!E10 -> 919.79 | G31: ='Water Sewer'!F10 -> 962.02 | H31: ='Water Sewer'!G10 -> 946.57 | I31: ='Water Sewer'!H10 -> 1572.81 | J31: ='Water Sewer'!I10 -> 2022.92 | K31: ='Water Sewer'!J10 -> 2235.1 | L31: ='Water Sewer'!K10 -> 2706.84 | ... P31: ='Water Sewer'!O10 -> 975.41 | Q31: =SUM(E31:P31) -> 19406.23 | R31: =Q31/$B$4 -> 0.3593214 | S31: 11349.98 | T31: =IFERROR(Q31/S31-1,"-") -> 0.70980301 | U31: AK | V31: 2025 Business Plan grown 3%
D33: Building Maint.-Contractual | E33: ='Building Maint'!C17 -> 2737 | F33: ='Building Maint'!D17 -> 1037 | G33: ='Building Maint'!E17 -> 6671 | H33: ='Building Maint'!F17 -> 4383 | I33: ='Building Maint'!G17 -> 1037 | J33: ='Building Maint'!H17 -> 6653 | K33: ='Building Maint'!I17 -> 2737 | L33: ='Building Maint'!J17 -> 1037 | ... P33: ='Building Maint'!N17 -> 6653 | Q33: =SUM(E33:P33) -> 45018 | R33: =Q33/$B$4 -> 0.83354318 | U33: DW | V33: 2025 Business Plan grown 3%
D34: Building Maint.-Recurring | E34: ='Building Maint'!C6 -> 2350 | F34: ='Building Maint'!D6 -> 1100 | G34: ='Building Maint'!E6 -> 1300 | H34: ='Building Maint'!F6 -> 1725 | I34: ='Building Maint'!G6 -> 2940 | J34: ='Building Maint'!H6 -> 1475 | K34: ='Building Maint'!I6 -> 3845 | L34: ='Building Maint'!J6 -> 1100 | ... P34: ='Building Maint'!N6 -> 1100 | Q34: =SUM(E34:P34) -> 21535 | R34: =Q34/$B$4 -> 0.39873722 | U34: DW | V34: 2025 Business Plan grown 3%
D35: Building Maint.-Big Projects | G35: 10000 | N35: 10000 | Q35: =SUM(E35:P35) -> 20000 | R35: =Q35/$B$4 -> 0.37031551 | U35: AK | V35: Contingency for repairs
A36: 6220-8502 | C36: Building Maintenance | E36: =SUM(E33:E35) -> 5087 | F36: =SUM(F33:F35) -> 2137 | G36: =SUM(G33:G35) -> 17971 | H36: =SUM(H33:H35) -> 6108 | I36: =SUM(I33:I35) -> 3977 | J36: =SUM(J33:J35) -> 8128 | K36: =SUM(K33:K35) -> 6582 | L36: =SUM(L33:L35) -> 2137 | ... Q36: =SUM(Q33:Q35) -> 86553 | R36: =Q36/$B$4 -> 1.6025959 | S36: 86001.72 | T36: =IFERROR(Q36/S36-1,"-") -> 0.0064101044
A38: 6330-850 | B38: (SC) | C38: Parking Lot Cleaning | Q38: =SUM(E38:P38) -> 0 | R38: =Q38/$B$4 -> 0
D40: Parking Lot Maint.-Contractual | Q40: =SUM(E40:P40) -> 0 | R40: =Q40/$B$4 -> 0
D41: Parking Lot Maint.-Recurring | E41: ='Parking Lot Maint'!C6 -> 803.4 | F41: ='Parking Lot Maint'!D6 -> 803.4 | G41: ='Parking Lot Maint'!E6 -> 1323.55 | H41: ='Parking Lot Maint'!F6 -> 803.4 | I41: ='Parking Lot Maint'!G6 -> 803.4 | J41: ='Parking Lot Maint'!H6 -> 1323.55 | K41: ='Parking Lot Maint'!I6 -> 803.4 | L41: ='Parking Lot Maint'!J6 -> 803.4 | ... P41: ='Parking Lot Maint'!N6 -> 1323.55 | Q41: =SUM(E41:P41) -> 11721.4 | R41: =Q41/$B$4 -> 0.21703081 | U41: DW | V41: 2025 Business Plan grown 3%
D42: Parking Lot Maint.-Big Projects | H42: 6000 | M42: 6000 | Q42: =SUM(E42:P42) -> 12000 | R42: =Q42/$B$4 -> 0.22218931 | U42: AK | V42: Estimate for asphalt/pothole repairs
A43: 6330-8502 | C43: Parking Lot Maintenance | E43: =SUM(E40:E42) -> 803.4 | F43: =SUM(F40:F42) -> 803.4 | G43: =SUM(G40:G42) -> 1323.55 | H43: =SUM(H40:H42) -> 6803.4 | I43: =SUM(I40:I42) -> 803.4 | J43: =SUM(J40:J42) -> 1323.55 | K43: =SUM(K40:K42) -> 803.4 | L43: =SUM(L40:L42) -> 803.4 | ... Q43: =SUM(Q40:Q42) -> 23721.4 | R43: =Q43/$B$4 -> 0.43922012 | S43: 16795.6 | T43: =IFERROR(Q43/S43-1,"-") -> 0.412358
A45: 6370-8502 | C45: Snow Removal | E45: =1.03*3500 -> 3605 | F45: =1.03*3500 -> 3605 | G45: =1.03*3500 -> 3605 | O45: =1.03*1000 -> 1030 | P45: =1.03*3500 -> 3605 | Q45: =SUM(E45:P45) -> 15450 | R45: =Q45/$B$4 -> 0.28606873 | S45: 11247.51 | T45: =IFERROR(Q45/S45-1,"-") -> 0.37363737 | U45: DW | V45: 2025 Business Plan grown 3%
D47: Landscaping-Contractual | E47: ='Allocated Expenses'!F17 -> 0 | F47: ='Allocated Expenses'!G17 -> 0 | G47: ='Allocated Expenses'!H17 -> 922.69385 | H47: ='Allocated Expenses'!I17 -> 922.69385 | I47: ='Allocated Expenses'!J17 -> 922.69385 | J47: ='Allocated Expenses'!K17 -> 922.69385 | K47: ='Allocated Expenses'!L17 -> 922.69385 | L47: ='Allocated Expenses'!M17 -> 922.69385 | ... P47: ='Allocated Expenses'!Q17 -> 0 | Q47: =SUM(E47:P47) -> 8304.2446 | R47: =Q47/$B$4 -> 0.15375953 | U47: DW | V47: 2025 Business Plan grown 3%
D48: Landscaping-Recurring | E48: =Landscaping!C6 -> 0 | F48: =Landscaping!D6 -> 0 | G48: =Landscaping!E6 -> 463.5 | H48: =Landscaping!F6 -> 463.5 | I48: =Landscaping!G6 -> 2008.5 | J48: =Landscaping!H6 -> 463.5 | K48: =Landscaping!I6 -> 463.5 | L48: =Landscaping!J6 -> 463.5 | ... P48: =Landscaping!N6 -> 0 | Q48: =SUM(E48:P48) -> 7004 | R48: =Q48/$B$4 -> 0.12968449 | U48: DW | V48: 2025 Business Plan grown 3%
D49: Landscaping-Big Projects | E49: ='Allocated Expenses'!F28 -> 566.38519 | F49: ='Allocated Expenses'!G28 -> 566.38519 | G49: ='Allocated Expenses'!H28 -> 566.38519 | H49: ='Allocated Expenses'!I28 -> 566.38519 | I49: ='Allocated Expenses'!J28 -> 566.38519 | J49: ='Allocated Expenses'!K28 -> 566.38519 | K49: ='Allocated Expenses'!L28 -> 566.38519 | L49: ='Allocated Expenses'!M28 -> 566.38519 | ... P49: ='Allocated Expenses'!Q28 -> 566.38519 | Q49: =SUM(E49:P49) -> 6796.6223 | R49: =Q49/$B$4 -> 0.12584473 | U49: AK | V49: Fountain repairs
A50: 6380-8502 | C50: Landscaping | E50: =SUM(E47:E49) -> 566.38519 | F50: =SUM(F47:F49) -> 566.38519 | G50: =SUM(G47:G49) -> 1952.579 | H50: =SUM(H47:H49) -> 1952.579 | I50: =SUM(I47:I49) -> 3497.579 | J50: =SUM(J47:J49) -> 1952.579 | K50: =SUM(K47:K49) -> 1952.579 | L50: =SUM(L47:L49) -> 1952.579 | ... Q50: =SUM(Q47:Q49) -> 22104.867 | R50: =Q50/$B$4 -> 0.40928875 | S50: 14324.67 | T50: =IFERROR(Q50/S50-1,"-") -> 0.54313272
A52: 6350-8502 | C52: Security | E52: ='Allocated Expenses'!F39 -> 295.68 | F52: ='Allocated Expenses'!G39 -> 295.68 | G52: ='Allocated Expenses'!H39 -> 295.68 | H52: ='Allocated Expenses'!I39 -> 295.68 | I52: ='Allocated Expenses'!J39 -> 295.68 | J52: ='Allocated Expenses'!K39 -> 295.68 | K52: ='Allocated Expenses'!L39 -> 295.68 | L52: ='Allocated Expenses'!M39 -> 295.68 | ... P52: ='Allocated Expenses'!Q39 -> 295.68 | Q52: =SUM(E52:P52) -> 3548.16 | R52: =Q52/$B$4 -> 0.065696934 | S52: 3980.86 | T52: =IFERROR(Q52/S52-1,"-") -> -0.10869511 | U52: DW | V52: 2025 Business Plan grown 3%
...

Sheet 4060
