Workbook
Name \r: [1]TOTALS!#REF!
Name \r: [2]TOTALS!#REF!
Name \t: #N/A
Name _39_PNB: #N/A
Name _57_2_PNB: #N/A
Name _57_3_PNB: #N/A
Name _57_5_PNB: #N/A
Name _70_NOTE: #N/A

Sheet The Office Works
F1: 4900 | J1: Operating Budget | R1: 46023
J2: The Office Works
F6: Jan | G6: Feb | H6: Mar | I6: Apr | J6: May | K6: Jun | L6: Jul | M6: Aug | N6: Sep | O6: Oct | P6: Nov | Q6: Dec | R6: Total | T6: Notes
B8: Revenues:
A9: 4230-8501 | C9: Rental Income | F9: ='Monthly Rent Roll & CIP'!E36 -> 22330 | G9: ='Monthly Rent Roll & CIP'!F36 -> 21435 | H9: ='Monthly Rent Roll & CIP'!G36 -> 21495 | I9: ='Monthly Rent Roll & CIP'!H36 -> 22345 | J9: ='Monthly Rent Roll & CIP'!I36 -> 22345 | K9: ='Monthly Rent Roll & CIP'!J36 -> 22365 | L9: ='Monthly Rent Roll & CIP'!K36 -> 23285 | M9: ='Monthly Rent Roll & CIP'!L36 -> 23285 | ... Q9: ='Monthly Rent Roll & CIP'!P36 -> 23305 | R9: =SUM(F9:Q9) -> 272085
A10: 4990-8501 | C10: Equipment Rentals & Other | F10: 5 | G10: 5 | H10: 5 | I10: 5 | J10: 5 | K10: 5 | L10: 5 | M10: 5 | N10: 5 | O10: 5 | P10: 5 | Q10: 5 | R10: =SUM(F10:Q10) -> 60 | T10: File cabinet rental for one tenant
A11: 9190-8501 | C11: Interest Income | F11: 2 | G11: 2 | H11: 2 | I11: 2 | J11: 2 | K11: 2 | L11: 2 | M11: 2 | N11: 2 | O11: 2 | P11: 2 | Q11: 2
C12: TOTAL RENTAL & OTHER | F12: =SUM(F9:F11) -> 22337 | G12: =SUM(G9:G11) -> 21442 | H12: =SUM(H9:H11) -> 21502 | I12: =SUM(I9:I11) -> 22352 | J12: =SUM(J9:J11) -> 22352 | K12: =SUM(K9:K11) -> 22372 | L12: =SUM(L9:L11) -> 23292 | M12: =SUM(M9:M11) -> 23292 | ... R12: =SUM(R9:R11) -> 272145
B14: Reimbursements:
A15: 4810-8502 | C15: CIP Memberships | F15: ='Monthly Rent Roll & CIP'!E57 -> 2130 | G15: ='Monthly Rent Roll & CIP'!F57 -> 2130 | H15: ='Monthly Rent Roll & CIP'!G57 -> 2130 | I15: ='Monthly Rent Roll & CIP'!H57 -> 2130 | J15: ='Monthly Rent Roll & CIP'!I57 -> 2130 | K15: ='Monthly Rent Roll & CIP'!J57 -> 2130 | L15: ='Monthly Rent Roll & CIP'!K57 -> 2130 | M15: ='Monthly Rent Roll & CIP'!L57 -> 2130 | ... Q15: ='Monthly Rent Roll & CIP'!P57 -> 2130 | R15: =SUM(F15:Q15) -> 25560 | T15: Mailbox "virtual office" rentals. Approx $75/mailbox
A16: 4820-8502 | C16: Conference Room Rental | F16: 60 | G16: 60 | H16: 60 | I16: 100 | J16: 60 | K16: 60 | L16: 60 | M16: 60 | N16: 100 | O16: 60 | P16: 60 | Q16: 60 | R16: =SUM(F16:Q16) -> 800 | T16: $25-35/hr or $200 for full day
A17: 4830-8502 | C17: Supplies (6960-8502) | F17: 37 | G17: 37 | H17: 37 | I17: 37 | J17: 37 | K17: 37 | L17: 37 | M17: 37 | N17: 37 | O17: 37 | P17: 37 | Q17: 37 | R17: =SUM(F17:Q17) -> 444 | T17: Paper, name on directory, "service supply"
A18: 4840-8502 | C18: Postage (1PO-2PO) (1PP-2PP) | F18: 103 | G18: 103 | H18: 103 | I18: 103 | J18: 103 | K18: 103 | L18: 103 | M18: 103 | N18: 103 | O18: 103 | P18: 103 | Q18: 103 | R18: =SUM(F18:Q18) -> 1236 | T18: Cost of postage + 20% markup
A19: 4850-8502 | C19: Clerical (Notary-KCP) (1CE-2NO) | F19: 450 | G19: 450 | H19: 450 | I19: 450 | J19: 450 | K19: 450 | L19: 450 | M19: 450 | N19: 450 | O19: 450 | P19: 450 | Q19: 450 | R19: =SUM(F19:Q19) -> 5400 | T19: KCP phone
A20: 4860-8502 | C20: Copier - B&W (1CI) | F20: 79 | G20: 79 | H20: 79 | I20: 79 | J20: 79 | K20: 79 | L20: 79 | M20: 79 | N20: 79 | O20: 79 | P20: 79 | Q20: 79 | R20: =SUM(F20:Q20) -> 948 | T20: $0.13 per page
A21: 4890-8502 | C21: Copier - Color (1CO) | F21: 30 | G21: 30 | H21: 30 | I21: 30 | J21: 30 | K21: 30 | L21: 30 | M21: 30 | N21: 30 | O21: 30 | P21: 30 | Q21: 30 | R21: =SUM(F21:Q21) -> 360 | T21: $.49 per page
A22: 4870-8502 | C22: Start-up (2UP) | F22: 0 | G22: 0 | H22: 0 | I22: 325 | J22: 0 | K22: 0 | L22: 325 | M22: 0 | N22: 0 | O22: 0 | P22: 0 | Q22: 0 | R22: =SUM(F22:Q22) -> 650 | T22: Flat fee for paint in office, locks changed, mailbox key
A23: 4880-8502 | C23: Fax (1FX) | F23: 1 | G23: 1 | H23: 1 | I23: 1 | J23: 1 | K23: 1 | L23: 1 | M23: 1 | N23: 1 | O23: 1 | P23: 1 | Q23: 1 | R23: =SUM(F23:Q23) -> 12
A24: 4900-8502 | C24: Telephone (1CL-1VM-1CK) | F24: 975 | G24: 975 | H24: 975 | I24: 975 | J24: 975 | K24: 975 | L24: 975 | M24: 975 | N24: 975 | O24: 975 | P24: 975 | Q24: 975 | R24: =SUM(F24:Q24) -> 11700 | T24: Some tenants have phone baked into base rent
A25: 4950-8502 | C25: Internet (2IP) | F25: 2052 | G25: 2052 | H25: 2052 | I25: 2052 | J25: 2052 | K25: 2052 | L25: 2052 | M25: 2052 | N25: 2052 | O25: 2052 | P25: 2052 | Q25: 2052 | R25: =SUM(F25:Q25) -> 24624 | T25: Some tenants have internet baked into base rent
C26: TOTAL REIMBURSEMENTS | F26: =SUM(F15:F25) -> 5917 | G26: =SUM(G15:G25) -> 5917 | H26: =SUM(H15:H25) -> 5917 | I26: =SUM(I15:I25) -> 6282 | J26: =SUM(J15:J25) -> 5917 | K26: =SUM(K15:K25) -> 5917 | L26: =SUM(L15:L25) -> 6242 | M26: =SUM(M15:M25) -> 5917 | ... R26: =SUM(R15:R25) -> 71734
C27: TOTAL REVENUES | F27: =F12+F26 -> 28254 | G27: =G12+G26 -> 27359 | H27: =H12+H26 -> 27419 | I27: =I12+I26 -> 28634 | J27: =J12+J26 -> 28269 | K27: =K12+K26 -> 28289 | L27: =L12+L26 -> 29534 | M27: =M12+M26 -> 29209 | ... R27: =R12+R26 -> 343879
B29: Operation Expenses:
A30: 6030-8502 | C30: Salaries- Secretarial Staff | F30: 8682 | G30: 6946 | H30: 6946 | I30: 6946 | J30: 6946 | K30: 6946 | L30: 8682 | M30: 6946 | N30: 6946 | O30: 6946 | P30: 6946 | Q30: 6946 | R30: =SUM(F30:Q30) -> 86824
A31: 6950-8502 | C31: Postage (Pitney Bowes machine and Fex Ex) | F31: 0 | G31: 135 | H31: 200 | I31: 0 | J31: 135 | K31: 200 | L31: 0 | M31: 135 | N31: 200 | O31: 0 | P31: 135 | Q31: 2000 | R31: =SUM(F31:Q31) -> 3140 | T31: Postage meter with quarterly refills
A32: 6960-8502 | C32: Office Supplies | F32: 20 | G32: 20 | H32: 20 | I32: 20 | J32: 20 | K32: 20 | L32: 20 | M32: 20 | N32: 20 | O32: 20 | P32: 20 | Q32: 20 | R32: =SUM(F32:Q32) -> 240 | T32: non-reimbursible
A33: 6970-8502 | C33: Telephone (TDS) | F33: 880 | G33: 880 | H33: 880 | I33: 880 | J33: 880 | K33: 880 | L33: 880 | M33: 880 | N33: 880 | O33: 880 | P33: 880 | Q33: 880 | R33: =SUM(F33:Q33) -> 10560 | T33: Actual cost from TDS
A34: 6670-8502 | C34: Fax | F34: 0 | G34: 0 | H34: 0 | I34: 0 | J34: 0 | K34: 0 | L34: 0 | M34: 0 | N34: 0 | O34: 0 | P34: 0 | Q34: 0 | R34: =SUM(F34:Q34) -> 0
A35: 6650-8502 | C35: Copier-B&W | F35: 75 | G35: 75 | H35: 75 | I35: 75 | J35: 75 | K35: 75 | L35: 75 | M35: 75 | N35: 75 | O35: 75 | P35: 75 | Q35: 75 | R35: =SUM(F35:Q35) -> 900 | T35: $.04 per page
A36: 6660-8502 | C36: Copier-Color | F36: 50 | G36: 50 | H36: 50 | I36: 50 | J36: 50 | K36: 50 | L36: 50 | M36: 50 | N36: 50 | O36: 50 | P36: 50 | Q36: 50 | R36: =SUM(F36:Q36) -> 600 | T36: $.22 per page
A37: 6680-8502 | C37: Internet (Verizon/Comcast) | F37: 350 | G37: 350 | H37: 350 | I37: 350 | J37: 350 | K37: 350 | L37: 350 | M37: 350 | N37: 350 | O37: 350 | P37: 350 | Q37: 350 | R37: =SUM(F37:Q37) -> 4200
A38: 6220-8502 | C38: Start-up | D38: (Keys, Signage, Painting) | F38: 0 | G38: 0 | H38: 0 | I38: 0 | J38: 0 | K38: 0 | L38: 300 | M38: 0 | N38: 0 | O38: 0 | P38: 0 | Q38: 0 | R38: =SUM(F38:Q38) -> 300
C39: TOTAL SECRETARIAL SERVICES | F39: =SUM(F30:F38) -> 10057 | G39: =SUM(G30:G38) -> 8456 | H39: =SUM(H30:H38) -> 8521 | I39: =SUM(I30:I38) -> 8321 | J39: =SUM(J30:J38) -> 8456 | K39: =SUM(K30:K38) -> 8521 | L39: =SUM(L30:L38) -> 10357 | M39: =SUM(M30:M38) -> 8456 | ... R39: =SUM(R30:R38) -> 106764
B41: Non-Reimbursable Expenses:
C42: Bad Debt | R42: =SUM(F42:Q42) -> 0
A43: 6010-8501 | C43: Salaries- Supervisor | F43: 660 | G43: 660 | H43: 660 | I43: 660 | J43: 660 | K43: 660 | L43: 660 | M43: 660 | N43: 660 | O43: 660 | P43: 660 | Q43: 660 | R43: =SUM(F43:Q43) -> 7920
A44: 6220-8501 | C44: Building Maintenance | F44: 150 | G44: 150 | H44: 150 | I44: 150 | J44: 150 | K44: 150 | L44: 150 | M44: 150 | N44: 150 | O44: 150 | P44: 150 | Q44: 150 | R44: =SUM(F44:Q44) -> 1800
A45: 6510-8501 | C45: Insurance | E45: 191-0000 | F45: 30 | G45: 30 | H45: 30 | I45: 30 | J45: 30 | K45: 30 | L45: 30 | M45: 30 | N45: 30 | O45: 30 | P45: 30 | Q45: 30 | R45: =SUM(F45:Q45) -> 360
A46: 8110-8501 | C46: Office Rent & electric $17.50 psf (10,048 sf)) | F46: 17300 | G46: 17300 | H46: 17300 | I46: 17300 | J46: 17300 | K46: 17300 | L46: 17300 | M46: 17300 | N46: 17300 | O46: 17300 | P46: 17300 | Q46: 17300 | R46: =SUM(F46:Q46) -> 207600
A47: 7110-8501 | C47: Marketing | F47: 10 | G47: 10 | H47: 10 | I47: 10 | J47: 10 | K47: 10 | L47: 10 | M47: 10 | N47: 10 | O47: 10 | P47: 10 | Q47: 10 | R47: =SUM(F47:Q47) -> 120
...

Sheet Monthly Rent Roll & CIP
B2: NAME | C2: OFC.# | D2: Expiration | E2: ='The Office Works'!F6 -> Jan | F2: ='The Office Works'!G6 -> Feb | G2: ='The Office Works'!H6 -> Mar | H2: ='The Office Works'!I6 -> Apr | I2: ='The Office Works'!J6 -> May | J2: ='The Office Works'!K6 -> Jun | K2: ='The Office Works'!L6 -> Jul | L2: ='The Office Works'!M6 -> Aug | ... P2: ='The Office Works'!Q6 -> Dec
B4: Courtesy | C4: 1
B5: Vacant | C5: 2
B6: Vacant | C6: 3
B7: Elizabeth Briola | C7: 4 | D7: M-M | E7: 675 | F7: 675 | G7: 675 | H7: 675 | I7: 675 | J7: 675 | K7: 675 | L7: 675 | M7: 675 | N7: 675 | O7: 675 | P7: 675
B8: PA Ware/Projection | C8: 5 | D8: 46053 | E8: 895 | F8: 0 | G8: 0 | H8: 0 | I8: 0 | J8: 0 | K8: 900 | L8: 900 | M8: 900 | N8: 900 | O8: 900 | P8: 900
B9: Leverage | C9: 6 | D9: 46081 | E9: 670 | F9: 670 | G9: 685 | H9: 685 | I9: 685 | J9: 685 | K9: 685 | L9: 685 | M9: 685 | N9: 685 | O9: 685 | P9: 685
B10: Moore Insurance | C10: 7 | D10: M-M | E10: 900 | F10: 900 | G10: 900 | H10: 900 | I10: 900 | J10: 900 | K10: 900 | L10: 900 | M10: 900 | N10: 900 | O10: 900 | P10: 900
B11: Martin & Martin | C11: 8 | D11: M-M | E11: 775 | F11: 775 | G11: 775 | H11: 775 | I11: 775 | J11: 775 | K11: 775 | L11: 775 | M11: 775 | N11: 775 | O11: 775 | P11: 775
B12: Zhilo Law | C12: 9 | D12: M-M | E12: 900 | F12: 900 | G12: 900 | H12: 900 | I12: 900 | J12: 900 | K12: 900 | L12: 900 | M12: 900 | N12: 900 | O12: 900 | P12: 900
B13: Donald Williford | C13: 10 | D13: 46265 | E13: 900 | F13: 900 | G13: 900 | H13: 900 | I13: 900 | J13: 900 | K13: 900 | L13: 900 | M13: 900 | N13: 900 | O13: 900 | P13: 900
B14: Simplend Mortgage | C14: 11 | D14: M-M | E14: 1500 | F14: 1500 | G14: 1500 | H14: 1500 | I14: 1500 | J14: 1500 | K14: 1500 | L14: 1500 | M14: 1500 | N14: 1500 | O14: 1500 | P14: 1500
B15: John Sisk & Son | C15: 12 | D15: M-M | E15: 1200 | F15: 1200 | G15: 1200 | H15: 1200 | I15: 1200 | J15: 1200 | K15: 1200 | L15: 1200 | M15: 1200 | N15: 1200 | O15: 1200 | P15: 1200
B16: DP Associates | C16: 13 | D16: 46356 | E16: 845 | F16: 845 | G16: 845 | H16: 845 | I16: 845 | J16: 845 | K16: 845 | L16: 845 | M16: 845 | N16: 845 | O16: 845 | P16: 845
B17: Robert Scotese | C17: 14 | D17: 46203 | E17: 920 | F17: 920 | G17: 920 | H17: 920 | I17: 920 | J17: 920 | K17: 940 | L17: 940 | M17: 940 | N17: 940 | O17: 940 | P17: 940
B18: Gary Goodman | C18: 15 | D18: 46173 | E18: 720 | F18: 720 | G18: 720 | H18: 720 | I18: 720 | J18: 740 | K18: 740 | L18: 740 | M18: 740 | N18: 740 | O18: 740 | P18: 740
B19: Timothy Geisheimer | C19: 16 | D19: 46326 | E19: 810 | F19: 810 | G19: 810 | H19: 810 | I19: 810 | J19: 810 | K19: 810 | L19: 810 | M19: 810 | N19: 810 | O19: 810 | P19: 810
B20: Evercleaning | C20: 17 | D20: M-M | E20: 725 | F20: 725 | G20: 725 | H20: 725 | I20: 725 | J20: 725 | K20: 725 | L20: 725 | M20: 725 | N20: 725 | O20: 725 | P20: 725
B21: Creative Financial | C21: 18 | D21: 46295 | E21: 925 | F21: 925 | G21: 925 | H21: 925 | I21: 925 | J21: 925 | K21: 925 | L21: 925 | M21: 925 | N21: 945 | O21: 945 | P21: 945
B22: Vacant | C22: 19
B23: Jacobs Engineering | C23: 20 | D23: 46295 | E23: 1325 | F23: 1325 | G23: 1325 | H23: 1325 | I23: 1325 | J23: 1325 | K23: 1325 | L23: 1325 | M23: 1325 | N23: 1325 | O23: 1325 | P23: 1325
B24: Benoff | C24: 21 | D24: 46081 | E24: 1220 | F24: 1220 | G24: 1240 | H24: 1240 | I24: 1240 | J24: 1240 | K24: 1240 | L24: 1240 | M24: 1240 | N24: 1240 | O24: 1240 | P24: 1240
B25: Benoff | C25: 22 | D25: 46081 | E25: 640 | F25: 640 | G25: 655 | H25: 655 | I25: 655 | J25: 655 | K25: 655 | L25: 655 | M25: 655 | N25: 655 | O25: 655 | P25: 655
B26: Vlad Tinovsky | C26: 23 | D26: 46387 | E26: 590 | F26: 590 | G26: 590 | H26: 590 | I26: 590 | J26: 590 | K26: 590 | L26: 590 | M26: 590 | N26: 590 | O26: 590 | P26: 590
B27: Well Advised Wealth | C27: 24 | D27: 46081 | E27: 575 | F27: 575 | G27: 585 | H27: 585 | I27: 585 | J27: 585 | K27: 585 | L27: 585 | M27: 585 | N27: 585 | O27: 585 | P27: 585
B28: Pro Software | C28: 25 | D28: 46387 | E28: 600 | F28: 600 | G28: 600 | H28: 600 | I28: 600 | J28: 600 | K28: 600 | L28: 600 | M28: 600 | N28: 600 | O28: 600 | P28: 600
B29: R&N Exteriors | C29: 26 | D29: M-M | E29: 600 | F29: 600 | G29: 600 | H29: 600 | I29: 600 | J29: 600 | K29: 600 | L29: 600 | M29: 600 | N29: 600 | O29: 600 | P29: 600
B30: Citiwdie Adjusters | C30: 27 | D30: M-M | E30: 575 | F30: 575 | G30: 575 | H30: 575 | I30: 575 | J30: 575 | K30: 575 | L30: 575 | M30: 575 | N30: 575 | O30: 575 | P30: 575
B31: R&N Exteriors | C31: 28 | D31: M-M | E31: 600 | F31: 600 | G31: 600 | H31: 600 | I31: 600 | J31: 600 | K31: 600 | L31: 600 | M31: 600 | N31: 600 | O31: 600 | P31: 600
B32: Vlad Tinovsky | C32: 29 | D32: 46387 | E32: 770 | F32: 770 | G32: 770 | H32: 770 | I32: 770 | J32: 770 | K32: 770 | L32: 770 | M32: 770 | N32: 770 | O32: 770 | P32: 770
B33: New Point RE | C33: 30 | D33: 46387 | E33: 825 | F33: 825 | G33: 825 | H33: 825 | I33: 825 | J33: 825 | K33: 825 | L33: 825 | M33: 825 | N33: 825 | O33: 825 | P33: 825
B34: New Point RE | C34: 31 | D34: 46387 | E34: 650 | F34: 650 | G34: 650 | H34: 650 | I34: 650 | J34: 650 | K34: 650 | L34: 650 | M34: 650 | N34: 650 | O34: 650 | P34: 650
B35: Vacant/Lyneer | C35: 32 | E35: 0 | F35: 0 | G35: 0 | H35: 850 | I35: 850 | J35: 850 | K35: 850 | L35: 850 | M35: 850 | N35: 850 | O35: 850 | P35: 850
B36: SUB-TOTAL | E36: =SUM(E4:E35) -> 22330 | F36: =SUM(F4:F35) -> 21435 | G36: =SUM(G4:G35) -> 21495 | H36: =SUM(H4:H35) -> 22345 | I36: =SUM(I4:I35) -> 22345 | J36: =SUM(J4:J35) -> 22365 | K36: =SUM(K4:K35) -> 23285 | L36: =SUM(L4:L35) -> 23285 | ... P36: =SUM(P4:P35) -> 23305 | Q36: =SUM(E36:P36) -> 272085
B39: Atlantic Heating & Air | C39: CIP | E39: 60 | F39: 60 | G39: 60 | H39: 60 | I39: 60 | J39: 60 | K39: 60 | L39: 60 | M39: 60 | N39: 60 | O39: 60 | P39: 60
B40: Sadek Law | C40: CIP | E40: 200 | F40: 200 | G40: 200 | H40: 200 | I40: 200 | J40: 200 | K40: 200 | L40: 200 | M40: 200 | N40: 200 | O40: 200 | P40: 200
B41: Hygene Connect | C41: CIP | E41: 75 | F41: 75 | G41: 75 | H41: 75 | I41: 75 | J41: 75 | K41: 75 | L41: 75 | M41: 75 | N41: 75 | O41: 75 | P41: 75
B42: Robert Savoy | C42: CIP | E42: 200 | F42: 200 | G42: 200 | H42: 200 | I42: 200 | J42: 200 | K42: 200 | L42: 200 | M42: 200 | N42: 200 | O42: 200 | P42: 200
B43: Ellen Fanning | C43: CIP | E43: 175 | F43: 175 | G43: 175 | H43: 175 | I43: 175 | J43: 175 | K43: 175 | L43: 175 | M43: 175 | N43: 175 | O43: 175 | P43: 175
B44: Human Capital | C44: CIP | E44: 150 | F44: 150 | G44: 150 | H44: 150 | I44: 150 | J44: 150 | K44: 150 | L44: 150 | M44: 150 | N44: 150 | O44: 150 | P44: 150
...
