Workbook
Name PaiementsParAn: 'INS RET DEBT'!$G$6
Name pmtType: 'INS RET DEBT'!$F$20
Name rate: 'INS RET DEBT'!$J$6
Name roundOpt: 'INS RET DEBT'!$F$24
Name TauxIntérêt: 'INS RET DEBT'!$G$3

Sheet Cover Sheet
A1: ='All Shopping Centers'!J1 -> Operating Budget
A2: ='All Shopping Centers'!J2 -> Shopping Centers
A3: ='All Shopping Centers'!Q1 -> 46023

Sheet All Shopping Centers
B1: All Shopping Centers | J1: Operating Budget | Q1: =DATE(2026,1,1) -> 46023
J2: Shopping Centers
B4: ='Renew & Vac '!A6+'Renew & Vac '!A28+'Renew & Vac '!A50+'Renew & Vac '!A72+'Renew & Vac '!A94+'Renew & Vac '!A116+'Renew & Vac '!A138+'7300'!B4+'8200'!B4+'9510'!B4 -> 296787 | E4: Jan | F4: Feb | G4: Mar | H4: Apr | I4: May | J4: Jun | K4: Jul | L4: Aug | M4: Sep | N4: Oct | O4: Nov | P4: Dec | Q4: Total
D6: Occupancy % | E6: =SUM('1100'!E7,'1500'!E7,'2300'!E7,'4500'!E7,'5600'!E7,'7010'!E7,'7200'!E7)/$B$4 -> 0.74016202 | F6: =SUM('1100'!F7,'1500'!F7,'2300'!F7,'4500'!F7,'5600'!F7,'7010'!F7,'7200'!F7)/$B$4 -> 0.74016202 | G6: =SUM('1100'!G7,'1500'!G7,'2300'!G7,'4500'!G7,'5600'!G7,'7010'!G7,'7200'!G7)/$B$4 -> 0.74016202 | H6: =SUM('1100'!H7,'1500'!H7,'2300'!H7,'4500'!H7,'5600'!H7,'7010'!H7,'7200'!H7)/$B$4 -> 0.74016202 | I6: =SUM('1100'!I7,'1500'!I7,'2300'!I7,'4500'!I7,'5600'!I7,'7010'!I7,'7200'!I7)/$B$4 -> 0.74825355 | J6: =SUM('1100'!J7,'1500'!J7,'2300'!J7,'4500'!J7,'5600'!J7,'7010'!J7,'7200'!J7)/$B$4 -> 0.75162378 | K6: =SUM('1100'!K7,'1500'!K7,'2300'!K7,'4500'!K7,'5600'!K7,'7010'!K7,'7200'!K7)/$B$4 -> 0.75162378 | L6: =SUM('1100'!L7,'1500'!L7,'2300'!L7,'4500'!L7,'5600'!L7,'7010'!L7,'7200'!L7)/$B$4 -> 0.75162378 | ... P6: =SUM('1100'!P7,'1500'!P7,'2300'!P7,'4500'!P7,'5600'!P7,'7010'!P7,'7200'!P7)/$B$4 -> 0.75162378
B8: Revenues
A10: 4230-8501 | C10: Rental Income - In Place | E10: =+'1100'!E10+'1500'!E10+'2300'!E10+'4500'!E10+'5600'!E10+'7010'!E10+'7200'!E10+'7300'!E10+'8200'!E10+'9510'!E10 -> 423443.68 | F10: =+'1100'!F10+'1500'!F10+'2300'!F10+'4500'!F10+'5600'!F10+'7010'!F10+'7200'!F10+'7300'!F10+'8200'!F10+'9510'!F10 -> 423473.68 | G10: =+'1100'!G10+'1500'!G10+'2300'!G10+'4500'!G10+'5600'!G10+'7010'!G10+'7200'!G10+'7300'!G10+'8200'!G10+'9510'!G10 -> 423923.68 | H10: =+'1100'!H10+'1500'!H10+'2300'!H10+'4500'!H10+'5600'!H10+'7010'!H10+'7200'!H10+'7300'!H10+'8200'!H10+'9510'!H10 -> 420610.35 | I10: =+'1100'!I10+'1500'!I10+'2300'!I10+'4500'!I10+'5600'!I10+'7010'!I10+'7200'!I10+'7300'!I10+'8200'!I10+'9510'!I10 -> 420717.18 | J10: =+'1100'!J10+'1500'!J10+'2300'!J10+'4500'!J10+'5600'!J10+'7010'!J10+'7200'!J10+'7300'!J10+'8200'!J10+'9510'!J10 -> 420911.26 | K10: =+'1100'!K10+'1500'!K10+'2300'!K10+'4500'!K10+'5600'!K10+'7010'!K10+'7200'!K10+'7300'!K10+'8200'!K10+'9510'!K10 -> 413746.55 | L10: =+'1100'!L10+'1500'!L10+'2300'!L10+'4500'!L10+'5600'!L10+'7010'!L10+'7200'!L10+'7300'!L10+'8200'!L10+'9510'!L10 -> 398617.55 | ... P10: =+'1100'!P10+'1500'!P10+'2300'!P10+'4500'!P10+'5600'!P10+'7010'!P10+'7200'!P10+'7300'!P10+'8200'!P10+'9510'!P10 -> 390617.53 | Q10: =SUM(E10:P10) -> 4894551.7
A11: 4230-8501 | C11: Rental Income - New & Renewal | E11: =+'1100'!E11+'1500'!E11+'2300'!E11+'4500'!E11+'5600'!E11+'7010'!E11+'7200'!E11+'7300'!E11+'8200'!E11+'9510'!E11 -> 11422.167 | F11: =+'1100'!F11+'1500'!F11+'2300'!F11+'4500'!F11+'5600'!F11+'7010'!F11+'7200'!F11+'7300'!F11+'8200'!F11+'9510'!F11 -> 11422.167 | G11: =+'1100'!G11+'1500'!G11+'2300'!G11+'4500'!G11+'5600'!G11+'7010'!G11+'7200'!G11+'7300'!G11+'8200'!G11+'9510'!G11 -> 8272.1667 | H11: =+'1100'!H11+'1500'!H11+'2300'!H11+'4500'!H11+'5600'!H11+'7010'!H11+'7200'!H11+'7300'!H11+'8200'!H11+'9510'!H11 -> 11401.61 | I11: =+'1100'!I11+'1500'!I11+'2300'!I11+'4500'!I11+'5600'!I11+'7010'!I11+'7200'!I11+'7300'!I11+'8200'!I11+'9510'!I11 -> 19801.61 | J11: =+'1100'!J11+'1500'!J11+'2300'!J11+'4500'!J11+'5600'!J11+'7010'!J11+'7200'!J11+'7300'!J11+'8200'!J11+'9510'!J11 -> 22851.61 | K11: =+'1100'!K11+'1500'!K11+'2300'!K11+'4500'!K11+'5600'!K11+'7010'!K11+'7200'!K11+'7300'!K11+'8200'!K11+'9510'!K11 -> 31300.426 | L11: =+'1100'!L11+'1500'!L11+'2300'!L11+'4500'!L11+'5600'!L11+'7010'!L11+'7200'!L11+'7300'!L11+'8200'!L11+'9510'!L11 -> 50652.876 | ... P11: =+'1100'!P11+'1500'!P11+'2300'!P11+'4500'!P11+'5600'!P11+'7010'!P11+'7200'!P11+'7300'!P11+'8200'!P11+'9510'!P11 -> 68777.312 | Q11: =SUM(E11:P11) -> 436977.21
A12: 4240-8501 | C12: Percentage Rents | E12: =+'1100'!E12+'1500'!E12+'2300'!E12+'4500'!E12+'5600'!E12+'7010'!E12+'7200'!E12+'7300'!E12+'8200'!E12+'9510'!E12 -> 0 | F12: =+'1100'!F12+'1500'!F12+'2300'!F12+'4500'!F12+'5600'!F12+'7010'!F12+'7200'!F12+'7300'!F12+'8200'!F12+'9510'!F12 -> 0 | G12: =+'1100'!G12+'1500'!G12+'2300'!G12+'4500'!G12+'5600'!G12+'7010'!G12+'7200'!G12+'7300'!G12+'8200'!G12+'9510'!G12 -> 0 | H12: =+'1100'!H12+'1500'!H12+'2300'!H12+'4500'!H12+'5600'!H12+'7010'!H12+'7200'!H12+'7300'!H12+'8200'!H12+'9510'!H12 -> 0 | I12: =+'1100'!I12+'1500'!I12+'2300'!I12+'4500'!I12+'5600'!I12+'7010'!I12+'7200'!I12+'7300'!I12+'8200'!I12+'9510'!I12 -> 0 | J12: =+'1100'!J12+'1500'!J12+'2300'!J12+'4500'!J12+'5600'!J12+'7010'!J12+'7200'!J12+'7300'!J12+'8200'!J12+'9510'!J12 -> 0 | K12: =+'1100'!K12+'1500'!K12+'2300'!K12+'4500'!K12+'5600'!K12+'7010'!K12+'7200'!K12+'7300'!K12+'8200'!K12+'9510'!K12 -> 0 | L12: =+'1100'!L12+'1500'!L12+'2300'!L12+'4500'!L12+'5600'!L12+'7010'!L12+'7200'!L12+'7300'!L12+'8200'!L12+'9510'!L12 -> 0 | ... P12: =+'1100'!P12+'1500'!P12+'2300'!P12+'4500'!P12+'5600'!P12+'7010'!P12+'7200'!P12+'7300'!P12+'8200'!P12+'9510'!P12 -> 33958.07 | Q12: =SUM(E12:P12) -> 33958.07
A13: 4990-8501 | C13: Miscellaneous | E13: =+'1100'!E13+'1500'!E13+'2300'!E13+'4500'!E13+'5600'!E13+'7010'!E13+'7200'!E13+'7300'!E13+'8200'!E13+'9510'!E13 -> 10530.967 | F13: =+'1100'!F13+'1500'!F13+'2300'!F13+'4500'!F13+'5600'!F13+'7010'!F13+'7200'!F13+'7300'!F13+'8200'!F13+'9510'!F13 -> 10530.967 | G13: =+'1100'!G13+'1500'!G13+'2300'!G13+'4500'!G13+'5600'!G13+'7010'!G13+'7200'!G13+'7300'!G13+'8200'!G13+'9510'!G13 -> 10530.967 | H13: =+'1100'!H13+'1500'!H13+'2300'!H13+'4500'!H13+'5600'!H13+'7010'!H13+'7200'!H13+'7300'!H13+'8200'!H13+'9510'!H13 -> 10530.967 | I13: =+'1100'!I13+'1500'!I13+'2300'!I13+'4500'!I13+'5600'!I13+'7010'!I13+'7200'!I13+'7300'!I13+'8200'!I13+'9510'!I13 -> 10530.967 | J13: =+'1100'!J13+'1500'!J13+'2300'!J13+'4500'!J13+'5600'!J13+'7010'!J13+'7200'!J13+'7300'!J13+'8200'!J13+'9510'!J13 -> 10530.967 | K13: =+'1100'!K13+'1500'!K13+'2300'!K13+'4500'!K13+'5600'!K13+'7010'!K13+'7200'!K13+'7300'!K13+'8200'!K13+'9510'!K13 -> 10530.967 | L13: =+'1100'!L13+'1500'!L13+'2300'!L13+'4500'!L13+'5600'!L13+'7010'!L13+'7200'!L13+'7300'!L13+'8200'!L13+'9510'!L13 -> 10530.967 | ... P13: =+'1100'!P13+'1500'!P13+'2300'!P13+'4500'!P13+'5600'!P13+'7010'!P13+'7200'!P13+'7300'!P13+'8200'!P13+'9510'!P13 -> 10530.967 | Q13: =SUM(E13:P13) -> 126371.61
A14: 9190-8501 | C14: Interest Income | E14: =+'1100'!E14+'1500'!E14+'2300'!E14+'4500'!E14+'5600'!E14+'7010'!E14+'7200'!E14+'7300'!E14+'8200'!E14+'9510'!E14 -> 243.08 | F14: =+'1100'!F14+'1500'!F14+'2300'!F14+'4500'!F14+'5600'!F14+'7010'!F14+'7200'!F14+'7300'!F14+'8200'!F14+'9510'!F14 -> 243.08 | G14: =+'1100'!G14+'1500'!G14+'2300'!G14+'4500'!G14+'5600'!G14+'7010'!G14+'7200'!G14+'7300'!G14+'8200'!G14+'9510'!G14 -> 243.08 | H14: =+'1100'!H14+'1500'!H14+'2300'!H14+'4500'!H14+'5600'!H14+'7010'!H14+'7200'!H14+'7300'!H14+'8200'!H14+'9510'!H14 -> 243.08 | I14: =+'1100'!I14+'1500'!I14+'2300'!I14+'4500'!I14+'5600'!I14+'7010'!I14+'7200'!I14+'7300'!I14+'8200'!I14+'9510'!I14 -> 243.08 | J14: =+'1100'!J14+'1500'!J14+'2300'!J14+'4500'!J14+'5600'!J14+'7010'!J14+'7200'!J14+'7300'!J14+'8200'!J14+'9510'!J14 -> 243.08 | K14: =+'1100'!K14+'1500'!K14+'2300'!K14+'4500'!K14+'5600'!K14+'7010'!K14+'7200'!K14+'7300'!K14+'8200'!K14+'9510'!K14 -> 243.08 | L14: =+'1100'!L14+'1500'!L14+'2300'!L14+'4500'!L14+'5600'!L14+'7010'!L14+'7200'!L14+'7300'!L14+'8200'!L14+'9510'!L14 -> 243.08 | ... P14: =+'1100'!P14+'1500'!P14+'2300'!P14+'4500'!P14+'5600'!P14+'7010'!P14+'7200'!P14+'7300'!P14+'8200'!P14+'9510'!P14 -> 243.08 | Q14: =SUM(E14:P14) -> 2916.96
D15: Total Rental and Other: | E15: =SUM(E10:E14) -> 445639.89 | F15: =SUM(F10:F14) -> 445669.89 | G15: =SUM(G10:G14) -> 442969.89 | H15: =SUM(H10:H14) -> 442786.01 | I15: =SUM(I10:I14) -> 451292.84 | J15: =SUM(J10:J14) -> 454536.92 | K15: =SUM(K10:K14) -> 455821.02 | L15: =SUM(L10:L14) -> 460044.47 | ... Q15: =SUM(Q10:Q14) -> 5494775.5
B17: Reimbursements
A18: 4710-8502 | C18: Electric | E18: =+'1100'!E18+'1500'!E18+'2300'!E18+'4500'!E18+'5600'!E18+'7010'!E18+'7200'!E18+'7300'!E18+'8200'!E18+'9510'!E18 -> 1978.2 | F18: =+'1100'!F18+'1500'!F18+'2300'!F18+'4500'!F18+'5600'!F18+'7010'!F18+'7200'!F18+'7300'!F18+'8200'!F18+'9510'!F18 -> 1802.85 | G18: =+'1100'!G18+'1500'!G18+'2300'!G18+'4500'!G18+'5600'!G18+'7010'!G18+'7200'!G18+'7300'!G18+'8200'!G18+'9510'!G18 -> 1659 | H18: =+'1100'!H18+'1500'!H18+'2300'!H18+'4500'!H18+'5600'!H18+'7010'!H18+'7200'!H18+'7300'!H18+'8200'!H18+'9510'!H18 -> 1174.95 | I18: =+'1100'!I18+'1500'!I18+'2300'!I18+'4500'!I18+'5600'!I18+'7010'!I18+'7200'!I18+'7300'!I18+'8200'!I18+'9510'!I18 -> 1174.95 | J18: =+'1100'!J18+'1500'!J18+'2300'!J18+'4500'!J18+'5600'!J18+'7010'!J18+'7200'!J18+'7300'!J18+'8200'!J18+'9510'!J18 -> 1191.75 | K18: =+'1100'!K18+'1500'!K18+'2300'!K18+'4500'!K18+'5600'!K18+'7010'!K18+'7200'!K18+'7300'!K18+'8200'!K18+'9510'!K18 -> 1503.6 | L18: =+'1100'!L18+'1500'!L18+'2300'!L18+'4500'!L18+'5600'!L18+'7010'!L18+'7200'!L18+'7300'!L18+'8200'!L18+'9510'!L18 -> 1451.1 | ... P18: =+'1100'!P18+'1500'!P18+'2300'!P18+'4500'!P18+'5600'!P18+'7010'!P18+'7200'!P18+'7300'!P18+'8200'!P18+'9510'!P18 -> 1978.2 | Q18: =SUM(E18:P18) -> 18551.4
A19: 4910-8502 | C19: Common Area Maintenance | E19: =+'1100'!E19+'1500'!E19+'2300'!E19+'4500'!E19+'5600'!E19+'7010'!E19+'7200'!E19+'7300'!E19+'8200'!E19+'9510'!E19 -> 90900 | F19: =+'1100'!F19+'1500'!F19+'2300'!F19+'4500'!F19+'5600'!F19+'7010'!F19+'7200'!F19+'7300'!F19+'8200'!F19+'9510'!F19 -> 90900 | G19: =+'1100'!G19+'1500'!G19+'2300'!G19+'4500'!G19+'5600'!G19+'7010'!G19+'7200'!G19+'7300'!G19+'8200'!G19+'9510'!G19 -> 90900 | H19: =+'1100'!H19+'1500'!H19+'2300'!H19+'4500'!H19+'5600'!H19+'7010'!H19+'7200'!H19+'7300'!H19+'8200'!H19+'9510'!H19 -> 96539.25 | I19: =+'1100'!I19+'1500'!I19+'2300'!I19+'4500'!I19+'5600'!I19+'7010'!I19+'7200'!I19+'7300'!I19+'8200'!I19+'9510'!I19 -> 90900 | J19: =+'1100'!J19+'1500'!J19+'2300'!J19+'4500'!J19+'5600'!J19+'7010'!J19+'7200'!J19+'7300'!J19+'8200'!J19+'9510'!J19 -> 90900 | K19: =+'1100'!K19+'1500'!K19+'2300'!K19+'4500'!K19+'5600'!K19+'7010'!K19+'7200'!K19+'7300'!K19+'8200'!K19+'9510'!K19 -> 96539.25 | L19: =+'1100'!L19+'1500'!L19+'2300'!L19+'4500'!L19+'5600'!L19+'7010'!L19+'7200'!L19+'7300'!L19+'8200'!L19+'9510'!L19 -> 90900 | ... P19: =+'1100'!P19+'1500'!P19+'2300'!P19+'4500'!P19+'5600'!P19+'7010'!P19+'7200'!P19+'7300'!P19+'8200'!P19+'9510'!P19 -> 96539.25 | Q19: =SUM(E19:P19) -> 1113357
A20: 4920-8502 | C20: Real Estate Taxes | E20: =+'1100'!E20+'1500'!E20+'2300'!E20+'4500'!E20+'5600'!E20+'7010'!E20+'7200'!E20+'7300'!E20+'8200'!E20+'9510'!E20 -> 36100 | F20: =+'1100'!F20+'1500'!F20+'2300'!F20+'4500'!F20+'5600'!F20+'7010'!F20+'7200'!F20+'7300'!F20+'8200'!F20+'9510'!F20 -> 36100 | G20: =+'1100'!G20+'1500'!G20+'2300'!G20+'4500'!G20+'5600'!G20+'7010'!G20+'7200'!G20+'7300'!G20+'8200'!G20+'9510'!G20 -> 36100 | H20: =+'1100'!H20+'1500'!H20+'2300'!H20+'4500'!H20+'5600'!H20+'7010'!H20+'7200'!H20+'7300'!H20+'8200'!H20+'9510'!H20 -> 37669 | I20: =+'1100'!I20+'1500'!I20+'2300'!I20+'4500'!I20+'5600'!I20+'7010'!I20+'7200'!I20+'7300'!I20+'8200'!I20+'9510'!I20 -> 36100 | J20: =+'1100'!J20+'1500'!J20+'2300'!J20+'4500'!J20+'5600'!J20+'7010'!J20+'7200'!J20+'7300'!J20+'8200'!J20+'9510'!J20 -> 36100 | K20: =+'1100'!K20+'1500'!K20+'2300'!K20+'4500'!K20+'5600'!K20+'7010'!K20+'7200'!K20+'7300'!K20+'8200'!K20+'9510'!K20 -> 37669 | L20: =+'1100'!L20+'1500'!L20+'2300'!L20+'4500'!L20+'5600'!L20+'7010'!L20+'7200'!L20+'7300'!L20+'8200'!L20+'9510'!L20 -> 36100 | ... P20: =+'1100'!P20+'1500'!P20+'2300'!P20+'4500'!P20+'5600'!P20+'7010'!P20+'7200'!P20+'7300'!P20+'8200'!P20+'9510'!P20 -> 37669 | Q20: =SUM(E20:P20) -> 439476
A21: 4930-8502 | C21: Insurance | E21: =+'1100'!E21+'1500'!E21+'2300'!E21+'4500'!E21+'5600'!E21+'7010'!E21+'7200'!E21+'7300'!E21+'8200'!E21+'9510'!E21 -> 10365 | F21: =+'1100'!F21+'1500'!F21+'2300'!F21+'4500'!F21+'5600'!F21+'7010'!F21+'7200'!F21+'7300'!F21+'8200'!F21+'9510'!F21 -> 0 | G21: =+'1100'!G21+'1500'!G21+'2300'!G21+'4500'!G21+'5600'!G21+'7010'!G21+'7200'!G21+'7300'!G21+'8200'!G21+'9510'!G21 -> 0 | H21: =+'1100'!H21+'1500'!H21+'2300'!H21+'4500'!H21+'5600'!H21+'7010'!H21+'7200'!H21+'7300'!H21+'8200'!H21+'9510'!H21 -> 0 | I21: =+'1100'!I21+'1500'!I21+'2300'!I21+'4500'!I21+'5600'!I21+'7010'!I21+'7200'!I21+'7300'!I21+'8200'!I21+'9510'!I21 -> 0 | J21: =+'1100'!J21+'1500'!J21+'2300'!J21+'4500'!J21+'5600'!J21+'7010'!J21+'7200'!J21+'7300'!J21+'8200'!J21+'9510'!J21 -> 0 | K21: =+'1100'!K21+'1500'!K21+'2300'!K21+'4500'!K21+'5600'!K21+'7010'!K21+'7200'!K21+'7300'!K21+'8200'!K21+'9510'!K21 -> 0 | L21: =+'1100'!L21+'1500'!L21+'2300'!L21+'4500'!L21+'5600'!L21+'7010'!L21+'7200'!L21+'7300'!L21+'8200'!L21+'9510'!L21 -> 0 | ... P21: =+'1100'!P21+'1500'!P21+'2300'!P21+'4500'!P21+'5600'!P21+'7010'!P21+'7200'!P21+'7300'!P21+'8200'!P21+'9510'!P21 -> 0 | Q21: =SUM(E21:P21) -> 10365
D22: Total Reimbursements: | E22: =SUM(E18:E21) -> 139343.2 | F22: =SUM(F18:F21) -> 128802.85 | G22: =SUM(G18:G21) -> 128659 | H22: =SUM(H18:H21) -> 135383.2 | I22: =SUM(I18:I21) -> 128174.95 | J22: =SUM(J18:J21) -> 128191.75 | K22: =SUM(K18:K21) -> 135711.85 | L22: =SUM(L18:L21) -> 128451.1 | ... Q22: =SUM(Q18:Q21) -> 1581749.4
B24: TOTAL REVENUES | E24: =+E15+E22 -> 584983.09 | F24: =+F15+F22 -> 574472.74 | G24: =+G15+G22 -> 571628.89 | H24: =+H15+H22 -> 578169.21 | I24: =+I15+I22 -> 579467.79 | J24: =+J15+J22 -> 582728.67 | K24: =+K15+K22 -> 591532.87 | L24: =+L15+L22 -> 588495.57 | ... Q24: =+Q15+Q22 -> 7076524.9
Q25: =+'1100'!Q24+'1500'!Q24+'2300'!Q24+'4500'!Q24+'5600'!Q24+'7010'!Q24+'7200'!Q24 -> 5700115.3
B26: Reimbursable Expenses
A27: 6030-8502 | C27: Maintenance Salaries | E27: =+'1100'!E27+'1500'!E27+'2300'!E27+'4500'!E27+'5600'!E27+'7010'!E27+'7200'!E27+'7300'!E27+'8200'!E27+'9510'!E27 -> 9139 | F27: =+'1100'!F27+'1500'!F27+'2300'!F27+'4500'!F27+'5600'!F27+'7010'!F27+'7200'!F27+'7300'!F27+'8200'!F27+'9510'!F27 -> 9139 | G27: =+'1100'!G27+'1500'!G27+'2300'!G27+'4500'!G27+'5600'!G27+'7010'!G27+'7200'!G27+'7300'!G27+'8200'!G27+'9510'!G27 -> 9139 | H27: =+'1100'!H27+'1500'!H27+'2300'!H27+'4500'!H27+'5600'!H27+'7010'!H27+'7200'!H27+'7300'!H27+'8200'!H27+'9510'!H27 -> 9139 | I27: =+'1100'!I27+'1500'!I27+'2300'!I27+'4500'!I27+'5600'!I27+'7010'!I27+'7200'!I27+'7300'!I27+'8200'!I27+'9510'!I27 -> 9139 | J27: =+'1100'!J27+'1500'!J27+'2300'!J27+'4500'!J27+'5600'!J27+'7010'!J27+'7200'!J27+'7300'!J27+'8200'!J27+'9510'!J27 -> 9139 | K27: =+'1100'!K27+'1500'!K27+'2300'!K27+'4500'!K27+'5600'!K27+'7010'!K27+'7200'!K27+'7300'!K27+'8200'!K27+'9510'!K27 -> 9139 | L27: =+'1100'!L27+'1500'!L27+'2300'!L27+'4500'!L27+'5600'!L27+'7010'!L27+'7200'!L27+'7300'!L27+'8200'!L27+'9510'!L27 -> 9139 | ... P27: =+'1100'!P27+'1500'!P27+'2300'!P27+'4500'!P27+'5600'!P27+'7010'!P27+'7200'!P27+'7300'!P27+'8200'!P27+'9510'!P27 -> 9139 | Q27: =SUM(E27:P27) -> 109668
A29: 6120-8502 | C29: Electric | E29: =+'1100'!E29+'1500'!E29+'2300'!E29+'4500'!E29+'5600'!E29+'7010'!E29+'7200'!E29+'7300'!E29+'8200'!E29+'9510'!E29+'7010'!E30+'7010'!E31 -> 5858.77 | F29: =+'1100'!F29+'1500'!F29+'2300'!F29+'4500'!F29+'5600'!F29+'7010'!F29+'7200'!F29+'7300'!F29+'8200'!F29+'9510'!F29+'7010'!F30+'7010'!F31 -> 5449.32 | G29: =+'1100'!G29+'1500'!G29+'2300'!G29+'4500'!G29+'5600'!G29+'7010'!G29+'7200'!G29+'7300'!G29+'8200'!G29+'9510'!G29+'7010'!G30+'7010'!G31 -> 5228.6 | H29: =+'1100'!H29+'1500'!H29+'2300'!H29+'4500'!H29+'5600'!H29+'7010'!H29+'7200'!H29+'7300'!H29+'8200'!H29+'9510'!H29+'7010'!H30+'7010'!H31 -> 4155.54 | I29: =+'1100'!I29+'1500'!I29+'2300'!I29+'4500'!I29+'5600'!I29+'7010'!I29+'7200'!I29+'7300'!I29+'8200'!I29+'9510'!I29+'7010'!I30+'7010'!I31 -> 3999.05 | J29: =+'1100'!J29+'1500'!J29+'2300'!J29+'4500'!J29+'5600'!J29+'7010'!J29+'7200'!J29+'7300'!J29+'8200'!J29+'9510'!J29+'7010'!J30+'7010'!J31 -> 3954.79 | K29: =+'1100'!K29+'1500'!K29+'2300'!K29+'4500'!K29+'5600'!K29+'7010'!K29+'7200'!K29+'7300'!K29+'8200'!K29+'9510'!K29+'7010'!K30+'7010'!K31 -> 4422.77 | L29: =+'1100'!L29+'1500'!L29+'2300'!L29+'4500'!L29+'5600'!L29+'7010'!L29+'7200'!L29+'7300'!L29+'8200'!L29+'9510'!L29+'7010'!L30+'7010'!L31 -> 4069.85 | ... P29: =+'1100'!P29+'1500'!P29+'2300'!P29+'4500'!P29+'5600'!P29+'7010'!P29+'7200'!P29+'7300'!P29+'8200'!P29+'9510'!P29+'7010'!P30+'7010'!P31 -> 6116.61 | Q29: =SUM(E29:P29) -> 57194.8
A31: 6130-8502 | C31: Water & Sewer | E31: =+'1100'!E31+'1500'!E31+'2300'!E31+'4500'!E31+'5600'!E31+'7010'!E33+'7200'!E31+'7300'!E31+'8200'!E31+'9510'!E31 -> 490.28 | F31: =+'1100'!F31+'1500'!F31+'2300'!F31+'4500'!F31+'5600'!F31+'7010'!F33+'7200'!F31+'7300'!F31+'8200'!F31+'9510'!F31 -> 717.91 | G31: =+'1100'!G31+'1500'!G31+'2300'!G31+'4500'!G31+'5600'!G31+'7010'!G33+'7200'!G31+'7300'!G31+'8200'!G31+'9510'!G31 -> 692.16 | H31: =+'1100'!H31+'1500'!H31+'2300'!H31+'4500'!H31+'5600'!H31+'7010'!H33+'7200'!H31+'7300'!H31+'8200'!H31+'9510'!H31 -> 621.09 | I31: =+'1100'!I31+'1500'!I31+'2300'!I31+'4500'!I31+'5600'!I31+'7010'!I33+'7200'!I31+'7300'!I31+'8200'!I31+'9510'!I31 -> 443.93 | J31: =+'1100'!J31+'1500'!J31+'2300'!J31+'4500'!J31+'5600'!J31+'7010'!J33+'7200'!J31+'7300'!J31+'8200'!J31+'9510'!J31 -> 459.38 | K31: =+'1100'!K31+'1500'!K31+'2300'!K31+'4500'!K31+'5600'!K31+'7010'!K33+'7200'!K31+'7300'!K31+'8200'!K31+'9510'!K31 -> 478.95 | L31: =+'1100'!L31+'1500'!L31+'2300'!L31+'4500'!L31+'5600'!L31+'7010'!L33+'7200'!L31+'7300'!L31+'8200'!L31+'9510'!L31 -> 468.65 | ... P31: =+'1100'!P31+'1500'!P31+'2300'!P31+'4500'!P31+'5600'!P31+'7010'!P33+'7200'!P31+'7300'!P31+'8200'!P31+'9510'!P31 -> 490.28 | Q31: =SUM(E31:P31) -> 6355.1
D33: Building Maint.-Contractual | E33: =+'1100'!E33+'1500'!E33+'2300'!E33+'4500'!E33+'5600'!E33+'7010'!E35+'7200'!E33+'7300'!E33+'8200'!E33+'9510'!E33 -> 3916 | F33: =+'1100'!F33+'1500'!F33+'2300'!F33+'4500'!F33+'5600'!F33+'7010'!F35+'7200'!F33+'7300'!F33+'8200'!F33+'9510'!F33 -> 850 | G33: =+'1100'!G33+'1500'!G33+'2300'!G33+'4500'!G33+'5600'!G33+'7010'!G35+'7200'!G33+'7300'!G33+'8200'!G33+'9510'!G33 -> 0 | H33: =+'1100'!H33+'1500'!H33+'2300'!H33+'4500'!H33+'5600'!H33+'7010'!H35+'7200'!H33+'7300'!H33+'8200'!H33+'9510'!H33 -> 4716 | I33: =+'1100'!I33+'1500'!I33+'2300'!I33+'4500'!I33+'5600'!I33+'7010'!I35+'7200'!I33+'7300'!I33+'8200'!I33+'9510'!I33 -> 4379.25 | J33: =+'1100'!J33+'1500'!J33+'2300'!J33+'4500'!J33+'5600'!J33+'7010'!J35+'7200'!J33+'7300'!J33+'8200'!J33+'9510'!J33 -> 0 | K33: =+'1100'!K33+'1500'!K33+'2300'!K33+'4500'!K33+'5600'!K33+'7010'!K35+'7200'!K33+'7300'!K33+'8200'!K33+'9510'!K33 -> 3916 | L33: =+'1100'!L33+'1500'!L33+'2300'!L33+'4500'!L33+'5600'!L33+'7010'!L35+'7200'!L33+'7300'!L33+'8200'!L33+'9510'!L33 -> 400 | ... P33: =+'1100'!P33+'1500'!P33+'2300'!P33+'4500'!P33+'5600'!P33+'7010'!P35+'7200'!P33+'7300'!P33+'8200'!P33+'9510'!P33 -> 0 | Q33: =SUM(E33:P33) -> 40557.5
D34: Building Maint.-Recurring | E34: =+'1100'!E34+'1500'!E34+'2300'!E34+'4500'!E34+'5600'!E34+'7010'!E36+'7200'!E34+'7300'!E34+'8200'!E34+'9510'!E34 -> 2835.15 | F34: =+'1100'!F34+'1500'!F34+'2300'!F34+'4500'!F34+'5600'!F34+'7010'!F36+'7200'!F34+'7300'!F34+'8200'!F34+'9510'!F34 -> 2835.15 | G34: =+'1100'!G34+'1500'!G34+'2300'!G34+'4500'!G34+'5600'!G34+'7010'!G36+'7200'!G34+'7300'!G34+'8200'!G34+'9510'!G34 -> 2835.15 | H34: =+'1100'!H34+'1500'!H34+'2300'!H34+'4500'!H34+'5600'!H34+'7010'!H36+'7200'!H34+'7300'!H34+'8200'!H34+'9510'!H34 -> 3135.15 | I34: =+'1100'!I34+'1500'!I34+'2300'!I34+'4500'!I34+'5600'!I34+'7010'!I36+'7200'!I34+'7300'!I34+'8200'!I34+'9510'!I34 -> 3460.15 | J34: =+'1100'!J34+'1500'!J34+'2300'!J34+'4500'!J34+'5600'!J34+'7010'!J36+'7200'!J34+'7300'!J34+'8200'!J34+'9510'!J34 -> 2835.15 | K34: =+'1100'!K34+'1500'!K34+'2300'!K34+'4500'!K34+'5600'!K34+'7010'!K36+'7200'!K34+'7300'!K34+'8200'!K34+'9510'!K34 -> 2835.15 | L34: =+'1100'!L34+'1500'!L34+'2300'!L34+'4500'!L34+'5600'!L34+'7010'!L36+'7200'!L34+'7300'!L34+'8200'!L34+'9510'!L34 -> 2835.15 | ... P34: =+'1100'!P34+'1500'!P34+'2300'!P34+'4500'!P34+'5600'!P34+'7010'!P36+'7200'!P34+'7300'!P34+'8200'!P34+'9510'!P34 -> 2835.15 | Q34: =SUM(E34:P34) -> 37998.8
D35: Building Maint.-7010 Office Center | E35: ='7010'!E37 -> 824 | F35: ='7010'!F37 -> 901.25 | G35: ='7010'!G37 -> 51.5 | H35: ='7010'!H37 -> 824 | I35: ='7010'!I37 -> 1364.75 | J35: ='7010'!J37 -> 51.5 | K35: ='7010'!K37 -> 824 | L35: ='7010'!L37 -> 901.25 | ... P35: ='7010'!P37 -> 51.5 | Q35: =SUM(E35:P35) -> 7570.5
D36: Building Maint.-Big Projects | E36: =+'1100'!E35+'1500'!E35+'2300'!E35+'4500'!E35+'5600'!E35+'7010'!E38+'7200'!E35+'7300'!E35+'8200'!E35+'9510'!E35 -> 0 | F36: =+'1100'!F35+'1500'!F35+'2300'!F35+'4500'!F35+'5600'!F35+'7010'!F38+'7200'!F35+'7300'!F35+'8200'!F35+'9510'!F35 -> 500 | G36: =+'1100'!G35+'1500'!G35+'2300'!G35+'4500'!G35+'5600'!G35+'7010'!G38+'7200'!G35+'7300'!G35+'8200'!G35+'9510'!G35 -> 23100 | H36: =+'1100'!H35+'1500'!H35+'2300'!H35+'4500'!H35+'5600'!H35+'7010'!H38+'7200'!H35+'7300'!H35+'8200'!H35+'9510'!H35 -> 24860 | I36: =+'1100'!I35+'1500'!I35+'2300'!I35+'4500'!I35+'5600'!I35+'7010'!I38+'7200'!I35+'7300'!I35+'8200'!I35+'9510'!I35 -> 500 | J36: =+'1100'!J35+'1500'!J35+'2300'!J35+'4500'!J35+'5600'!J35+'7010'!J38+'7200'!J35+'7300'!J35+'8200'!J35+'9510'!J35 -> 0 | K36: =+'1100'!K35+'1500'!K35+'2300'!K35+'4500'!K35+'5600'!K35+'7010'!K38+'7200'!K35+'7300'!K35+'8200'!K35+'9510'!K35 -> 0 | L36: =+'1100'!L35+'1500'!L35+'2300'!L35+'4500'!L35+'5600'!L35+'7010'!L38+'7200'!L35+'7300'!L35+'8200'!L35+'9510'!L35 -> 13000 | ... P36: =+'1100'!P35+'1500'!P35+'2300'!P35+'4500'!P35+'5600'!P35+'7010'!P38+'7200'!P35+'7300'!P35+'8200'!P35+'9510'!P35 -> 0 | Q36: =SUM(E36:P36) -> 97920
A37: 6220-8502 | C37: Building Maintenance | E37: =SUM(E33:E36) -> 7575.15 | F37: =SUM(F33:F36) -> 5086.4 | G37: =SUM(G33:G36) -> 25986.65 | H37: =SUM(H33:H36) -> 33535.15 | I37: =SUM(I33:I36) -> 9704.15 | J37: =SUM(J33:J36) -> 2886.65 | K37: =SUM(K33:K36) -> 7575.15 | L37: =SUM(L33:L36) -> 17136.4 | ... Q37: =SUM(Q33:Q36) -> 184046.8
A39: 6330-8502 | B39: (SC) | C39: Parking Lot Cleaning | E39: =+'1100'!E38+'1500'!E38+'2300'!E38+'4500'!E38+'5600'!E38+'7010'!E41+'7200'!E38+'7300'!E38+'8200'!E38+'9510'!E38 -> 11454.9 | F39: =+'1100'!F38+'1500'!F38+'2300'!F38+'4500'!F38+'5600'!F38+'7010'!F41+'7200'!F38+'7300'!F38+'8200'!F38+'9510'!F38 -> 12042 | G39: =+'1100'!G38+'1500'!G38+'2300'!G38+'4500'!G38+'5600'!G38+'7010'!G41+'7200'!G38+'7300'!G38+'8200'!G38+'9510'!G38 -> 11969.9 | H39: =+'1100'!H38+'1500'!H38+'2300'!H38+'4500'!H38+'5600'!H38+'7010'!H41+'7200'!H38+'7300'!H38+'8200'!H38+'9510'!H38 -> 11454.9 | I39: =+'1100'!I38+'1500'!I38+'2300'!I38+'4500'!I38+'5600'!I38+'7010'!I41+'7200'!I38+'7300'!I38+'8200'!I38+'9510'!I38 -> 12042 | J39: =+'1100'!J38+'1500'!J38+'2300'!J38+'4500'!J38+'5600'!J38+'7010'!J41+'7200'!J38+'7300'!J38+'8200'!J38+'9510'!J38 -> 11454.9 | K39: =+'1100'!K38+'1500'!K38+'2300'!K38+'4500'!K38+'5600'!K38+'7010'!K41+'7200'!K38+'7300'!K38+'8200'!K38+'9510'!K38 -> 11660.9 | L39: =+'1100'!L38+'1500'!L38+'2300'!L38+'4500'!L38+'5600'!L38+'7010'!L41+'7200'!L38+'7300'!L38+'8200'!L38+'9510'!L38 -> 12042 | ... P39: =+'1100'!P38+'1500'!P38+'2300'!P38+'4500'!P38+'5600'!P38+'7010'!P41+'7200'!P38+'7300'!P38+'8200'!P38+'9510'!P38 -> 11351.9 | Q39: =SUM(E39:P39) -> 140940.2
D41: Parking Lot Maint.-Contractual | E41: =+'1100'!E40+'1500'!E40+'2300'!E40+'4500'!E40+'5600'!E40+'7010'!E43+'7200'!E40+'7300'!E40+'8200'!E40+'9510'!E40 -> 0 | F41: =+'1100'!F40+'1500'!F40+'2300'!F40+'4500'!F40+'5600'!F40+'7010'!F43+'7200'!F40+'7300'!F40+'8200'!F40+'9510'!F40 -> 0 | G41: =+'1100'!G40+'1500'!G40+'2300'!G40+'4500'!G40+'5600'!G40+'7010'!G43+'7200'!G40+'7300'!G40+'8200'!G40+'9510'!G40 -> 0 | H41: =+'1100'!H40+'1500'!H40+'2300'!H40+'4500'!H40+'5600'!H40+'7010'!H43+'7200'!H40+'7300'!H40+'8200'!H40+'9510'!H40 -> 0 | I41: =+'1100'!I40+'1500'!I40+'2300'!I40+'4500'!I40+'5600'!I40+'7010'!I43+'7200'!I40+'7300'!I40+'8200'!I40+'9510'!I40 -> 0 | J41: =+'1100'!J40+'1500'!J40+'2300'!J40+'4500'!J40+'5600'!J40+'7010'!J43+'7200'!J40+'7300'!J40+'8200'!J40+'9510'!J40 -> 0 | K41: =+'1100'!K40+'1500'!K40+'2300'!K40+'4500'!K40+'5600'!K40+'7010'!K43+'7200'!K40+'7300'!K40+'8200'!K40+'9510'!K40 -> 0 | L41: =+'1100'!L40+'1500'!L40+'2300'!L40+'4500'!L40+'5600'!L40+'7010'!L43+'7200'!L40+'7300'!L40+'8200'!L40+'9510'!L40 -> 0 | ... P41: =+'1100'!P40+'1500'!P40+'2300'!P40+'4500'!P40+'5600'!P40+'7010'!P43+'7200'!P40+'7300'!P40+'8200'!P40+'9510'!P40 -> 0 | Q41: =SUM(E41:P41) -> 0
D42: Parking Lot Maint.-Recurring | E42: =+'1100'!E41+'1500'!E41+'2300'!E41+'4500'!E41+'5600'!E41+'7010'!E44+'7200'!E41+'7300'!E41+'8200'!E41+'9510'!E41 -> 2523.5 | F42: =+'1100'!F41+'1500'!F41+'2300'!F41+'4500'!F41+'5600'!F41+'7010'!F44+'7200'!F41+'7300'!F41+'8200'!F41+'9510'!F41 -> 2163 | G42: =+'1100'!G41+'1500'!G41+'2300'!G41+'4500'!G41+'5600'!G41+'7010'!G44+'7200'!G41+'7300'!G41+'8200'!G41+'9510'!G41 -> 7172.5 | H42: =+'1100'!H41+'1500'!H41+'2300'!H41+'4500'!H41+'5600'!H41+'7010'!H44+'7200'!H41+'7300'!H41+'8200'!H41+'9510'!H41 -> 5768 | I42: =+'1100'!I41+'1500'!I41+'2300'!I41+'4500'!I41+'5600'!I41+'7010'!I44+'7200'!I41+'7300'!I41+'8200'!I41+'9510'!I41 -> 2163 | J42: =+'1100'!J41+'1500'!J41+'2300'!J41+'4500'!J41+'5600'!J41+'7010'!J44+'7200'!J41+'7300'!J41+'8200'!J41+'9510'!J41 -> 7172.5 | K42: =+'1100'!K41+'1500'!K41+'2300'!K41+'4500'!K41+'5600'!K41+'7010'!K44+'7200'!K41+'7300'!K41+'8200'!K41+'9510'!K41 -> 2102.23 | L42: =+'1100'!L41+'1500'!L41+'2300'!L41+'4500'!L41+'5600'!L41+'7010'!L44+'7200'!L41+'7300'!L41+'8200'!L41+'9510'!L41 -> 2163 | ... P42: =+'1100'!P41+'1500'!P41+'2300'!P41+'4500'!P41+'5600'!P41+'7010'!P44+'7200'!P41+'7300'!P41+'8200'!P41+'9510'!P41 -> 7496.95 | Q42: =SUM(E42:P42) -> 54755.18
D43: Parking Lot Maint.-Big Projects | E43: =+'1100'!E42+'1500'!E42+'2300'!E42+'4500'!E42+'5600'!E42+'7010'!E45+'7200'!E42+'7300'!E42+'8200'!E42+'9510'!E42 -> 0 | F43: =+'1100'!F42+'1500'!F42+'2300'!F42+'4500'!F42+'5600'!F42+'7010'!F45+'7200'!F42+'7300'!F42+'8200'!F42+'9510'!F42 -> 0 | G43: =+'1100'!G42+'1500'!G42+'2300'!G42+'4500'!G42+'5600'!G42+'7010'!G45+'7200'!G42+'7300'!G42+'8200'!G42+'9510'!G42 -> 25750 | H43: =+'1100'!H42+'1500'!H42+'2300'!H42+'4500'!H42+'5600'!H42+'7010'!H45+'7200'!H42+'7300'!H42+'8200'!H42+'9510'!H42 -> 15150 | I43: =+'1100'!I42+'1500'!I42+'2300'!I42+'4500'!I42+'5600'!I42+'7010'!I45+'7200'!I42+'7300'!I42+'8200'!I42+'9510'!I42 -> 0 | J43: =+'1100'!J42+'1500'!J42+'2300'!J42+'4500'!J42+'5600'!J42+'7010'!J45+'7200'!J42+'7300'!J42+'8200'!J42+'9510'!J42 -> 15450 | K43: =+'1100'!K42+'1500'!K42+'2300'!K42+'4500'!K42+'5600'!K42+'7010'!K45+'7200'!K42+'7300'!K42+'8200'!K42+'9510'!K42 -> 0 | L43: =+'1100'!L42+'1500'!L42+'2300'!L42+'4500'!L42+'5600'!L42+'7010'!L45+'7200'!L42+'7300'!L42+'8200'!L42+'9510'!L42 -> 0 | ... P43: =+'1100'!P42+'1500'!P42+'2300'!P42+'4500'!P42+'5600'!P42+'7010'!P45+'7200'!P42+'7300'!P42+'8200'!P42+'9510'!P42 -> 0 | Q43: =SUM(E43:P43) -> 102400
A44: 6360-8502 | C44: Parking Lot Maintenance | E44: =SUM(E41:E43) -> 2523.5 | F44: =SUM(F41:F43) -> 2163 | G44: =SUM(G41:G43) -> 32922.5 | H44: =SUM(H41:H43) -> 20918 | I44: =SUM(I41:I43) -> 2163 | J44: =SUM(J41:J43) -> 22622.5 | K44: =SUM(K41:K43) -> 2102.23 | L44: =SUM(L41:L43) -> 2163 | ... Q44: =SUM(Q41:Q43) -> 157155.18
A46: 6370-8502 | C46: Snow Removal | E46: =+'1100'!E45+'1500'!E45+'2300'!E45+'4500'!E45+'5600'!E45+'7010'!E48+'7200'!E45+'7300'!E45+'8200'!E45+'9510'!E45 -> 47380 | F46: =+'1100'!F45+'1500'!F45+'2300'!F45+'4500'!F45+'5600'!F45+'7010'!F48+'7200'!F45+'7300'!F45+'8200'!F45+'9510'!F45 -> 47380 | G46: =+'1100'!G45+'1500'!G45+'2300'!G45+'4500'!G45+'5600'!G45+'7010'!G48+'7200'!G45+'7300'!G45+'8200'!G45+'9510'!G45 -> 14420 | H46: =+'1100'!H45+'1500'!H45+'2300'!H45+'4500'!H45+'5600'!H45+'7010'!H48+'7200'!H45+'7300'!H45+'8200'!H45+'9510'!H45 -> 0 | I46: =+'1100'!I45+'1500'!I45+'2300'!I45+'4500'!I45+'5600'!I45+'7010'!I48+'7200'!I45+'7300'!I45+'8200'!I45+'9510'!I45 -> 0 | J46: =+'1100'!J45+'1500'!J45+'2300'!J45+'4500'!J45+'5600'!J45+'7010'!J48+'7200'!J45+'7300'!J45+'8200'!J45+'9510'!J45 -> 0 | K46: =+'1100'!K45+'1500'!K45+'2300'!K45+'4500'!K45+'5600'!K45+'7010'!K48+'7200'!K45+'7300'!K45+'8200'!K45+'9510'!K45 -> 0 | L46: =+'1100'!L45+'1500'!L45+'2300'!L45+'4500'!L45+'5600'!L45+'7010'!L48+'7200'!L45+'7300'!L45+'8200'!L45+'9510'!L45 -> 0 | ... P46: =+'1100'!P45+'1500'!P45+'2300'!P45+'4500'!P45+'5600'!P45+'7010'!P48+'7200'!P45+'7300'!P45+'8200'!P45+'9510'!P45 -> 29355 | Q46: =SUM(E46:P46) -> 151410
D48: Landscaping-Contractual | E48: =+'1100'!E47+'1500'!E47+'2300'!E47+'4500'!E47+'5600'!E47+'7010'!E50+'7200'!E47+'7300'!E47+'8200'!E47+'9510'!E47 -> 0 | F48: =+'1100'!F47+'1500'!F47+'2300'!F47+'4500'!F47+'5600'!F47+'7010'!F50+'7200'!F47+'7300'!F47+'8200'!F47+'9510'!F47 -> 0 | G48: =+'1100'!G47+'1500'!G47+'2300'!G47+'4500'!G47+'5600'!G47+'7010'!G50+'7200'!G47+'7300'!G47+'8200'!G47+'9510'!G47 -> 1998.2 | H48: =+'1100'!H47+'1500'!H47+'2300'!H47+'4500'!H47+'5600'!H47+'7010'!H50+'7200'!H47+'7300'!H47+'8200'!H47+'9510'!H47 -> 5773.2 | I48: =+'1100'!I47+'1500'!I47+'2300'!I47+'4500'!I47+'5600'!I47+'7010'!I50+'7200'!I47+'7300'!I47+'8200'!I47+'9510'!I47 -> 5773.2 | J48: =+'1100'!J47+'1500'!J47+'2300'!J47+'4500'!J47+'5600'!J47+'7010'!J50+'7200'!J47+'7300'!J47+'8200'!J47+'9510'!J47 -> 5773.2 | K48: =+'1100'!K47+'1500'!K47+'2300'!K47+'4500'!K47+'5600'!K47+'7010'!K50+'7200'!K47+'7300'!K47+'8200'!K47+'9510'!K47 -> 5773.2 | L48: =+'1100'!L47+'1500'!L47+'2300'!L47+'4500'!L47+'5600'!L47+'7010'!L50+'7200'!L47+'7300'!L47+'8200'!L47+'9510'!L47 -> 5773.2 | ... P48: =+'1100'!P47+'1500'!P47+'2300'!P47+'4500'!P47+'5600'!P47+'7010'!P50+'7200'!P47+'7300'!P47+'8200'!P47+'9510'!P47 -> 0 | Q48: =SUM(E48:P48) -> 42410.6
D49: Landscaping-Recurring | E49: =+'1100'!E48+'1500'!E48+'2300'!E48+'4500'!E48+'5600'!E48+'7010'!E51+'7200'!E48+'7300'!E48+'8200'!E48+'9510'!E48 -> 0 | F49: =+'1100'!F48+'1500'!F48+'2300'!F48+'4500'!F48+'5600'!F48+'7010'!F51+'7200'!F48+'7300'!F48+'8200'!F48+'9510'!F48 -> 0 | G49: =+'1100'!G48+'1500'!G48+'2300'!G48+'4500'!G48+'5600'!G48+'7010'!G51+'7200'!G48+'7300'!G48+'8200'!G48+'9510'!G48 -> 206 | H49: =+'1100'!H48+'1500'!H48+'2300'!H48+'4500'!H48+'5600'!H48+'7010'!H51+'7200'!H48+'7300'!H48+'8200'!H48+'9510'!H48 -> 1030 | I49: =+'1100'!I48+'1500'!I48+'2300'!I48+'4500'!I48+'5600'!I48+'7010'!I51+'7200'!I48+'7300'!I48+'8200'!I48+'9510'!I48 -> 1030 | J49: =+'1100'!J48+'1500'!J48+'2300'!J48+'4500'!J48+'5600'!J48+'7010'!J51+'7200'!J48+'7300'!J48+'8200'!J48+'9510'!J48 -> 1030 | K49: =+'1100'!K48+'1500'!K48+'2300'!K48+'4500'!K48+'5600'!K48+'7010'!K51+'7200'!K48+'7300'!K48+'8200'!K48+'9510'!K48 -> 1030 | L49: =+'1100'!L48+'1500'!L48+'2300'!L48+'4500'!L48+'5600'!L48+'7010'!L51+'7200'!L48+'7300'!L48+'8200'!L48+'9510'!L48 -> 1030 | ... P49: =+'1100'!P48+'1500'!P48+'2300'!P48+'4500'!P48+'5600'!P48+'7010'!P51+'7200'!P48+'7300'!P48+'8200'!P48+'9510'!P48 -> 0 | Q49: =SUM(E49:P49) -> 7416
D50: Landscaping-Big Projects | E50: =+'1100'!E49+'1500'!E49+'2300'!E49+'4500'!E49+'5600'!E49+'7010'!E52+'7200'!E49+'7300'!E49+'8200'!E49+'9510'!E49 -> 0 | F50: =+'1100'!F49+'1500'!F49+'2300'!F49+'4500'!F49+'5600'!F49+'7010'!F52+'7200'!F49+'7300'!F49+'8200'!F49+'9510'!F49 -> 0 | G50: =+'1100'!G49+'1500'!G49+'2300'!G49+'4500'!G49+'5600'!G49+'7010'!G52+'7200'!G49+'7300'!G49+'8200'!G49+'9510'!G49 -> 0 | H50: =+'1100'!H49+'1500'!H49+'2300'!H49+'4500'!H49+'5600'!H49+'7010'!H52+'7200'!H49+'7300'!H49+'8200'!H49+'9510'!H49 -> 0 | I50: =+'1100'!I49+'1500'!I49+'2300'!I49+'4500'!I49+'5600'!I49+'7010'!I52+'7200'!I49+'7300'!I49+'8200'!I49+'9510'!I49 -> 31100 | J50: =+'1100'!J49+'1500'!J49+'2300'!J49+'4500'!J49+'5600'!J49+'7010'!J52+'7200'!J49+'7300'!J49+'8200'!J49+'9510'!J49 -> 0 | K50: =+'1100'!K49+'1500'!K49+'2300'!K49+'4500'!K49+'5600'!K49+'7010'!K52+'7200'!K49+'7300'!K49+'8200'!K49+'9510'!K49 -> 0 | L50: =+'1100'!L49+'1500'!L49+'2300'!L49+'4500'!L49+'5600'!L49+'7010'!L52+'7200'!L49+'7300'!L49+'8200'!L49+'9510'!L49 -> 10500 | ... P50: =+'1100'!P49+'1500'!P49+'2300'!P49+'4500'!P49+'5600'!P49+'7010'!P52+'7200'!P49+'7300'!P49+'8200'!P49+'9510'!P49 -> 0 | Q50: =SUM(E50:P50) -> 45720
A51: 6380-8502 | C51: Landscaping | E51: =SUM(E48:E50) -> 0 | F51: =SUM(F48:F50) -> 0 | G51: =SUM(G48:G50) -> 2204.2 | H51: =SUM(H48:H50) -> 6803.2 | I51: =SUM(I48:I50) -> 37903.2 | J51: =SUM(J48:J50) -> 6803.2 | K51: =SUM(K48:K50) -> 6803.2 | L51: =SUM(L48:L50) -> 17303.2 | ... Q51: =SUM(Q48:Q50) -> 95546.6
A53: 6350-8502 | C53: Security | E53: =+'1100'!E52+'1500'!E52+'2300'!E52+'4500'!E52+'5600'!E52+'7010'!E55+'7200'!E52+'7300'!E52+'8200'!E52+'9510'!E52 -> 25684.7 | F53: =+'1100'!F52+'1500'!F52+'2300'!F52+'4500'!F52+'5600'!F52+'7010'!F55+'7200'!F52+'7300'!F52+'8200'!F52+'9510'!F52 -> 25684.7 | G53: =+'1100'!G52+'1500'!G52+'2300'!G52+'4500'!G52+'5600'!G52+'7010'!G55+'7200'!G52+'7300'!G52+'8200'!G52+'9510'!G52 -> 26714.7 | H53: =+'1100'!H52+'1500'!H52+'2300'!H52+'4500'!H52+'5600'!H52+'7010'!H55+'7200'!H52+'7300'!H52+'8200'!H52+'9510'!H52 -> 25684.7 | I53: =+'1100'!I52+'1500'!I52+'2300'!I52+'4500'!I52+'5600'!I52+'7010'!I55+'7200'!I52+'7300'!I52+'8200'!I52+'9510'!I52 -> 28259.7 | J53: =+'1100'!J52+'1500'!J52+'2300'!J52+'4500'!J52+'5600'!J52+'7010'!J55+'7200'!J52+'7300'!J52+'8200'!J52+'9510'!J52 -> 25684.7 | K53: =+'1100'!K52+'1500'!K52+'2300'!K52+'4500'!K52+'5600'!K52+'7010'!K55+'7200'!K52+'7300'!K52+'8200'!K52+'9510'!K52 -> 25684.7 | L53: =+'1100'!L52+'1500'!L52+'2300'!L52+'4500'!L52+'5600'!L52+'7010'!L55+'7200'!L52+'7300'!L52+'8200'!L52+'9510'!L52 -> 25684.7 | ... P53: =+'1100'!P52+'1500'!P52+'2300'!P52+'4500'!P52+'5600'!P52+'7010'!P55+'7200'!P52+'7300'!P52+'8200'!P52+'9510'!P52 -> 25684.7 | Q53: =SUM(E53:P53) -> 315426.4
A55: 6610-8502 | B55: (BP) | C55: Management Fee | E55: ='1100'!E54+'1500'!E54+'2300'!E54+'4500'!E54+'5600'!E54+'7010'!E57+'7200'!E54+'7300'!E54+'8200'!E54+'9510'!E54 -> 0 | F55: ='1100'!F54+'1500'!F54+'2300'!F54+'4500'!F54+'5600'!F54+'7010'!F57+'7200'!F54+'7300'!F54+'8200'!F54+'9510'!F54 -> 0 | G55: ='1100'!G54+'1500'!G54+'2300'!G54+'4500'!G54+'5600'!G54+'7010'!G57+'7200'!G54+'7300'!G54+'8200'!G54+'9510'!G54 -> 0 | H55: ='1100'!H54+'1500'!H54+'2300'!H54+'4500'!H54+'5600'!H54+'7010'!H57+'7200'!H54+'7300'!H54+'8200'!H54+'9510'!H54 -> 0 | I55: ='1100'!I54+'1500'!I54+'2300'!I54+'4500'!I54+'5600'!I54+'7010'!I57+'7200'!I54+'7300'!I54+'8200'!I54+'9510'!I54 -> 0 | J55: ='1100'!J54+'1500'!J54+'2300'!J54+'4500'!J54+'5600'!J54+'7010'!J57+'7200'!J54+'7300'!J54+'8200'!J54+'9510'!J54 -> 0 | K55: ='1100'!K54+'1500'!K54+'2300'!K54+'4500'!K54+'5600'!K54+'7010'!K57+'7200'!K54+'7300'!K54+'8200'!K54+'9510'!K54 -> 0 | L55: ='1100'!L54+'1500'!L54+'2300'!L54+'4500'!L54+'5600'!L54+'7010'!L57+'7200'!L54+'7300'!L54+'8200'!L54+'9510'!L54 -> 0 | ... P55: ='1100'!P54+'1500'!P54+'2300'!P54+'4500'!P54+'5600'!P54+'7010'!P57+'7200'!P54+'7300'!P54+'8200'!P54+'9510'!P54 -> 0 | Q55: =SUM(E55:P55) -> 0
...

Sheet 1100
B1: 1100 | C1: - Parkwood Professional Building | J1: =+'All Shopping Centers'!J1 -> Operating Budget | Q1: ='All Shopping Centers'!Q1 -> 46023
J2: ='All Shopping Centers'!J2&" - "&B1 -> Shopping Centers - 1100
B4: 8287 | E4: Jan | F4: Feb | G4: Mar | H4: Apr | I4: May | J4: Jun | K4: Jul | L4: Aug | M4: Sep | N4: Oct | O4: Nov | P4: Dec | Q4: Total | R4: Total PSF | S4: Input | T4: Notes
D6: Occupancy % | E6: ='Renew & Vac '!AJ9 -> 0.5143 | F6: ='Renew & Vac '!AK9 -> 0.5143 | G6: ='Renew & Vac '!AL9 -> 0.5143 | H6: ='Renew & Vac '!AM9 -> 0.5143 | I6: ='Renew & Vac '!AN9 -> 0.5143 | J6: ='Renew & Vac '!AO9 -> 0.635 | K6: ='Renew & Vac '!AP9 -> 0.635 | L6: ='Renew & Vac '!AQ9 -> 0.635 | ... P6: ='Renew & Vac '!AU9 -> 0.635
D7: Occupancy SF | E7: =$B$4*E6 -> 4262.0041 | F7: =$B$4*F6 -> 4262.0041 | G7: =$B$4*G6 -> 4262.0041 | H7: =$B$4*H6 -> 4262.0041 | I7: =$B$4*I6 -> 4262.0041 | J7: =$B$4*J6 -> 5262.245 | K7: =$B$4*K6 -> 5262.245 | L7: =$B$4*L6 -> 5262.245 | ... P7: =$B$4*P6 -> 5262.245
B8: Revenues
A10: 4230-8501 | C10: Rental Income - In Place | E10: =SUMIFS('In Place Revenue'!$G:$G,'In Place Revenue'!$A:$A,$B$1,'In Place Revenue'!$H:$H,1) -> 0 | F10: =SUMIFS('In Place Revenue'!$G:$G,'In Place Revenue'!$A:$A,$B$1,'In Place Revenue'!$H:$H,2) -> 0 | G10: =SUMIFS('In Place Revenue'!$G:$G,'In Place Revenue'!$A:$A,$B$1,'In Place Revenue'!$H:$H,3) -> 0 | H10: =SUMIFS('In Place Revenue'!$G:$G,'In Place Revenue'!$A:$A,$B$1,'In Place Revenue'!$H:$H,4) -> 0 | I10: =SUMIFS('In Place Revenue'!$G:$G,'In Place Revenue'!$A:$A,$B$1,'In Place Revenue'!$H:$H,5) -> 0 | J10: =SUMIFS('In Place Revenue'!$G:$G,'In Place Revenue'!$A:$A,$B$1,'In Place Revenue'!$H:$H,6) -> 0 | K10: =SUMIFS('In Place Revenue'!$G:$G,'In Place Revenue'!$A:$A,$B$1,'In Place Revenue'!$H:$H,7) -> 0 | L10: =SUMIFS('In Place Revenue'!$G:$G,'In Place Revenue'!$A:$A,$B$1,'In Place Revenue'!$H:$H,8) -> 0 | M10: =SUMIFS('In Place Revenue'!$G:$G,'In Place Revenue'!$A:$A,$B$1,'In Place Revenue'!$H:$H,9) -> 0 | N10: =SUMIFS('In Place Revenue'!$G:$G,'In Place Revenue'!$A:$A,$B$1,'In Place Revenue'!$H:$H,10) -> 0 | O10: =SUMIFS('In Place Revenue'!$G:$G,'In Place Revenue'!$A:$A,$B$1,'In Place Revenue'!$H:$H,11) -> 0 | P10: =SUMIFS('In Place Revenue'!$G:$G,'In Place Revenue'!$A:$A,$B$1,'In Place Revenue'!$H:$H,12) -> 0 | Q10: =SUM(E10:P10) -> 0 | R10: =Q10/$B$4 -> 0
A11: 4230-8501 | C11: Rental Income - New & Renewal | E11: ='Renew & Vac '!AJ10 -> 3056.1667 | F11: ='Renew & Vac '!AK10 -> 3056.1667 | G11: ='Renew & Vac '!AL10 -> 3056.1667 | H11: ='Renew & Vac '!AM10 -> 3056.1667 | I11: ='Renew & Vac '!AN10 -> 3056.1667 | J11: ='Renew & Vac '!AO10 -> 4306.1667 | K11: ='Renew & Vac '!AP10 -> 4306.1667 | L11: ='Renew & Vac '!AQ10 -> 4306.1667 | ... P11: ='Renew & Vac '!AU10 -> 4306.1667 | Q11: =SUM(E11:P11) -> 45424 | R11: =Q11/$B$4 -> 5.4813563
A12: 4240-8501 | C12: Percentage Rents | E12: 0 | F12: 0 | G12: 0 | H12: 0 | I12: 0 | J12: 0 | K12: 0 | L12: 0 | M12: 0 | N12: 0 | O12: 0 | P12: 0 | Q12: =SUM(E12:P12) -> 0 | R12: =Q12/$B$4 -> 0
A13: 4990-8501 | C13: Miscellaneous | E13: 0 | F13: 0 | G13: 0 | H13: 0 | I13: 0 | J13: 0 | K13: 0 | L13: 0 | M13: 0 | N13: 0 | O13: 0 | P13: 0 | Q13: =SUM(E13:P13) -> 0 | R13: =Q13/$B$4 -> 0
A14: 9190-8501 | C14: Interest Income | E14: =1.03*3 -> 3.09 | F14: =1.03*3 -> 3.09 | G14: =1.03*3 -> 3.09 | H14: =1.03*3 -> 3.09 | I14: =1.03*3 -> 3.09 | J14: =1.03*3 -> 3.09 | K14: =1.03*3 -> 3.09 | L14: =1.03*3 -> 3.09 | ... P14: =1.03*3 -> 3.09 | Q14: =SUM(E14:P14) -> 37.08 | R14: =Q14/$B$4 -> 0.0044744781 | S14: DW | T14: 2025 Business Plan grown 3%
C15: Total Rental and Other | E15: =SUM(E10:E14) -> 3059.2567 | F15: =SUM(F10:F14) -> 3059.2567 | G15: =SUM(G10:G14) -> 3059.2567 | H15: =SUM(H10:H14) -> 3059.2567 | I15: =SUM(I10:I14) -> 3059.2567 | J15: =SUM(J10:J14) -> 4309.2567 | K15: =SUM(K10:K14) -> 4309.2567 | L15: =SUM(L10:L14) -> 4309.2567 | ... Q15: =SUM(Q10:Q14) -> 45461.08 | R15: =Q15/$B$4 -> 5.4858308
B17: Reimbursements
A18: 4710-8502 | C18: Electric | Q18: =SUM(E18:P18) -> 0 | R18: =Q18/$B$4 -> 0
A19: 4910-8502 | C19: Common Area Maintenance | E19: =+'Tenant Recoveries'!E26 -> 2600 | F19: =+E19 -> 2600 | G19: =+F19 -> 2600 | H19: =+G19 -> 2600 | I19: =+H19 -> 2600 | J19: =+I19 -> 2600 | K19: =+J19 -> 2600 | L19: =+K19 -> 2600 | M19: =+L19 -> 2600 | ... P19: =+O19 -> 2600 | Q19: =SUM(E19:P19) -> 31200 | R19: =Q19/$B$4 -> 3.764933
A20: 4920-8502 | C20: Real Estate Taxes | E20: =+'Tenant Recoveries'!E27 -> 600 | F20: =+E20 -> 600 | G20: =+F20 -> 600 | H20: =+G20 -> 600 | I20: =+H20 -> 600 | J20: =+I20 -> 600 | K20: =+J20 -> 600 | L20: =+K20 -> 600 | M20: =+L20 -> 600 | ... P20: =+O20 -> 600 | Q20: =SUM(E20:P20) -> 7200 | R20: =Q20/$B$4 -> 0.8688307
A21: 4930-8502 | C21: Insurance | Q21: =SUM(E21:P21) -> 0 | R21: =Q21/$B$4 -> 0
C22: Total Reimbursements | E22: =SUM(E18:E21) -> 3200 | F22: =SUM(F18:F21) -> 3200 | G22: =SUM(G18:G21) -> 3200 | H22: =SUM(H18:H21) -> 3200 | I22: =SUM(I18:I21) -> 3200 | J22: =SUM(J18:J21) -> 3200 | K22: =SUM(K18:K21) -> 3200 | L22: =SUM(L18:L21) -> 3200 | ... Q22: =SUM(Q18:Q21) -> 38400 | R22: =Q22/$B$4 -> 4.6337637
R23: =Q23/$B$4 -> 0
B24: TOTAL REVENUES | E24: =+E15+E22 -> 6259.2567 | F24: =+F15+F22 -> 6259.2567 | G24: =+G15+G22 -> 6259.2567 | H24: =+H15+H22 -> 6259.2567 | I24: =+I15+I22 -> 6259.2567 | J24: =+J15+J22 -> 7509.2567 | K24: =+K15+K22 -> 7509.2567 | L24: =+L15+L22 -> 7509.2567 | ... Q24: =+Q15+Q22 -> 83861.08 | R24: =Q24/$B$4 -> 10.119595
B26: Reimbursable Expenses
A27: 6030-8502 | C27: Maintenance Salaries | E27: =VLOOKUP($B$1,'Allocated Expenses'!$B$6:$P$15,4,FALSE) -> 255.18265 | F27: =VLOOKUP($B$1,'Allocated Expenses'!$B$6:$P$15,5,FALSE) -> 255.18265 | G27: =VLOOKUP($B$1,'Allocated Expenses'!$B$6:$P$15,6,FALSE) -> 255.18265 | H27: =VLOOKUP($B$1,'Allocated Expenses'!$B$6:$P$15,7,FALSE) -> 255.18265 | I27: =VLOOKUP($B$1,'Allocated Expenses'!$B$6:$P$15,8,FALSE) -> 255.18265 | J27: =VLOOKUP($B$1,'Allocated Expenses'!$B$6:$P$15,9,FALSE) -> 255.18265 | K27: =VLOOKUP($B$1,'Allocated Expenses'!$B$6:$P$15,10,FALSE) -> 255.18265 | L27: =VLOOKUP($B$1,'Allocated Expenses'!$B$6:$P$15,11,FALSE) -> 255.18265 | M27: =VLOOKUP($B$1,'Allocated Expenses'!$B$6:$P$15,12,FALSE) -> 255.18265 | N27: =VLOOKUP($B$1,'Allocated Expenses'!$B$6:$P$15,13,FALSE) -> 255.18265 | O27: =VLOOKUP($B$1,'Allocated Expenses'!$B$6:$P$15,14,FALSE) -> 255.18265 | P27: =VLOOKUP($B$1,'Allocated Expenses'!$B$6:$P$15,15,FALSE) -> 255.18265 | Q27: =SUM(E27:P27) -> 3062.1918 | R27: =Q27/$B$4 -> 0.36951753
A29: 6120-8502 | C29: Electric | E29: =1.03*641 -> 660.23 | F29: =1.03*622 -> 640.66 | G29: =1.03*712 -> 733.36 | H29: =1.03*651 -> 670.53 | I29: =1.03*616 -> 634.48 | J29: =1.03*527 -> 542.81 | K29: =1.03*192 -> 197.76 | L29: =1.03*171 -> 176.13 | M29: =1.03*176 -> 181.28 | N29: =1.03*170 -> 175.1 | O29: =1.03*581 -> 598.43 | P29: =1.03*774 -> 797.22 | Q29: =SUM(E29:P29) -> 6007.99 | R29: =Q29/$B$4 -> 0.72498974 | S29: DW | T29: 2025 Business Plan grown 3%
A31: 6130-8502 | C31: Water & Sewer | Q31: =SUM(E31:P31) -> 0 | R31: =Q31/$B$4 -> 0
D33: Building Maint.-Contractual | E33: ='Building Maint'!C20 -> 0 | F33: ='Building Maint'!D20 -> 0 | G33: ='Building Maint'!E20 -> 0 | H33: ='Building Maint'!F20 -> 0 | I33: ='Building Maint'!G20 -> 400 | J33: ='Building Maint'!H20 -> 0 | K33: ='Building Maint'!I20 -> 0 | L33: ='Building Maint'!J20 -> 0 | ... P33: ='Building Maint'!N20 -> 0 | Q33: =SUM(E33:P33) -> 1100 | R33: =Q33/$B$4 -> 0.13273802 | S33: DW | T33: 2025 Business Plan grown 3%
D34: Building Maint.-Recurring | E34: ='Building Maint'!C6 -> 200 | F34: ='Building Maint'!D6 -> 200 | G34: ='Building Maint'!E6 -> 200 | H34: ='Building Maint'!F6 -> 500 | I34: ='Building Maint'!G6 -> 200 | J34: ='Building Maint'!H6 -> 200 | K34: ='Building Maint'!I6 -> 200 | L34: ='Building Maint'!J6 -> 200 | ... P34: ='Building Maint'!N6 -> 200 | Q34: =SUM(E34:P34) -> 3150 | R34: =Q34/$B$4 -> 0.38011343 | S34: DW | T34: 2025 Business Plan grown 3%
D35: Building Maint.-Big Projects | F35: 500 | I35: 500 | L35: 500 | O35: 500 | Q35: =SUM(E35:P35) -> 2000 | R35: =Q35/$B$4 -> 0.24134186 | S35: GM | T35: Roof maintenance
A36: 6220-8502 | C36: Building Maintenance | E36: =SUM(E33:E35) -> 200 | F36: =SUM(F33:F35) -> 700 | G36: =SUM(G33:G35) -> 200 | H36: =SUM(H33:H35) -> 500 | I36: =SUM(I33:I35) -> 1100 | J36: =SUM(J33:J35) -> 200 | K36: =SUM(K33:K35) -> 200 | L36: =SUM(L33:L35) -> 700 | ... Q36: =SUM(Q33:Q35) -> 6250 | R36: =Q36/$B$4 -> 0.75419331
A38: 6330-8502 | B38: (SC) | C38: Parking Lot Cleaning | E38: 300 | F38: 300 | G38: 300 | H38: 300 | I38: 300 | J38: 300 | K38: 300 | L38: 300 | M38: 300 | N38: 300 | O38: 300 | P38: 300 | Q38: =SUM(E38:P38) -> 3600 | R38: =Q38/$B$4 -> 0.43441535 | S38: DW | T38: 2025 Business Plan grown 3%
D40: Parking Lot Maint.-Contractual | Q40: =SUM(E40:P40) -> 0 | R40: =Q40/$B$4 -> 0
D41: Parking Lot Maint.-Recurring | G41: 1250 | J41: 1250 | M41: 1250 | P41: 1250 | Q41: =SUM(E41:P41) -> 5000 | R41: =Q41/$B$4 -> 0.60335465 | S41: DW | T41: Est Misc. Repairs
D42: Parking Lot Maint.-Big Projects | Q42: =SUM(E42:P42) -> 0 | R42: =Q42/$B$4 -> 0 | S42: GM
A43: 6360-8502 | C43: Parking Lot Maintenance | E43: =SUM(E40:E42) -> 0 | F43: =SUM(F40:F42) -> 0 | G43: =SUM(G40:G42) -> 1250 | H43: =SUM(H40:H42) -> 0 | I43: =SUM(I40:I42) -> 0 | J43: =SUM(J40:J42) -> 1250 | K43: =SUM(K40:K42) -> 0 | L43: =SUM(L40:L42) -> 0 | ... Q43: =SUM(Q40:Q42) -> 5000 | R43: =Q43/$B$4 -> 0.60335465
A45: 6370-8502 | C45: Snow Removal | E45: =1.03*3500 -> 3605 | F45: =1.03*3500 -> 3605 | G45: =1.03*1000 -> 1030 | O45: =1.03*1000 -> 1030 | P45: =1.03*2000 -> 2060 | Q45: =SUM(E45:P45) -> 11330 | R45: =Q45/$B$4 -> 1.3672016 | S45: DW | T45: 2025 Business Plan grown 3%
D47: Landscaping-Contractual | H47: 376 | I47: 376 | J47: 376 | K47: 376 | L47: 376 | M47: 376 | N47: 376 | Q47: =SUM(E47:P47) -> 2632 | R47: =Q47/$B$4 -> 0.31760589 | S47: DW | T47: For mowing SC area only
D48: Landscaping-Recurring | H48: =1.03*100 -> 103 | I48: =1.03*100 -> 103 | J48: =1.03*100 -> 103 | K48: =1.03*100 -> 103 | L48: =1.03*100 -> 103 | M48: =1.03*100 -> 103 | N48: =1.03*100 -> 103 | Q48: =SUM(E48:P48) -> 721 | R48: =Q48/$B$4 -> 0.087003741 | S48: DW | T48: 2025 Business Plan grown 3%
D49: Landscaping-Big Projects | I49: 500 | L49: 500 | Q49: =SUM(G49:P49) -> 1000 | R49: =Q49/$B$4 -> 0.12067093 | S49: DW
A50: 6380-8502 | C50: Landscaping | E50: =SUM(E47:E49) -> 0 | F50: =SUM(F47:F49) -> 0 | G50: =SUM(G47:G49) -> 0 | H50: =SUM(H47:H49) -> 479 | I50: =SUM(I47:I49) -> 979 | J50: =SUM(J47:J49) -> 479 | K50: =SUM(K47:K49) -> 479 | L50: =SUM(L47:L49) -> 979 | ... Q50: =SUM(Q47:Q49) -> 4353 | R50: =Q50/$B$4 -> 0.52528056
A52: 6350-8502 | C52: Security | E52: =1.03*1300 -> 1339 | F52: =1.03*1300 -> 1339 | G52: =1.03*1300 -> 1339 | H52: =1.03*1300 -> 1339 | I52: =1.03*1300 -> 1339 | J52: =1.03*1300 -> 1339 | K52: =1.03*1300 -> 1339 | L52: =1.03*1300 -> 1339 | ... P52: =1.03*1300 -> 1339 | Q52: =SUM(E52:P52) -> 16068 | R52: =Q52/$B$4 -> 1.9389405 | S52: DW | T52: 2025 Business Plan grown 3%
A54: 6610-8502 | B54: (BP) | C54: Management Fee | Q54: =SUM(E54:P54) -> 0 | R54: =Q54/$B$4 -> 0
...

Sheet 1500
B1: 1500 | C1: - Eastwick JV I | J1: =+'All Shopping Centers'!J1 -> Operating Budget | Q1: ='All Shopping Centers'!Q1 -> 46023
J2: ='All Shopping Centers'!J2&" - "&B1 -> Shopping Centers - 1500
B4: 2280 | E4: Jan | F4: Feb | G4: Mar | H4: Apr | I4: May | J4: Jun | K4: Jul | L4: Aug | M4: Sep | N4: Oct | O4: Nov | P4: Dec | Q4: Total | R4: Total PSF | S4: Input | T4: Notes
D6: Occupancy % | E6: ='Renew & Vac '!AJ31 -> 1 | F6: ='Renew & Vac '!AK31 -> 1 | G6: ='Renew & Vac '!AL31 -> 1 | H6: ='Renew & Vac '!AM31 -> 1 | I6: ='Renew & Vac '!AN31 -> 1 | J6: ='Renew & Vac '!AO31 -> 1 | K6: ='Renew & Vac '!AP31 -> 1 | L6: ='Renew & Vac '!AQ31 -> 1 | ... P6: ='Renew & Vac '!AU31 -> 1
D7: Occupancy SF | E7: =$B$4*E6 -> 2280 | F7: =$B$4*F6 -> 2280 | G7: =$B$4*G6 -> 2280 | H7: =$B$4*H6 -> 2280 | I7: =$B$4*I6 -> 2280 | J7: =$B$4*J6 -> 2280 | K7: =$B$4*K6 -> 2280 | L7: =$B$4*L6 -> 2280 | ... P7: =$B$4*P6 -> 2280
B8: Revenues
A10: 4230-8501 | C10: Rental Income - In Place | E10: =SUMIFS('In Place Revenue'!$G:$G,'In Place Revenue'!$A:$A,$B$1,'In Place Revenue'!$H:$H,1) -> 0 | F10: =SUMIFS('In Place Revenue'!$G:$G,'In Place Revenue'!$A:$A,$B$1,'In Place Revenue'!$H:$H,2) -> 0 | G10: =SUMIFS('In Place Revenue'!$G:$G,'In Place Revenue'!$A:$A,$B$1,'In Place Revenue'!$H:$H,3) -> 0 | H10: =SUMIFS('In Place Revenue'!$G:$G,'In Place Revenue'!$A:$A,$B$1,'In Place Revenue'!$H:$H,4) -> 0 | I10: =SUMIFS('In Place Revenue'!$G:$G,'In Place Revenue'!$A:$A,$B$1,'In Place Revenue'!$H:$H,5) -> 0 | J10: =SUMIFS('In Place Revenue'!$G:$G,'In Place Revenue'!$A:$A,$B$1,'In Place Revenue'!$H:$H,6) -> 0 | K10: =SUMIFS('In Place Revenue'!$G:$G,'In Place Revenue'!$A:$A,$B$1,'In Place Revenue'!$H:$H,7) -> 0 | L10: =SUMIFS('In Place Revenue'!$G:$G,'In Place Revenue'!$A:$A,$B$1,'In Place Revenue'!$H:$H,8) -> 0 | M10: =SUMIFS('In Place Revenue'!$G:$G,'In Place Revenue'!$A:$A,$B$1,'In Place Revenue'!$H:$H,9) -> 0 | N10: =SUMIFS('In Place Revenue'!$G:$G,'In Place Revenue'!$A:$A,$B$1,'In Place Revenue'!$H:$H,10) -> 0 | O10: =SUMIFS('In Place Revenue'!$G:$G,'In Place Revenue'!$A:$A,$B$1,'In Place Revenue'!$H:$H,11) -> 0 | P10: =SUMIFS('In Place Revenue'!$G:$G,'In Place Revenue'!$A:$A,$B$1,'In Place Revenue'!$H:$H,12) -> 0 | Q10: =SUM(E10:P10) -> 0 | R10: =Q10/$B$4 -> 0
A11: 4230-8501 | C11: Rental Income - New & Renewal | E11: ='Renew & Vac '!AJ32 -> 0 | F11: ='Renew & Vac '!AK32 -> 0 | G11: ='Renew & Vac '!AL32 -> 0 | H11: ='Renew & Vac '!AM32 -> 0 | I11: ='Renew & Vac '!AN32 -> 0 | J11: ='Renew & Vac '!AO32 -> 0 | K11: ='Renew & Vac '!AP32 -> 0 | L11: ='Renew & Vac '!AQ32 -> 0 | ... P11: ='Renew & Vac '!AU32 -> 0 | Q11: =SUM(E11:P11) -> 0 | R11: =Q11/$B$4 -> 0
A12: 4240-8501 | C12: Percentage Rent | Q12: =SUM(E12:P12) -> 0 | R12: =Q12/$B$4 -> 0
A13: 4990-8501 | C13: Miscellaneous | Q13: =SUM(E13:P13) -> 0 | R13: =Q13/$B$4 -> 0
A14: 9190-8501 | C14: Interest Income | Q14: =SUM(E14:P14) -> 0 | R14: =Q14/$B$4 -> 0
C15: Total Rental and Other | E15: =SUM(E10:E14) -> 0 | F15: =SUM(F10:F14) -> 0 | G15: =SUM(G10:G14) -> 0 | H15: =SUM(H10:H14) -> 0 | I15: =SUM(I10:I14) -> 0 | J15: =SUM(J10:J14) -> 0 | K15: =SUM(K10:K14) -> 0 | L15: =SUM(L10:L14) -> 0 | ... Q15: =SUM(Q10:Q14) -> 0 | R15: =Q15/$B$4 -> 0
B17: Reimbursements
A18: 4710-8502 | C18: Electric | Q18: =SUM(E18:P18) -> 0 | R18: =Q18/$B$4 -> 0
A19: 4910-8502 | C19: Common Area Maintenance | E19: =+'Tenant Recoveries'!F26 -> 0 | F19: =+E19 -> 0 | G19: =+F19 -> 0 | H19: =+G19 -> 0 | I19: =+H19 -> 0 | J19: =+I19 -> 0 | K19: =+J19 -> 0 | L19: =+K19 -> 0 | M19: =+L19 -> 0 | ... P19: =+O19 -> 0 | Q19: =SUM(E19:P19) -> 0 | R19: =Q19/$B$4 -> 0
A20: 4920-8502 | C20: Real Estate Taxes | E20: =+'Tenant Recoveries'!F27 -> 0 | F20: =+E20 -> 0 | G20: =+F20 -> 0 | H20: =+G20 -> 0 | I20: =+H20 -> 0 | J20: =+I20 -> 0 | K20: =+J20 -> 0 | L20: =+K20 -> 0 | M20: =+L20 -> 0 | ... P20: =+O20 -> 0 | Q20: =SUM(E20:P20) -> 0 | R20: =Q20/$B$4 -> 0
A21: 4930-8502 | C21: Insurance | Q21: =SUM(E21:P21) -> 0 | R21: =Q21/$B$4 -> 0
C22: Total Reimbursements | E22: =SUM(E18:E21) -> 0 | F22: =SUM(F18:F21) -> 0 | G22: =SUM(G18:G21) -> 0 | H22: =SUM(H18:H21) -> 0 | I22: =SUM(I18:I21) -> 0 | J22: =SUM(J18:J21) -> 0 | K22: =SUM(K18:K21) -> 0 | L22: =SUM(L18:L21) -> 0 | ... Q22: =SUM(Q18:Q21) -> 0 | R22: =Q22/$B$4 -> 0
R23: =Q23/$B$4 -> 0
B24: TOTAL REVENUES | E24: =+E15+E22 -> 0 | F24: =+F15+F22 -> 0 | G24: =+G15+G22 -> 0 | H24: =+H15+H22 -> 0 | I24: =+I15+I22 -> 0 | J24: =+J15+J22 -> 0 | K24: =+K15+K22 -> 0 | L24: =+L15+L22 -> 0 | ... Q24: =+Q15+Q22 -> 0 | R24: =Q24/$B$4 -> 0
B26: Reimbursable Expenses
A27: 6030-8502 | C27: Maintenance Salaries | E27: =VLOOKUP($B$1,'Allocated Expenses'!$B$6:$P$15,4,FALSE) -> 70.208331 | F27: =VLOOKUP($B$1,'Allocated Expenses'!$B$6:$P$15,5,FALSE) -> 70.208331 | G27: =VLOOKUP($B$1,'Allocated Expenses'!$B$6:$P$15,6,FALSE) -> 70.208331 | H27: =VLOOKUP($B$1,'Allocated Expenses'!$B$6:$P$15,7,FALSE) -> 70.208331 | I27: =VLOOKUP($B$1,'Allocated Expenses'!$B$6:$P$15,8,FALSE) -> 70.208331 | J27: =VLOOKUP($B$1,'Allocated Expenses'!$B$6:$P$15,9,FALSE) -> 70.208331 | K27: =VLOOKUP($B$1,'Allocated Expenses'!$B$6:$P$15,10,FALSE) -> 70.208331 | L27: =VLOOKUP($B$1,'Allocated Expenses'!$B$6:$P$15,11,FALSE) -> 70.208331 | M27: =VLOOKUP($B$1,'Allocated Expenses'!$B$6:$P$15,12,FALSE) -> 70.208331 | N27: =VLOOKUP($B$1,'Allocated Expenses'!$B$6:$P$15,13,FALSE) -> 70.208331 | O27: =VLOOKUP($B$1,'Allocated Expenses'!$B$6:$P$15,14,FALSE) -> 70.208331 | P27: =VLOOKUP($B$1,'Allocated Expenses'!$B$6:$P$15,15,FALSE) -> 70.208331 | Q27: =SUM(E27:P27) -> 842.49997 | R27: =Q27/$B$4 -> 0.36951753
A29: 6120-8502 | C29: Electric | Q29: =SUM(E29:P29) -> 0 | R29: =Q29/$B$4 -> 0
A31: 6130-8502 | C31: Water & Sewer | Q31: =SUM(E31:P31) -> 0 | R31: =Q31/$B$4 -> 0
D33: Building Maint.-Contractual | E33: ='Building Maint'!C21 -> 0 | F33: ='Building Maint'!D21 -> 0 | G33: ='Building Maint'!E21 -> 0 | H33: ='Building Maint'!F21 -> 0 | I33: ='Building Maint'!G21 -> 0 | J33: ='Building Maint'!H21 -> 0 | K33: ='Building Maint'!I21 -> 0 | L33: ='Building Maint'!J21 -> 0 | ... P33: ='Building Maint'!N21 -> 0 | Q33: =SUM(E33:P33) -> 0 | R33: =Q33/$B$4 -> 0
D34: Building Maint.-Recurring | E34: ='Building Maint'!C7 -> 0 | F34: ='Building Maint'!D7 -> 0 | G34: ='Building Maint'!E7 -> 0 | H34: ='Building Maint'!F7 -> 0 | I34: ='Building Maint'!G7 -> 0 | J34: ='Building Maint'!H7 -> 0 | K34: ='Building Maint'!I7 -> 0 | L34: ='Building Maint'!J7 -> 0 | ... P34: ='Building Maint'!N7 -> 0 | Q34: =SUM(E34:P34) -> 0 | R34: =Q34/$B$4 -> 0
D35: Building Maint.-Big Projects | Q35: =SUM(E35:P35) -> 0 | R35: =Q35/$B$4 -> 0
A36: 6220-8502 | C36: Building Maintenance | E36: =SUM(E33:E35) -> 0 | F36: =SUM(F33:F35) -> 0 | G36: =SUM(G33:G35) -> 0 | H36: =SUM(H33:H35) -> 0 | I36: =SUM(I33:I35) -> 0 | J36: =SUM(J33:J35) -> 0 | K36: =SUM(K33:K35) -> 0 | L36: =SUM(L33:L35) -> 0 | ... Q36: =SUM(Q33:Q35) -> 0 | R36: =Q36/$B$4 -> 0
A38: 6330-8502 | B38: (SC) | C38: Parking Lot Cleaning | Q38: =SUM(E38:P38) -> 0 | R38: =Q38/$B$4 -> 0
D40: Parking Lot Maint.-Contractual | Q40: =SUM(E40:P40) -> 0 | R40: =Q40/$B$4 -> 0
D41: Parking Lot Maint.-Recurring | Q41: =SUM(E41:P41) -> 0 | R41: =Q41/$B$4 -> 0
D42: Parking Lot Maint.-Big Projects | Q42: =SUM(E42:P42) -> 0 | R42: =Q42/$B$4 -> 0
A43: 6360-8502 | C43: Parking Lot Maintenance | E43: =SUM(E40:E42) -> 0 | F43: =SUM(F40:F42) -> 0 | G43: =SUM(G40:G42) -> 0 | H43: =SUM(H40:H42) -> 0 | I43: =SUM(I40:I42) -> 0 | J43: =SUM(J40:J42) -> 0 | K43: =SUM(K40:K42) -> 0 | L43: =SUM(L40:L42) -> 0 | ... Q43: =SUM(Q40:Q42) -> 0 | R43: =Q43/$B$4 -> 0
A45: 6370-8502 | C45: Snow Removal | Q45: =SUM(E45:P45) -> 0 | R45: =Q45/$B$4 -> 0
Q46: =SUM(E46:P46) -> 0
D47: Landscaping-Contractual | Q47: =SUM(E47:P47) -> 0 | R47: =Q47/$B$4 -> 0
D48: Landscaping-Recurring | Q48: =SUM(E48:P48) -> 0 | R48: =Q48/$B$4 -> 0
D49: Landscaping-Big Projects | Q49: =SUM(E49:P49) -> 0 | R49: =Q49/$B$4 -> 0
A50: 6380-8502 | C50: Landscaping | E50: =SUM(E47:E49) -> 0 | F50: =SUM(F47:F49) -> 0 | G50: =SUM(G47:G49) -> 0 | H50: =SUM(H47:H49) -> 0 | I50: =SUM(I47:I49) -> 0 | J50: =SUM(J47:J49) -> 0 | K50: =SUM(K47:K49) -> 0 | L50: =SUM(L47:L49) -> 0 | ... Q50: =SUM(Q47:Q49) -> 0 | R50: =Q50/$B$4 -> 0
A52: 6350-8502 | C52: Security | Q52: =SUM(E52:P52) -> 0 | R52: =Q52/$B$4 -> 0
...

Sheet 2300
B1: 2300 | C1: - Brookwood Shopping Center | J1: =+'1500'!J1 -> Operating Budget | Q1: ='All Shopping Centers'!Q1 -> 46023
J2: ='All Shopping Centers'!J2&" - "&B1 -> Shopping Centers - 2300
S3: 9/2025 Reprojections
B4: 61572 | E4: Jan | F4: Feb | G4: Mar | H4: Apr | I4: May | J4: Jun | K4: Jul | L4: Aug | M4: Sep | N4: Oct | O4: Nov | P4: Dec | Q4: Total | R4: Total PSF | S4: Total | T4: Var. | U4: Input | V4: Notes
D6: Occupancy % | E6: ='Renew & Vac '!AJ53 -> 1 | F6: ='Renew & Vac '!AK53 -> 1 | G6: ='Renew & Vac '!AL53 -> 1 | H6: ='Renew & Vac '!AM53 -> 1 | I6: ='Renew & Vac '!AN53 -> 1 | J6: ='Renew & Vac '!AO53 -> 1 | K6: ='Renew & Vac '!AP53 -> 1 | L6: ='Renew & Vac '!AQ53 -> 1 | ... P6: ='Renew & Vac '!AU53 -> 1
D7: Occupancy SF | E7: =$B$4*E6 -> 61572 | F7: =$B$4*F6 -> 61572 | G7: =$B$4*G6 -> 61572 | H7: =$B$4*H6 -> 61572 | I7: =$B$4*I6 -> 61572 | J7: =$B$4*J6 -> 61572 | K7: =$B$4*K6 -> 61572 | L7: =$B$4*L6 -> 61572 | ... P7: =$B$4*P6 -> 61572
B8: Revenues
A10: 4230-8501 | C10: Rental Income - In Place | E10: =SUMIFS('In Place Revenue'!$G:$G,'In Place Revenue'!$A:$A,$B$1,'In Place Revenue'!$H:$H,1) -> 96896.61 | F10: =SUMIFS('In Place Revenue'!$G:$G,'In Place Revenue'!$A:$A,$B$1,'In Place Revenue'!$H:$H,2) -> 96896.61 | G10: =SUMIFS('In Place Revenue'!$G:$G,'In Place Revenue'!$A:$A,$B$1,'In Place Revenue'!$H:$H,3) -> 97346.61 | H10: =SUMIFS('In Place Revenue'!$G:$G,'In Place Revenue'!$A:$A,$B$1,'In Place Revenue'!$H:$H,4) -> 97346.61 | I10: =SUMIFS('In Place Revenue'!$G:$G,'In Place Revenue'!$A:$A,$B$1,'In Place Revenue'!$H:$H,5) -> 97346.61 | J10: =SUMIFS('In Place Revenue'!$G:$G,'In Place Revenue'!$A:$A,$B$1,'In Place Revenue'!$H:$H,6) -> 97479.94 | K10: =SUMIFS('In Place Revenue'!$G:$G,'In Place Revenue'!$A:$A,$B$1,'In Place Revenue'!$H:$H,7) -> 94386.36 | L10: =SUMIFS('In Place Revenue'!$G:$G,'In Place Revenue'!$A:$A,$B$1,'In Place Revenue'!$H:$H,8) -> 94386.36 | M10: =SUMIFS('In Place Revenue'!$G:$G,'In Place Revenue'!$A:$A,$B$1,'In Place Revenue'!$H:$H,9) -> 94386.36 | N10: =SUMIFS('In Place Revenue'!$G:$G,'In Place Revenue'!$A:$A,$B$1,'In Place Revenue'!$H:$H,10) -> 94386.36 | O10: =SUMIFS('In Place Revenue'!$G:$G,'In Place Revenue'!$A:$A,$B$1,'In Place Revenue'!$H:$H,11) -> 94386.36 | P10: =SUMIFS('In Place Revenue'!$G:$G,'In Place Revenue'!$A:$A,$B$1,'In Place Revenue'!$H:$H,12) -> 94386.36 | Q10: =SUM(E10:P10) -> 1149631.2 | R10: =Q10/$B$4 -> 18.67133 | S10: 1157263 | T10: =(Q10+Q11)/S10-1 -> 0.0099961288
A11: 4230-8501 | C11: Rental Income - New & Renewal | E11: ='Renew & Vac '!AJ54 -> 0 | F11: ='Renew & Vac '!AK54 -> 0 | G11: ='Renew & Vac '!AL54 -> 0 | H11: ='Renew & Vac '!AM54 -> 0 | I11: ='Renew & Vac '!AN54 -> 0 | J11: ='Renew & Vac '!AO54 -> 0 | K11: ='Renew & Vac '!AP54 -> 3200 | L11: ='Renew & Vac '!AQ54 -> 3200 | ... P11: ='Renew & Vac '!AU54 -> 3200 | Q11: =SUM(E11:P11) -> 19200 | R11: =Q11/$B$4 -> 0.31183005
A12: 4240-8501 | C12: Percentage Rents | Q12: =SUM(E12:P12) -> 0 | R12: =Q12/$B$4 -> 0 | S12: 0 | T12: =IFERROR(Q12/S12-1,"")
A13: 4990-8501 | C13: Miscellaneous | Q13: =SUM(E13:P13) -> 0 | R13: =Q13/$B$4 -> 0 | S13: 0 | T13: =IFERROR(Q13/S13-1,"")
A14: 9190-8501 | C14: Interest Income | Q14: =SUM(E14:P14) -> 0 | R14: =Q14/$B$4 -> 0 | S14: 31900 | T14: =IFERROR(Q14/S14-1,"") -> -1
C15: Total Rental and Other | E15: =SUM(E10:E14) -> 96896.61 | F15: =SUM(F10:F14) -> 96896.61 | G15: =SUM(G10:G14) -> 97346.61 | H15: =SUM(H10:H14) -> 97346.61 | I15: =SUM(I10:I14) -> 97346.61 | J15: =SUM(J10:J14) -> 97479.94 | K15: =SUM(K10:K14) -> 97586.36 | L15: =SUM(L10:L14) -> 97586.36 | ... Q15: =SUM(Q10:Q14) -> 1168831.2 | R15: =Q15/$B$4 -> 18.98316 | S15: =SUM(S10:S14) -> 1189163 | T15: =Q15/S15-1 -> -0.017097614
B17: Reimbursements
A18: 4710-8502 | C18: Electric | Q18: =SUM(E18:P18) -> 0 | R18: =Q18/$B$4 -> 0 | S18: 0 | T18: =IFERROR(Q18/S18-1,"")
A19: 4910-8502 | C19: Common Area Maintenance | E19: =+'Tenant Recoveries'!G26 -> 21100 | F19: =+E19 -> 21100 | G19: =+F19 -> 21100 | H19: =+G19 -> 21100 | I19: =+H19 -> 21100 | J19: =+I19 -> 21100 | K19: =+J19 -> 21100 | L19: =+K19 -> 21100 | M19: =+L19 -> 21100 | ... P19: =+O19 -> 21100 | Q19: =SUM(E19:P19) -> 253200 | R19: =Q19/$B$4 -> 4.1122588 | S19: 267960 | T19: =IFERROR(Q19/S19-1,"") -> -0.055082848
A20: 4920-8502 | C20: Real Estate Taxes | E20: =+'Tenant Recoveries'!G27 -> 11200 | F20: =+E20 -> 11200 | G20: =+F20 -> 11200 | H20: =+G20 -> 11200 | I20: =+H20 -> 11200 | J20: =+I20 -> 11200 | K20: =+J20 -> 11200 | L20: =+K20 -> 11200 | M20: =+L20 -> 11200 | ... P20: =+O20 -> 11200 | Q20: =SUM(E20:P20) -> 134400 | R20: =Q20/$B$4 -> 2.1828104 | S20: 140724 | T20: =IFERROR(Q20/S20-1,"") -> -0.04493903
A21: 4930-8502 | C21: Insurance | Q21: =SUM(E21:P21) -> 0 | R21: =Q21/$B$4 -> 0 | S21: 13468 | T21: =IFERROR(Q21/S21-1,"") -> -1
C22: Total Reimbursements | E22: =SUM(E18:E21) -> 32300 | F22: =SUM(F18:F21) -> 32300 | G22: =SUM(G18:G21) -> 32300 | H22: =SUM(H18:H21) -> 32300 | I22: =SUM(I18:I21) -> 32300 | J22: =SUM(J18:J21) -> 32300 | K22: =SUM(K18:K21) -> 32300 | L22: =SUM(L18:L21) -> 32300 | ... Q22: =SUM(Q18:Q21) -> 387600 | R22: =Q22/$B$4 -> 6.2950692 | S22: =SUM(S18:S21) -> 422152 | T22: =Q22/S22-1 -> -0.081847297
R23: =Q23/$B$4 -> 0
B24: TOTAL REVENUES | E24: =+E15+E22 -> 129196.61 | F24: =+F15+F22 -> 129196.61 | G24: =+G15+G22 -> 129646.61 | H24: =+H15+H22 -> 129646.61 | I24: =+I15+I22 -> 129646.61 | J24: =+J15+J22 -> 129779.94 | K24: =+K15+K22 -> 129886.36 | L24: =+L15+L22 -> 129886.36 | ... Q24: =+Q15+Q22 -> 1556431.2 | R24: =Q24/$B$4 -> 25.27823 | S24: =+S15+S22 -> 1611315 | T24: =Q24/S24-1 -> -0.034061527
B26: Reimbursable Expenses
